2019-01-19 22:34:46,743 INFO  Kname: samba_conf was get. 
2019-01-19 22:34:46,744 INFO  Kname: samba_conf was get. 
2019-01-19 22:34:46,745 INFO  Kname: samba_conf was get. 
2019-01-19 22:34:46,755 INFO  HR--------------------------- 
2019-01-19 22:34:46,823 ERROR  Section u'HR' already exists 
2019-01-19 22:34:46,823 INFO  Kname: valid users was set. 
2019-01-19 22:34:46,824 ERROR  Internal Server Error: /department/department_add 
Traceback (most recent call last):
  File "/data/django/lib/python2.7/site-packages/django/core/handlers/base.py", line 132, in get_response
    response = wrapped_callback(request, *callback_args, **callback_kwargs)
  File "/code/samba/web/department/views.py", line 47, in dpt_add
    sconf.config_save()
  File "/code/samba/web/wsamba/confhandler.py", line 25, in config_save
    self.config.write(f)
  File "/usr/lib64/python2.7/ConfigParser.py", line 412, in write
    key = " = ".join((key, str(value).replace('\n', '\n\t')))
UnicodeEncodeError: 'ascii' codec can't encode characters in position 0-2: ordinal not in range(128)
2019-01-19 22:35:23,321 ERROR  groupdel: group 'HR' does not exist
1
 
2019-01-19 22:35:23,363 ERROR  Internal Server Error: /department/department_delete 
Traceback (most recent call last):
  File "/data/django/lib/python2.7/site-packages/django/core/handlers/base.py", line 132, in get_response
    response = wrapped_callback(request, *callback_args, **callback_kwargs)
  File "/code/samba/web/department/views.py", line 139, in dpt_del
    sconf.remove_section(dpt_name)
  File "/usr/lib64/python2.7/ConfigParser.py", line 433, in remove_section
    existed = section in self._sections
AttributeError: Config_helper instance has no attribute '_sections'
2019-01-19 22:37:00,705 INFO  /deploy/ 
2019-01-19 22:37:11,018 ERROR  groupdel: group 'HR' does not exist
1
 
2019-01-19 22:37:11,042 ERROR  Internal Server Error: /department/department_delete 
Traceback (most recent call last):
  File "/data/django/lib/python2.7/site-packages/django/core/handlers/base.py", line 132, in get_response
    response = wrapped_callback(request, *callback_args, **callback_kwargs)
  File "/code/samba/web/department/views.py", line 139, in dpt_del
    sconf.remove_section(dpt_name)
  File "/usr/lib64/python2.7/ConfigParser.py", line 433, in remove_section
    existed = section in self._sections
AttributeError: Config_helper instance has no attribute '_sections'
2019-01-19 22:37:18,123 INFO  /deploy/ 
2019-01-19 22:37:20,503 INFO  /deploy/ 
2019-01-19 22:37:26,414 ERROR  userdel: wangbo1 home directory (/home/wangbo1) not found
 
2019-01-19 22:37:26,420 ERROR  1
 
2019-01-19 22:37:26,465 INFO  SAMBA USER:wangbo1  was deleted. 
2019-01-19 22:38:10,648 ERROR  groupdel: group 'FA' does not exist
1
 
2019-01-19 22:38:10,670 ERROR  Internal Server Error: /department/department_delete 
Traceback (most recent call last):
  File "/data/django/lib/python2.7/site-packages/django/core/handlers/base.py", line 132, in get_response
    response = wrapped_callback(request, *callback_args, **callback_kwargs)
  File "/code/samba/web/department/views.py", line 139, in dpt_del
    sconf.remove_section(dpt_name)
  File "/usr/lib64/python2.7/ConfigParser.py", line 433, in remove_section
    existed = section in self._sections
AttributeError: Config_helper instance has no attribute '_sections'
2019-01-19 22:38:41,148 INFO  HR--------------------------- 
2019-01-19 22:38:41,327 ERROR  Section u'HR' already exists 
2019-01-19 22:38:41,328 INFO  Kname: valid users was set. 
2019-01-19 22:38:41,328 ERROR  Internal Server Error: /department/department_add 
Traceback (most recent call last):
  File "/data/django/lib/python2.7/site-packages/django/core/handlers/base.py", line 132, in get_response
    response = wrapped_callback(request, *callback_args, **callback_kwargs)
  File "/code/samba/web/department/views.py", line 47, in dpt_add
    sconf.config_save()
  File "/code/samba/web/wsamba/confhandler.py", line 25, in config_save
    self.config.write(f)
  File "/usr/lib64/python2.7/ConfigParser.py", line 412, in write
    key = " = ".join((key, str(value).replace('\n', '\n\t')))
UnicodeEncodeError: 'ascii' codec can't encode characters in position 0-2: ordinal not in range(128)
2019-01-19 22:58:39,642 INFO  Kname: samba_conf was get. 
2019-01-19 22:58:39,643 INFO  Kname: samba_conf was get. 
2019-01-19 22:58:39,644 INFO  Kname: samba_conf was get. 
2019-01-19 22:58:42,424 ERROR  groupdel: group 'HR' does not exist
1
 
2019-01-19 22:58:42,468 ERROR  Internal Server Error: /department/department_delete 
Traceback (most recent call last):
  File "/data/django/lib/python2.7/site-packages/django/core/handlers/base.py", line 132, in get_response
    response = wrapped_callback(request, *callback_args, **callback_kwargs)
  File "/code/samba/web/department/views.py", line 139, in dpt_del
    sconf.remove_section(dpt_name)
  File "/usr/lib64/python2.7/ConfigParser.py", line 433, in remove_section
    existed = section in self._sections
AttributeError: Config_helper instance has no attribute '_sections'
2019-01-19 22:58:51,438 INFO  HR--------------------------- 
2019-01-19 22:58:51,502 ERROR  Section u'HR' already exists 
2019-01-19 22:58:51,502 INFO  Kname: valid users was set. 
2019-01-19 22:58:51,503 ERROR  Internal Server Error: /department/department_add 
Traceback (most recent call last):
  File "/data/django/lib/python2.7/site-packages/django/core/handlers/base.py", line 132, in get_response
    response = wrapped_callback(request, *callback_args, **callback_kwargs)
  File "/code/samba/web/department/views.py", line 47, in dpt_add
    sconf.config_save()
  File "/code/samba/web/wsamba/confhandler.py", line 25, in config_save
    self.config.write(f)
  File "/usr/lib64/python2.7/ConfigParser.py", line 412, in write
    key = " = ".join((key, str(value).replace('\n', '\n\t')))
UnicodeEncodeError: 'ascii' codec can't encode characters in position 0-2: ordinal not in range(128)
2019-01-19 22:59:14,883 ERROR  groupdel: group 'HR' does not exist
1
 
2019-01-19 22:59:14,919 ERROR  Internal Server Error: /department/department_delete 
Traceback (most recent call last):
  File "/data/django/lib/python2.7/site-packages/django/core/handlers/base.py", line 132, in get_response
    response = wrapped_callback(request, *callback_args, **callback_kwargs)
  File "/code/samba/web/department/views.py", line 139, in dpt_del
    sconf.remove_section(dpt_name)
  File "/usr/lib64/python2.7/ConfigParser.py", line 433, in remove_section
    existed = section in self._sections
AttributeError: Config_helper instance has no attribute '_sections'
2019-01-19 22:59:33,616 INFO  HR--------------------------- 
2019-01-19 22:59:33,674 INFO  Department :HR was added. 
2019-01-19 22:59:33,674 INFO  Kname: valid users was set. 
2019-01-19 22:59:33,674 ERROR  Internal Server Error: /department/department_add 
Traceback (most recent call last):
  File "/data/django/lib/python2.7/site-packages/django/core/handlers/base.py", line 132, in get_response
    response = wrapped_callback(request, *callback_args, **callback_kwargs)
  File "/code/samba/web/department/views.py", line 47, in dpt_add
    sconf.config_save()
  File "/code/samba/web/wsamba/confhandler.py", line 25, in config_save
    self.config.write(f)
  File "/usr/lib64/python2.7/ConfigParser.py", line 412, in write
    key = " = ".join((key, str(value).replace('\n', '\n\t')))
UnicodeEncodeError: 'ascii' codec can't encode characters in position 0-2: ordinal not in range(128)
2019-01-19 23:00:30,096 INFO  Kname: samba_conf was get. 
2019-01-19 23:00:30,097 INFO  Kname: samba_conf was get. 
2019-01-19 23:00:30,100 INFO  Kname: samba_conf was get. 
2019-01-19 23:00:30,128 ERROR  groupdel: group 'HR' does not exist
1
 
2019-01-19 23:00:30,279 ERROR  Internal Server Error: /department/department_delete 
Traceback (most recent call last):
  File "/data/django/lib/python2.7/site-packages/django/core/handlers/base.py", line 132, in get_response
    response = wrapped_callback(request, *callback_args, **callback_kwargs)
  File "/code/samba/web/department/views.py", line 139, in dpt_del
    sconf.remove_section(dpt_name)
  File "/usr/lib64/python2.7/ConfigParser.py", line 433, in remove_section
    existed = section in self._sections
AttributeError: Config_helper instance has no attribute '_sections'
2019-01-19 23:00:52,741 INFO  人事部--------------------------- 
2019-01-19 23:00:52,808 ERROR  Section u'HR' already exists 
2019-01-19 23:00:52,808 INFO  Kname: valid users was set. 
2019-01-19 23:00:52,808 ERROR  Internal Server Error: /department/department_add 
Traceback (most recent call last):
  File "/data/django/lib/python2.7/site-packages/django/core/handlers/base.py", line 132, in get_response
    response = wrapped_callback(request, *callback_args, **callback_kwargs)
  File "/code/samba/web/department/views.py", line 47, in dpt_add
    sconf.config_save()
  File "/code/samba/web/wsamba/confhandler.py", line 25, in config_save
    self.config.write(f)
  File "/usr/lib64/python2.7/ConfigParser.py", line 412, in write
    key = " = ".join((key, str(value).replace('\n', '\n\t')))
UnicodeEncodeError: 'ascii' codec can't encode characters in position 0-2: ordinal not in range(128)
2019-01-19 23:04:59,615 INFO  Kname: samba_conf was get. 
2019-01-19 23:04:59,616 INFO  Kname: samba_conf was get. 
2019-01-19 23:04:59,619 INFO  Kname: samba_conf was get. 
2019-01-19 23:05:06,448 INFO  /data/smb.conf--------------------------- 
2019-01-19 23:05:06,518 INFO  Department :HR was added. 
2019-01-19 23:05:06,519 INFO  Kname: valid users was set. 
2019-01-19 23:05:06,519 ERROR  Internal Server Error: /department/department_add 
Traceback (most recent call last):
  File "/data/django/lib/python2.7/site-packages/django/core/handlers/base.py", line 132, in get_response
    response = wrapped_callback(request, *callback_args, **callback_kwargs)
  File "/code/samba/web/department/views.py", line 47, in dpt_add
    sconf.config_save()
  File "/code/samba/web/wsamba/confhandler.py", line 25, in config_save
    self.config.write(f)
  File "/usr/lib64/python2.7/ConfigParser.py", line 412, in write
    key = " = ".join((key, str(value).replace('\n', '\n\t')))
UnicodeEncodeError: 'ascii' codec can't encode characters in position 0-2: ordinal not in range(128)
2019-01-19 23:06:49,539 INFO  /deploy/ 
2019-01-19 23:06:59,727 INFO  /deploy/ 
2019-01-19 23:07:05,207 ERROR  groupdel: group 'HR' does not exist
1
 
2019-01-19 23:07:05,260 ERROR  Internal Server Error: /department/department_delete 
Traceback (most recent call last):
  File "/data/django/lib/python2.7/site-packages/django/core/handlers/base.py", line 132, in get_response
    response = wrapped_callback(request, *callback_args, **callback_kwargs)
  File "/code/samba/web/department/views.py", line 139, in dpt_del
    sconf.remove_section(dpt_name)
  File "/usr/lib64/python2.7/ConfigParser.py", line 433, in remove_section
    existed = section in self._sections
AttributeError: Config_helper instance has no attribute '_sections'
2019-01-19 23:07:07,918 INFO  /deploy/ 
2019-01-19 23:07:14,987 ERROR  groupdel: group 'HR' does not exist
1
 
2019-01-19 23:07:15,012 ERROR  Internal Server Error: /department/department_delete 
Traceback (most recent call last):
  File "/data/django/lib/python2.7/site-packages/django/core/handlers/base.py", line 132, in get_response
    response = wrapped_callback(request, *callback_args, **callback_kwargs)
  File "/code/samba/web/department/views.py", line 139, in dpt_del
    sconf.remove_section(dpt_name)
  File "/usr/lib64/python2.7/ConfigParser.py", line 433, in remove_section
    existed = section in self._sections
AttributeError: Config_helper instance has no attribute '_sections'
2019-01-19 23:09:57,978 INFO  Kname: samba_conf was get. 
2019-01-19 23:09:57,979 INFO  Kname: samba_conf was get. 
2019-01-19 23:09:57,982 INFO  Kname: samba_conf was get. 
2019-01-19 23:10:02,374 INFO  /data/smb.conf--------------------------- 
2019-01-19 23:10:02,446 ERROR  Section u'HR' already exists 
2019-01-19 23:10:02,447 INFO  Kname: valid users was set. 
2019-01-19 23:10:02,447 INFO  Kname: valid users was set. 
2019-01-19 23:10:02,447 ERROR  Internal Server Error: /department/department_add 
Traceback (most recent call last):
  File "/data/django/lib/python2.7/site-packages/django/core/handlers/base.py", line 132, in get_response
    response = wrapped_callback(request, *callback_args, **callback_kwargs)
  File "/code/samba/web/department/views.py", line 48, in dpt_add
    sconf.config_save()
  File "/code/samba/web/wsamba/confhandler.py", line 25, in config_save
    self.config.write(f)
  File "/usr/lib64/python2.7/ConfigParser.py", line 412, in write
    key = " = ".join((key, str(value).replace('\n', '\n\t')))
UnicodeEncodeError: 'ascii' codec can't encode characters in position 0-2: ordinal not in range(128)
2019-01-19 23:10:08,723 INFO  /deploy/ 
2019-01-19 23:10:43,018 INFO  Kname: samba_conf was get. 
2019-01-19 23:10:43,019 INFO  Kname: samba_conf was get. 
2019-01-19 23:10:43,022 INFO  Kname: samba_conf was get. 
2019-01-19 23:10:43,041 ERROR  groupdel: group 'HR' does not exist
1
 
2019-01-19 23:10:43,089 ERROR  Internal Server Error: /department/department_delete 
Traceback (most recent call last):
  File "/data/django/lib/python2.7/site-packages/django/core/handlers/base.py", line 132, in get_response
    response = wrapped_callback(request, *callback_args, **callback_kwargs)
  File "/code/samba/web/department/views.py", line 140, in dpt_del
    sconf.remove_section(dpt_name)
  File "/usr/lib64/python2.7/ConfigParser.py", line 433, in remove_section
    existed = section in self._sections
AttributeError: Config_helper instance has no attribute '_sections'
2019-01-19 23:10:49,721 INFO  /data/smb.conf--------------------------- 
2019-01-19 23:10:49,818 ERROR  Section u'HR' already exists 
2019-01-19 23:10:49,818 INFO  Kname: comment was set. 
2019-01-19 23:10:49,818 INFO  Kname: valid users was set. 
2019-01-19 23:10:49,818 ERROR  Internal Server Error: /department/department_add 
Traceback (most recent call last):
  File "/data/django/lib/python2.7/site-packages/django/core/handlers/base.py", line 132, in get_response
    response = wrapped_callback(request, *callback_args, **callback_kwargs)
  File "/code/samba/web/department/views.py", line 48, in dpt_add
    sconf.config_save()
  File "/code/samba/web/wsamba/confhandler.py", line 25, in config_save
    self.config.write(f)
  File "/usr/lib64/python2.7/ConfigParser.py", line 412, in write
    key = " = ".join((key, str(value).replace('\n', '\n\t')))
UnicodeEncodeError: 'ascii' codec can't encode characters in position 0-2: ordinal not in range(128)
2019-01-19 23:11:16,354 ERROR  groupdel: group 'HR' does not exist
1
 
2019-01-19 23:11:16,399 ERROR  Internal Server Error: /department/department_delete 
Traceback (most recent call last):
  File "/data/django/lib/python2.7/site-packages/django/core/handlers/base.py", line 132, in get_response
    response = wrapped_callback(request, *callback_args, **callback_kwargs)
  File "/code/samba/web/department/views.py", line 140, in dpt_del
    sconf.remove_section(dpt_name)
  File "/usr/lib64/python2.7/ConfigParser.py", line 433, in remove_section
    existed = section in self._sections
AttributeError: Config_helper instance has no attribute '_sections'
2019-01-19 23:15:21,211 INFO  Kname: samba_conf was get. 
2019-01-19 23:15:21,213 INFO  Kname: samba_conf was get. 
2019-01-19 23:15:21,215 INFO  Kname: samba_conf was get. 
2019-01-19 23:15:30,497 INFO  /data/smb.conf--------------------------- 
2019-01-19 23:15:30,497 ERROR  Internal Server Error: /department/department_add 
Traceback (most recent call last):
  File "/data/django/lib/python2.7/site-packages/django/core/handlers/base.py", line 132, in get_response
    response = wrapped_callback(request, *callback_args, **callback_kwargs)
  File "/code/samba/web/department/views.py", line 38, in dpt_add
    if nb.objects.filter(dptname=dptname):
  File "/data/django/lib/python2.7/site-packages/django/db/models/manager.py", line 252, in __get__
    raise AttributeError("Manager isn't accessible via %s instances" % type.__name__)
AttributeError: Manager isn't accessible via Sa_dpt instances
2019-01-19 23:18:50,249 INFO  Kname: samba_conf was get. 
2019-01-19 23:18:50,251 INFO  Kname: samba_conf was get. 
2019-01-19 23:18:50,254 INFO  Kname: samba_conf was get. 
2019-01-19 23:18:57,966 INFO  /data/smb.conf--------------------------- 
2019-01-19 23:18:57,968 ERROR  Internal Server Error: /department/department_add 
Traceback (most recent call last):
  File "/data/django/lib/python2.7/site-packages/django/core/handlers/base.py", line 132, in get_response
    response = wrapped_callback(request, *callback_args, **callback_kwargs)
  File "/code/samba/web/department/views.py", line 38, in dpt_add
    sa_dpt = Sa_dpt.objects.get(dptname=dptname1)
  File "/data/django/lib/python2.7/site-packages/django/db/models/manager.py", line 127, in manager_method
    return getattr(self.get_queryset(), name)(*args, **kwargs)
  File "/data/django/lib/python2.7/site-packages/django/db/models/query.py", line 334, in get
    self.model._meta.object_name
DoesNotExist: Sa_dpt matching query does not exist.
2019-01-19 23:19:36,462 INFO  Kname: samba_conf was get. 
2019-01-19 23:19:36,464 INFO  Kname: samba_conf was get. 
2019-01-19 23:19:36,466 INFO  Kname: samba_conf was get. 
2019-01-19 23:19:38,306 INFO  /deploy/ 
2019-01-19 23:19:43,831 INFO  /data/smb.conf--------------------------- 
2019-01-19 23:19:43,833 ERROR  Internal Server Error: /department/department_add 
Traceback (most recent call last):
  File "/data/django/lib/python2.7/site-packages/django/core/handlers/base.py", line 132, in get_response
    response = wrapped_callback(request, *callback_args, **callback_kwargs)
  File "/code/samba/web/department/views.py", line 38, in dpt_add
    sa_dpt = Sa_dpt.objects.get(dptname=dptname1)
  File "/data/django/lib/python2.7/site-packages/django/db/models/manager.py", line 127, in manager_method
    return getattr(self.get_queryset(), name)(*args, **kwargs)
  File "/data/django/lib/python2.7/site-packages/django/db/models/query.py", line 334, in get
    self.model._meta.object_name
DoesNotExist: Sa_dpt matching query does not exist.
2019-01-19 23:20:46,886 INFO  Kname: samba_conf was get. 
2019-01-19 23:20:46,888 INFO  Kname: samba_conf was get. 
2019-01-19 23:20:46,889 ERROR  Internal Server Error: /department/ 
Traceback (most recent call last):
  File "/data/django/lib/python2.7/site-packages/django/core/handlers/base.py", line 119, in get_response
    resolver_match = resolver.resolve(request.path_info)
  File "/data/django/lib/python2.7/site-packages/django/core/urlresolvers.py", line 366, in resolve
    for pattern in self.url_patterns:
  File "/data/django/lib/python2.7/site-packages/django/core/urlresolvers.py", line 402, in url_patterns
    patterns = getattr(self.urlconf_module, "urlpatterns", self.urlconf_module)
  File "/data/django/lib/python2.7/site-packages/django/core/urlresolvers.py", line 396, in urlconf_module
    self._urlconf_module = import_module(self.urlconf_name)
  File "/usr/lib64/python2.7/importlib/__init__.py", line 37, in import_module
    __import__(name)
  File "/code/samba/web/web/urls.py", line 18, in <module>
    import dashboard.urls,browse.urls,consumer.urls,deploy.urls,department.urls
  File "/code/samba/web/department/urls.py", line 2, in <module>
    import views
  File "/code/samba/web/department/views.py", line 38
    sa_dpt = Sa_dpt.objects.get(dptname=dptname1,'')
SyntaxError: non-keyword arg after keyword arg
2019-01-19 23:20:58,932 ERROR  Internal Server Error: /department/ 
Traceback (most recent call last):
  File "/data/django/lib/python2.7/site-packages/django/core/handlers/base.py", line 119, in get_response
    resolver_match = resolver.resolve(request.path_info)
  File "/data/django/lib/python2.7/site-packages/django/core/urlresolvers.py", line 366, in resolve
    for pattern in self.url_patterns:
  File "/data/django/lib/python2.7/site-packages/django/core/urlresolvers.py", line 402, in url_patterns
    patterns = getattr(self.urlconf_module, "urlpatterns", self.urlconf_module)
  File "/data/django/lib/python2.7/site-packages/django/core/urlresolvers.py", line 396, in urlconf_module
    self._urlconf_module = import_module(self.urlconf_name)
  File "/usr/lib64/python2.7/importlib/__init__.py", line 37, in import_module
    __import__(name)
  File "/code/samba/web/web/urls.py", line 18, in <module>
    import dashboard.urls,browse.urls,consumer.urls,deploy.urls,department.urls
  File "/code/samba/web/department/urls.py", line 2, in <module>
    import views
  File "/code/samba/web/department/views.py", line 38
    sa_dpt = Sa_dpt.objects.get(dptname=dptname1,' ')
SyntaxError: non-keyword arg after keyword arg
2019-01-19 23:22:44,595 INFO  Kname: samba_conf was get. 
2019-01-19 23:22:56,655 INFO  Kname: samba_conf was get. 
2019-01-19 23:22:56,657 INFO  Kname: samba_conf was get. 
2019-01-19 23:22:56,657 INFO  Kname: samba_conf was get. 
2019-01-19 23:23:00,733 INFO  /data/smb.conf--------------------------- 
2019-01-19 23:23:00,734 INFO  Sa_dpt matching query does not exist. 
2019-01-19 23:26:09,639 INFO  Kname: samba_conf was get. 
2019-01-19 23:26:09,641 INFO  Kname: samba_conf was get. 
2019-01-19 23:26:09,643 ERROR  Internal Server Error: /department/ 
Traceback (most recent call last):
  File "/data/django/lib/python2.7/site-packages/django/core/handlers/base.py", line 119, in get_response
    resolver_match = resolver.resolve(request.path_info)
  File "/data/django/lib/python2.7/site-packages/django/core/urlresolvers.py", line 366, in resolve
    for pattern in self.url_patterns:
  File "/data/django/lib/python2.7/site-packages/django/core/urlresolvers.py", line 402, in url_patterns
    patterns = getattr(self.urlconf_module, "urlpatterns", self.urlconf_module)
  File "/data/django/lib/python2.7/site-packages/django/core/urlresolvers.py", line 396, in urlconf_module
    self._urlconf_module = import_module(self.urlconf_name)
  File "/usr/lib64/python2.7/importlib/__init__.py", line 37, in import_module
    __import__(name)
  File "/code/samba/web/web/urls.py", line 18, in <module>
    import dashboard.urls,browse.urls,consumer.urls,deploy.urls,department.urls
  File "/code/samba/web/department/urls.py", line 2, in <module>
    import views
  File "/code/samba/web/department/views.py", line 45
    continue
SyntaxError: 'continue' not properly in loop
2019-01-19 23:27:07,263 INFO  Kname: samba_conf was get. 
2019-01-19 23:27:14,332 INFO  /data/smb.conf--------------------------- 
2019-01-19 23:27:14,334 INFO  Sa_dpt matching query does not exist. 
2019-01-19 23:27:23,261 INFO  /data/smb.conf--------------------------- 
2019-01-19 23:27:23,263 ERROR  Internal Server Error: /department/department_add 
Traceback (most recent call last):
  File "/data/django/lib/python2.7/site-packages/django/core/handlers/base.py", line 132, in get_response
    response = wrapped_callback(request, *callback_args, **callback_kwargs)
  File "/code/samba/web/department/views.py", line 44, in dpt_add
    if sa_dpt:
UnboundLocalError: local variable 'sa_dpt' referenced before assignment
2019-01-19 23:27:32,030 INFO  /deploy/ 
2019-01-19 23:31:06,833 INFO  Kname: samba_conf was get. 
2019-01-19 23:31:06,834 INFO  Kname: samba_conf was get. 
2019-01-19 23:31:06,837 INFO  Kname: samba_conf was get. 
2019-01-19 23:31:13,030 INFO  /data/smb.conf--------------------------- 
2019-01-19 23:31:13,033 ERROR  Internal Server Error: /department/department_add 
Traceback (most recent call last):
  File "/data/django/lib/python2.7/site-packages/django/core/handlers/base.py", line 132, in get_response
    response = wrapped_callback(request, *callback_args, **callback_kwargs)
  File "/code/samba/web/department/views.py", line 45, in dpt_add
    if sa_dpt:
UnboundLocalError: local variable 'sa_dpt' referenced before assignment
2019-01-19 23:31:17,980 INFO  /deploy/ 
2019-01-19 23:31:22,808 ERROR  groupdel: group 'HR' does not exist
1
 
2019-01-19 23:31:22,851 ERROR  Internal Server Error: /department/department_delete 
Traceback (most recent call last):
  File "/data/django/lib/python2.7/site-packages/django/core/handlers/base.py", line 132, in get_response
    response = wrapped_callback(request, *callback_args, **callback_kwargs)
  File "/code/samba/web/department/views.py", line 148, in dpt_del
    sconf.remove_section(dpt_name)
  File "/usr/lib64/python2.7/ConfigParser.py", line 433, in remove_section
    existed = section in self._sections
AttributeError: Config_helper instance has no attribute '_sections'
2019-01-19 23:31:30,761 INFO  /data/smb.conf--------------------------- 
2019-01-19 23:31:30,762 INFO  False 
2019-01-19 23:31:30,831 INFO  Department :HR was added. 
2019-01-19 23:31:30,831 INFO  Kname: comment was set. 
2019-01-19 23:31:30,831 INFO  Kname: valid users was set. 
2019-01-19 23:31:30,832 ERROR  Internal Server Error: /department/department_add 
Traceback (most recent call last):
  File "/data/django/lib/python2.7/site-packages/django/core/handlers/base.py", line 132, in get_response
    response = wrapped_callback(request, *callback_args, **callback_kwargs)
  File "/code/samba/web/department/views.py", line 56, in dpt_add
    sconf.config_save()
  File "/code/samba/web/wsamba/confhandler.py", line 25, in config_save
    self.config.write(f)
  File "/usr/lib64/python2.7/ConfigParser.py", line 412, in write
    key = " = ".join((key, str(value).replace('\n', '\n\t')))
UnicodeEncodeError: 'ascii' codec can't encode characters in position 0-2: ordinal not in range(128)
2019-01-19 23:31:33,788 INFO  /deploy/ 
2019-01-19 23:31:41,596 INFO  /data/smb.conf--------------------------- 
2019-01-19 23:31:41,598 ERROR  Internal Server Error: /department/department_add 
Traceback (most recent call last):
  File "/data/django/lib/python2.7/site-packages/django/core/handlers/base.py", line 132, in get_response
    response = wrapped_callback(request, *callback_args, **callback_kwargs)
  File "/code/samba/web/department/views.py", line 45, in dpt_add
    if sa_dpt:
UnboundLocalError: local variable 'sa_dpt' referenced before assignment
2019-01-19 23:31:46,490 INFO  /deploy/ 
2019-01-19 23:32:56,226 ERROR  groupdel: group 'HR' does not exist
1
 
2019-01-19 23:32:56,319 ERROR  Internal Server Error: /department/department_delete 
Traceback (most recent call last):
  File "/data/django/lib/python2.7/site-packages/django/core/handlers/base.py", line 132, in get_response
    response = wrapped_callback(request, *callback_args, **callback_kwargs)
  File "/code/samba/web/department/views.py", line 148, in dpt_del
    sconf.remove_section(dpt_name)
  File "/usr/lib64/python2.7/ConfigParser.py", line 433, in remove_section
    existed = section in self._sections
AttributeError: Config_helper instance has no attribute '_sections'
2019-01-19 23:33:17,758 INFO  /data/smb.conf--------------------------- 
2019-01-19 23:33:17,760 INFO  False 
2019-01-19 23:33:17,819 ERROR  Section u'HR' already exists 
2019-01-19 23:33:17,819 INFO  Kname: comment was set. 
2019-01-19 23:33:17,819 INFO  Kname: valid users was set. 
2019-01-19 23:33:17,819 ERROR  Internal Server Error: /department/department_add 
Traceback (most recent call last):
  File "/data/django/lib/python2.7/site-packages/django/core/handlers/base.py", line 132, in get_response
    response = wrapped_callback(request, *callback_args, **callback_kwargs)
  File "/code/samba/web/department/views.py", line 56, in dpt_add
    sconf.config_save()
  File "/code/samba/web/wsamba/confhandler.py", line 25, in config_save
    self.config.write(f)
  File "/usr/lib64/python2.7/ConfigParser.py", line 412, in write
    key = " = ".join((key, str(value).replace('\n', '\n\t')))
UnicodeEncodeError: 'ascii' codec can't encode characters in position 0-2: ordinal not in range(128)
2019-01-19 23:35:21,235 INFO  Kname: samba_conf was get. 
2019-01-19 23:35:21,237 INFO  Kname: samba_conf was get. 
2019-01-19 23:35:21,241 INFO  Kname: samba_conf was get. 
2019-01-19 23:35:26,901 ERROR  groupdel: group 'HR' does not exist
1
 
2019-01-19 23:35:26,939 ERROR  Internal Server Error: /department/department_delete 
Traceback (most recent call last):
  File "/data/django/lib/python2.7/site-packages/django/core/handlers/base.py", line 132, in get_response
    response = wrapped_callback(request, *callback_args, **callback_kwargs)
  File "/code/samba/web/department/views.py", line 148, in dpt_del
    sconf.remove_section(dpt_name)
  File "/usr/lib64/python2.7/ConfigParser.py", line 433, in remove_section
    existed = section in self._sections
AttributeError: Config_helper instance has no attribute '_sections'
2019-01-19 23:35:32,338 INFO  /data/smb.conf--------------------------- 
2019-01-19 23:35:32,340 INFO  False 
2019-01-19 23:35:32,398 ERROR  Section u'HR' already exists 
2019-01-19 23:35:32,399 INFO  Kname: comment was set. 
2019-01-19 23:35:32,399 INFO  Kname: valid users was set. 
2019-01-19 23:35:32,399 ERROR  Internal Server Error: /department/department_add 
Traceback (most recent call last):
  File "/data/django/lib/python2.7/site-packages/django/core/handlers/base.py", line 132, in get_response
    response = wrapped_callback(request, *callback_args, **callback_kwargs)
  File "/code/samba/web/department/views.py", line 56, in dpt_add
    sconf.config_save()
  File "/code/samba/web/wsamba/confhandler.py", line 25, in config_save
    self.config.write(f)
  File "/usr/lib64/python2.7/ConfigParser.py", line 412, in write
    key = " = ".join((key, str(value).replace('\n', '\n\t')))
UnicodeEncodeError: 'ascii' codec can't encode characters in position 0-2: ordinal not in range(128)
2019-01-19 23:38:48,245 INFO  Kname: samba_conf was get. 
2019-01-19 23:38:48,246 INFO  Kname: samba_conf was get. 
2019-01-19 23:38:48,249 INFO  Kname: samba_conf was get. 
2019-01-19 23:38:52,772 ERROR  groupdel: group 'HR' does not exist
1
 
2019-01-19 23:38:52,813 ERROR  Internal Server Error: /department/department_delete 
Traceback (most recent call last):
  File "/data/django/lib/python2.7/site-packages/django/core/handlers/base.py", line 132, in get_response
    response = wrapped_callback(request, *callback_args, **callback_kwargs)
  File "/code/samba/web/department/views.py", line 148, in dpt_del
    sconf.remove_section(dpt_name)
  File "/usr/lib64/python2.7/ConfigParser.py", line 433, in remove_section
    existed = section in self._sections
AttributeError: Config_helper instance has no attribute '_sections'
2019-01-19 23:38:57,602 INFO  /deploy/ 
2019-01-19 23:39:03,432 INFO  /data/smb.conf--------------------------- 
2019-01-19 23:39:03,433 INFO  False 
2019-01-19 23:39:03,500 INFO  Department :HR was added. 
2019-01-19 23:39:03,500 INFO  Kname: comment was set. 
2019-01-19 23:39:03,500 INFO  Kname: valid users was set. 
2019-01-19 23:39:03,501 ERROR  Internal Server Error: /department/department_add 
Traceback (most recent call last):
  File "/data/django/lib/python2.7/site-packages/django/core/handlers/base.py", line 132, in get_response
    response = wrapped_callback(request, *callback_args, **callback_kwargs)
  File "/code/samba/web/department/views.py", line 56, in dpt_add
    sconf.config_save()
  File "/code/samba/web/wsamba/confhandler.py", line 25, in config_save
    self.config.write(f)
  File "/usr/lib64/python2.7/ConfigParser.py", line 412, in write
    key = " = ".join((key, str(value).replace('\n', '\n\t')))
UnicodeEncodeError: 'ascii' codec can't encode characters in position 0-2: ordinal not in range(128)
2019-01-19 23:39:12,360 ERROR  groupdel: group 'HR' does not exist
1
 
2019-01-19 23:39:12,402 ERROR  Internal Server Error: /department/department_delete 
Traceback (most recent call last):
  File "/data/django/lib/python2.7/site-packages/django/core/handlers/base.py", line 132, in get_response
    response = wrapped_callback(request, *callback_args, **callback_kwargs)
  File "/code/samba/web/department/views.py", line 148, in dpt_del
    sconf.remove_section(dpt_name)
  File "/usr/lib64/python2.7/ConfigParser.py", line 433, in remove_section
    existed = section in self._sections
AttributeError: Config_helper instance has no attribute '_sections'
2019-01-19 23:40:28,641 INFO  Kname: samba_conf was get. 
2019-01-19 23:40:28,643 INFO  Kname: samba_conf was get. 
2019-01-19 23:40:28,645 INFO  Kname: samba_conf was get. 
2019-01-19 23:40:45,254 INFO  /data/smb.conf--------------------------- 
2019-01-19 23:40:45,256 INFO  False 
2019-01-19 23:40:45,336 ERROR  Section u'HR' already exists 
2019-01-19 23:40:45,336 INFO  Kname: comment was set. 
2019-01-19 23:40:45,336 INFO  Kname: valid users was set. 
2019-01-19 23:40:45,336 ERROR  Internal Server Error: /department/department_add 
Traceback (most recent call last):
  File "/data/django/lib/python2.7/site-packages/django/core/handlers/base.py", line 132, in get_response
    response = wrapped_callback(request, *callback_args, **callback_kwargs)
  File "/code/samba/web/department/views.py", line 56, in dpt_add
    sconf.config_save()
  File "/code/samba/web/wsamba/confhandler.py", line 25, in config_save
    self.config.write(f)
  File "/usr/lib64/python2.7/ConfigParser.py", line 412, in write
    key = " = ".join((key, str(value).replace('\n', '\n\t')))
UnicodeEncodeError: 'ascii' codec can't encode characters in position 0-2: ordinal not in range(128)
2019-01-19 23:43:51,854 INFO  Kname: samba_conf was get. 
2019-01-19 23:43:51,855 INFO  Kname: samba_conf was get. 
2019-01-19 23:43:51,861 INFO  Kname: samba_conf was get. 
2019-01-19 23:43:51,880 ERROR  groupdel: group 'HR' does not exist
1
 
2019-01-19 23:43:51,922 ERROR  Internal Server Error: /department/department_delete 
Traceback (most recent call last):
  File "/data/django/lib/python2.7/site-packages/django/core/handlers/base.py", line 132, in get_response
    response = wrapped_callback(request, *callback_args, **callback_kwargs)
  File "/code/samba/web/department/views.py", line 149, in dpt_del
    sconf.remove_section(dpt_name)
  File "/usr/lib64/python2.7/ConfigParser.py", line 433, in remove_section
    existed = section in self._sections
AttributeError: Config_helper instance has no attribute '_sections'
2019-01-19 23:43:56,967 INFO  /data/smb.conf--------------------------- 
2019-01-19 23:43:56,969 INFO  False 
2019-01-19 23:43:57,014 ERROR  Section u'HR' already exists 
2019-01-19 23:43:57,015 INFO  Kname: comment was set. 
2019-01-19 23:43:57,015 INFO  Kname: valid users was set. 
2019-01-19 23:43:57,015 ERROR  Internal Server Error: /department/department_add 
Traceback (most recent call last):
  File "/data/django/lib/python2.7/site-packages/django/core/handlers/base.py", line 132, in get_response
    response = wrapped_callback(request, *callback_args, **callback_kwargs)
  File "/code/samba/web/department/views.py", line 57, in dpt_add
    sconf.config_save()
  File "/code/samba/web/wsamba/confhandler.py", line 25, in config_save
    self.config.write(f)
  File "/usr/lib64/python2.7/ConfigParser.py", line 412, in write
    key = " = ".join((key, str(value).replace('\n', '\n\t')))
UnicodeEncodeError: 'ascii' codec can't encode characters in position 0-2: ordinal not in range(128)
2019-01-19 23:44:12,520 INFO  /data/smb.conf--------------------------- 
2019-01-19 23:44:12,522 ERROR  Internal Server Error: /department/department_add 
Traceback (most recent call last):
  File "/data/django/lib/python2.7/site-packages/django/core/handlers/base.py", line 132, in get_response
    response = wrapped_callback(request, *callback_args, **callback_kwargs)
  File "/code/samba/web/department/views.py", line 45, in dpt_add
    if sa_dpt:
UnboundLocalError: local variable 'sa_dpt' referenced before assignment
2019-01-19 23:44:17,789 INFO  /deploy/ 
2019-01-19 23:44:27,158 ERROR  groupdel: group 'HR' does not exist
1
 
2019-01-19 23:44:27,286 ERROR  Internal Server Error: /department/department_delete 
Traceback (most recent call last):
  File "/data/django/lib/python2.7/site-packages/django/core/handlers/base.py", line 132, in get_response
    response = wrapped_callback(request, *callback_args, **callback_kwargs)
  File "/code/samba/web/department/views.py", line 149, in dpt_del
    sconf.remove_section(dpt_name)
  File "/usr/lib64/python2.7/ConfigParser.py", line 433, in remove_section
    existed = section in self._sections
AttributeError: Config_helper instance has no attribute '_sections'
2019-01-19 23:44:38,129 INFO  /data/smb.conf--------------------------- 
2019-01-19 23:44:38,132 INFO  False 
2019-01-19 23:44:38,205 ERROR  Section u'HR' already exists 
2019-01-19 23:44:38,206 INFO  Kname: comment was set. 
2019-01-19 23:44:38,206 INFO  Kname: valid users was set. 
2019-01-19 23:44:38,206 ERROR  Internal Server Error: /department/department_add 
Traceback (most recent call last):
  File "/data/django/lib/python2.7/site-packages/django/core/handlers/base.py", line 132, in get_response
    response = wrapped_callback(request, *callback_args, **callback_kwargs)
  File "/code/samba/web/department/views.py", line 57, in dpt_add
    sconf.config_save()
  File "/code/samba/web/wsamba/confhandler.py", line 25, in config_save
    self.config.write(f)
  File "/usr/lib64/python2.7/ConfigParser.py", line 412, in write
    key = " = ".join((key, str(value).replace('\n', '\n\t')))
UnicodeEncodeError: 'ascii' codec can't encode characters in position 0-2: ordinal not in range(128)
2019-01-19 23:44:40,143 INFO  /deploy/ 
2019-01-19 23:44:46,637 ERROR  groupdel: group 'HR' does not exist
1
 
2019-01-19 23:44:46,660 ERROR  Internal Server Error: /department/department_delete 
Traceback (most recent call last):
  File "/data/django/lib/python2.7/site-packages/django/core/handlers/base.py", line 132, in get_response
    response = wrapped_callback(request, *callback_args, **callback_kwargs)
  File "/code/samba/web/department/views.py", line 149, in dpt_del
    sconf.remove_section(dpt_name)
  File "/usr/lib64/python2.7/ConfigParser.py", line 433, in remove_section
    existed = section in self._sections
AttributeError: Config_helper instance has no attribute '_sections'
2019-01-19 23:45:14,633 INFO  Kname: samba_conf was get. 
2019-01-19 23:45:14,634 INFO  Kname: samba_conf was get. 
2019-01-19 23:45:14,636 INFO  Kname: samba_conf was get. 
2019-01-19 23:45:20,020 INFO  /data/smb.conf--------------------------- 
2019-01-19 23:45:20,022 INFO  False 
2019-01-19 23:45:20,091 ERROR  Section u'HR' already exists 
2019-01-19 23:45:20,092 INFO  Kname: comment was set. 
2019-01-19 23:45:20,092 INFO  Kname: valid users was set. 
2019-01-19 23:45:20,092 ERROR  Internal Server Error: /department/department_add 
Traceback (most recent call last):
  File "/data/django/lib/python2.7/site-packages/django/core/handlers/base.py", line 132, in get_response
    response = wrapped_callback(request, *callback_args, **callback_kwargs)
  File "/code/samba/web/department/views.py", line 56, in dpt_add
    sconf.config_save()
  File "/code/samba/web/wsamba/confhandler.py", line 25, in config_save
    self.config.write(f)
  File "/usr/lib64/python2.7/ConfigParser.py", line 412, in write
    key = " = ".join((key, str(value).replace('\n', '\n\t')))
UnicodeEncodeError: 'ascii' codec can't encode characters in position 0-2: ordinal not in range(128)
2019-01-19 23:45:21,899 INFO  /deploy/ 
2019-01-19 23:45:46,738 ERROR  groupdel: group 'HR' does not exist
1
 
2019-01-19 23:45:46,783 ERROR  Internal Server Error: /department/department_delete 
Traceback (most recent call last):
  File "/data/django/lib/python2.7/site-packages/django/core/handlers/base.py", line 132, in get_response
    response = wrapped_callback(request, *callback_args, **callback_kwargs)
  File "/code/samba/web/department/views.py", line 148, in dpt_del
    sconf.remove_section(dpt_name)
  File "/usr/lib64/python2.7/ConfigParser.py", line 433, in remove_section
    existed = section in self._sections
AttributeError: Config_helper instance has no attribute '_sections'
2019-01-19 23:45:49,969 INFO  /deploy/ 
2019-01-19 23:45:57,520 INFO  /deploy/ 
2019-01-19 23:49:08,410 INFO  /deploy/ 
2019-01-19 23:50:02,002 INFO  /data/smb.conf--------------------------- 
2019-01-19 23:50:02,004 INFO  False 
2019-01-19 23:50:02,098 ERROR  Section u'HR' already exists 
2019-01-19 23:50:02,099 INFO  Kname: comment was set. 
2019-01-19 23:50:02,099 INFO  Kname: valid users was set. 
2019-01-19 23:50:02,099 ERROR  Internal Server Error: /department/department_add 
Traceback (most recent call last):
  File "/data/django/lib/python2.7/site-packages/django/core/handlers/base.py", line 132, in get_response
    response = wrapped_callback(request, *callback_args, **callback_kwargs)
  File "/code/samba/web/department/views.py", line 56, in dpt_add
    sconf.config_save()
  File "/code/samba/web/wsamba/confhandler.py", line 25, in config_save
    self.config.write(f)
  File "/usr/lib64/python2.7/ConfigParser.py", line 412, in write
    key = " = ".join((key, str(value).replace('\n', '\n\t')))
UnicodeEncodeError: 'ascii' codec can't encode characters in position 0-2: ordinal not in range(128)
2019-01-19 23:50:51,881 INFO  /deploy/ 
2019-01-19 23:51:18,070 INFO  /deploy/ 
2019-01-19 23:54:08,365 ERROR  Internal Server Error: /department/ 
Traceback (most recent call last):
  File "/data/django/lib/python2.7/site-packages/django/core/handlers/base.py", line 119, in get_response
    resolver_match = resolver.resolve(request.path_info)
  File "/data/django/lib/python2.7/site-packages/django/core/urlresolvers.py", line 366, in resolve
    for pattern in self.url_patterns:
  File "/data/django/lib/python2.7/site-packages/django/core/urlresolvers.py", line 402, in url_patterns
    patterns = getattr(self.urlconf_module, "urlpatterns", self.urlconf_module)
  File "/data/django/lib/python2.7/site-packages/django/core/urlresolvers.py", line 396, in urlconf_module
    self._urlconf_module = import_module(self.urlconf_name)
  File "/usr/lib64/python2.7/importlib/__init__.py", line 37, in import_module
    __import__(name)
  File "/code/samba/web/web/urls.py", line 18, in <module>
    import dashboard.urls,browse.urls,consumer.urls,deploy.urls,department.urls
  File "/code/samba/web/dashboard/urls.py", line 2, in <module>
    import views
  File "/code/samba/web/dashboard/views.py", line 12, in <module>
    from wsamba import confhandler
  File "/code/samba/web/wsamba/confhandler.py", line 3, in <module>
    sys.setdefaultencoding('utf-8')
NameError: name 'sys' is not defined
2019-01-19 23:54:08,458 ERROR  Internal Server Error: /department/department_delete 
Traceback (most recent call last):
  File "/data/django/lib/python2.7/site-packages/django/core/handlers/base.py", line 108, in get_response
    response = middleware_method(request)
  File "/data/django/lib/python2.7/site-packages/django/middleware/common.py", line 74, in process_request
    if (not urlresolvers.is_valid_path(request.path_info, urlconf) and
  File "/data/django/lib/python2.7/site-packages/django/core/urlresolvers.py", line 647, in is_valid_path
    resolve(path, urlconf)
  File "/data/django/lib/python2.7/site-packages/django/core/urlresolvers.py", line 522, in resolve
    return get_resolver(urlconf).resolve(path)
  File "/data/django/lib/python2.7/site-packages/django/core/urlresolvers.py", line 366, in resolve
    for pattern in self.url_patterns:
  File "/data/django/lib/python2.7/site-packages/django/core/urlresolvers.py", line 402, in url_patterns
    patterns = getattr(self.urlconf_module, "urlpatterns", self.urlconf_module)
  File "/data/django/lib/python2.7/site-packages/django/core/urlresolvers.py", line 396, in urlconf_module
    self._urlconf_module = import_module(self.urlconf_name)
  File "/usr/lib64/python2.7/importlib/__init__.py", line 37, in import_module
    __import__(name)
  File "/code/samba/web/web/urls.py", line 18, in <module>
    import dashboard.urls,browse.urls,consumer.urls,deploy.urls,department.urls
  File "/code/samba/web/dashboard/urls.py", line 2, in <module>
    import views
  File "/code/samba/web/dashboard/views.py", line 12, in <module>
    from wsamba import confhandler
  File "/code/samba/web/wsamba/confhandler.py", line 3, in <module>
    sys.setdefaultencoding('utf-8')
NameError: name 'sys' is not defined
2019-01-19 23:54:44,380 ERROR  Internal Server Error: /department/ 
Traceback (most recent call last):
  File "/data/django/lib/python2.7/site-packages/django/core/handlers/base.py", line 119, in get_response
    resolver_match = resolver.resolve(request.path_info)
  File "/data/django/lib/python2.7/site-packages/django/core/urlresolvers.py", line 366, in resolve
    for pattern in self.url_patterns:
  File "/data/django/lib/python2.7/site-packages/django/core/urlresolvers.py", line 402, in url_patterns
    patterns = getattr(self.urlconf_module, "urlpatterns", self.urlconf_module)
  File "/data/django/lib/python2.7/site-packages/django/core/urlresolvers.py", line 396, in urlconf_module
    self._urlconf_module = import_module(self.urlconf_name)
  File "/usr/lib64/python2.7/importlib/__init__.py", line 37, in import_module
    __import__(name)
  File "/code/samba/web/web/urls.py", line 18, in <module>
    import dashboard.urls,browse.urls,consumer.urls,deploy.urls,department.urls
  File "/code/samba/web/dashboard/urls.py", line 2, in <module>
    import views
  File "/code/samba/web/dashboard/views.py", line 12, in <module>
    from wsamba import confhandler
  File "/code/samba/web/wsamba/confhandler.py", line 10, in <module>
    sys.setdefaultencoding('utf-8')
AttributeError: 'module' object has no attribute 'setdefaultencoding'
2019-01-19 23:55:31,429 INFO  Kname: samba_conf was get. 
2019-01-19 23:55:31,430 INFO  Kname: samba_conf was get. 
2019-01-19 23:55:31,431 INFO  Kname: samba_conf was get. 
2019-01-19 23:55:34,307 ERROR  groupdel: group 'HR' does not exist
1
 
2019-01-19 23:55:34,352 ERROR  Internal Server Error: /department/department_delete 
Traceback (most recent call last):
  File "/data/django/lib/python2.7/site-packages/django/core/handlers/base.py", line 132, in get_response
    response = wrapped_callback(request, *callback_args, **callback_kwargs)
  File "/code/samba/web/department/views.py", line 148, in dpt_del
    sconf.remove_section(dpt_name)
  File "/usr/lib64/python2.7/ConfigParser.py", line 433, in remove_section
    existed = section in self._sections
AttributeError: Config_helper instance has no attribute '_sections'
2019-01-19 23:55:42,280 INFO  /data/smb.conf--------------------------- 
2019-01-19 23:55:42,282 INFO  False 
2019-01-19 23:55:42,346 ERROR  Section u'HR' already exists 
2019-01-19 23:55:42,346 INFO  Kname: comment was set. 
2019-01-19 23:55:42,346 INFO  Kname: valid users was set. 
2019-01-19 23:55:42,346 INFO  CONFIGFILE: /data/smb.conf was saved. 
2019-01-19 23:55:42,387 WARNING  Department :HRwas added. 
2019-01-19 23:56:50,901 INFO  Kname: samba_conf was get. 
2019-01-19 23:56:50,902 INFO  Kname: samba_conf was get. 
2019-01-19 23:56:50,903 INFO  Kname: samba_conf was get. 
2019-01-19 23:56:50,961 WARNING  Department :HRwas deleted. 
2019-01-19 23:56:51,001 ERROR  Internal Server Error: /department/department_delete 
Traceback (most recent call last):
  File "/data/django/lib/python2.7/site-packages/django/core/handlers/base.py", line 132, in get_response
    response = wrapped_callback(request, *callback_args, **callback_kwargs)
  File "/code/samba/web/department/views.py", line 148, in dpt_del
    sconf.remove_section(dpt_name)
  File "/usr/lib64/python2.7/ConfigParser.py", line 433, in remove_section
    existed = section in self._sections
AttributeError: Config_helper instance has no attribute '_sections'
2019-01-19 23:56:58,898 INFO  /data/smb.conf--------------------------- 
2019-01-19 23:56:58,900 INFO  False 
2019-01-19 23:56:59,062 ERROR  Section u'HR' already exists 
2019-01-19 23:56:59,063 INFO  Kname: comment was set. 
2019-01-19 23:56:59,063 INFO  Kname: valid users was set. 
2019-01-19 23:56:59,063 ERROR  Internal Server Error: /department/department_add 
Traceback (most recent call last):
  File "/data/django/lib/python2.7/site-packages/django/core/handlers/base.py", line 132, in get_response
    response = wrapped_callback(request, *callback_args, **callback_kwargs)
  File "/code/samba/web/department/views.py", line 56, in dpt_add
    sconf.config_save()
  File "/code/samba/web/wsamba/confhandler.py", line 24, in config_save
    self.config.write(f)
  File "/usr/lib64/python2.7/ConfigParser.py", line 412, in write
    key = " = ".join((key, str(value).replace('\n', '\n\t')))
UnicodeEncodeError: 'ascii' codec can't encode characters in position 0-2: ordinal not in range(128)
2019-01-19 23:57:25,382 INFO  Kname: samba_conf was get. 
2019-01-19 23:57:25,383 INFO  Kname: samba_conf was get. 
2019-01-19 23:57:25,383 INFO  Kname: samba_conf was get. 
2019-01-19 23:57:33,774 ERROR  groupdel: group 'HR' does not exist
1
 
2019-01-19 23:57:33,819 ERROR  Internal Server Error: /department/department_delete 
Traceback (most recent call last):
  File "/data/django/lib/python2.7/site-packages/django/core/handlers/base.py", line 132, in get_response
    response = wrapped_callback(request, *callback_args, **callback_kwargs)
  File "/code/samba/web/department/views.py", line 148, in dpt_del
    sconf.remove_section(dpt_name)
  File "/usr/lib64/python2.7/ConfigParser.py", line 433, in remove_section
    existed = section in self._sections
AttributeError: Config_helper instance has no attribute '_sections'
2019-01-19 23:57:45,069 INFO  /data/smb.conf--------------------------- 
2019-01-19 23:57:45,071 INFO  False 
2019-01-19 23:57:45,141 ERROR  Section u'HR' already exists 
2019-01-19 23:57:45,141 INFO  Kname: comment was set. 
2019-01-19 23:57:45,141 INFO  Kname: valid users was set. 
2019-01-19 23:57:45,141 ERROR  Internal Server Error: /department/department_add 
Traceback (most recent call last):
  File "/data/django/lib/python2.7/site-packages/django/core/handlers/base.py", line 132, in get_response
    response = wrapped_callback(request, *callback_args, **callback_kwargs)
  File "/code/samba/web/department/views.py", line 56, in dpt_add
    sconf.config_save()
  File "/code/samba/web/wsamba/confhandler.py", line 23, in config_save
    sys.setdefaultencoding('utf-8')
AttributeError: 'module' object has no attribute 'setdefaultencoding'
2019-01-19 23:58:36,454 INFO  Kname: samba_conf was get. 
2019-01-19 23:58:36,456 INFO  Kname: samba_conf was get. 
2019-01-19 23:58:36,456 INFO  Kname: samba_conf was get. 
2019-01-19 23:58:38,527 ERROR  groupdel: group 'HR' does not exist
1
 
2019-01-19 23:58:38,576 ERROR  Internal Server Error: /department/department_delete 
Traceback (most recent call last):
  File "/data/django/lib/python2.7/site-packages/django/core/handlers/base.py", line 132, in get_response
    response = wrapped_callback(request, *callback_args, **callback_kwargs)
  File "/code/samba/web/department/views.py", line 148, in dpt_del
    sconf.remove_section(dpt_name)
  File "/usr/lib64/python2.7/ConfigParser.py", line 433, in remove_section
    existed = section in self._sections
AttributeError: Config_helper instance has no attribute '_sections'
2019-01-19 23:58:44,078 INFO  /data/smb.conf--------------------------- 
2019-01-19 23:58:44,080 INFO  False 
2019-01-19 23:58:44,152 ERROR  Section u'HR' already exists 
2019-01-19 23:58:44,152 INFO  Kname: comment was set. 
2019-01-19 23:58:44,152 INFO  Kname: valid users was set. 
2019-01-19 23:58:44,152 INFO  CONFIGFILE: /data/smb.conf was saved. 
2019-01-19 23:58:44,200 WARNING  Department :HRwas added. 
2019-01-19 23:58:52,799 INFO  /deploy/ 
2019-01-19 23:59:41,565 WARNING  Department :HRwas deleted. 
2019-01-19 23:59:41,609 ERROR  Internal Server Error: /department/department_delete 
Traceback (most recent call last):
  File "/data/django/lib/python2.7/site-packages/django/core/handlers/base.py", line 132, in get_response
    response = wrapped_callback(request, *callback_args, **callback_kwargs)
  File "/code/samba/web/department/views.py", line 148, in dpt_del
    sconf.remove_section(dpt_name)
  File "/usr/lib64/python2.7/ConfigParser.py", line 433, in remove_section
    existed = section in self._sections
AttributeError: Config_helper instance has no attribute '_sections'
2019-01-19 23:59:58,425 INFO  /deploy/ 
2019-01-20 00:00:01,839 INFO  /deploy/ 
2019-01-20 00:02:31,274 INFO  Kname: samba_conf was get. 
2019-01-20 00:02:31,275 INFO  Kname: samba_conf was get. 
2019-01-20 00:02:31,278 INFO  Kname: samba_conf was get. 
2019-01-20 00:02:31,292 INFO  False 
2019-01-20 00:02:31,376 ERROR  Section u'HR' already exists 
2019-01-20 00:02:31,376 INFO  Kname: comment was set. 
2019-01-20 00:02:31,376 INFO  Kname: valid users was set. 
2019-01-20 00:02:31,377 INFO  CONFIGFILE: /data/smb.conf was saved. 
2019-01-20 00:02:31,419 WARNING  Department :HRwas added. 
2019-01-20 00:02:39,150 INFO  /deploy/ 
2019-01-20 00:02:44,405 WARNING  Department :HRwas deleted. 
2019-01-20 00:02:44,469 WARNING  Department :HR was removed. 
2019-01-20 00:02:44,470 ERROR  Internal Server Error: /department/department_delete 
Traceback (most recent call last):
  File "/data/django/lib/python2.7/site-packages/django/core/handlers/base.py", line 151, in get_response
    % (callback.__module__, view_name))
ValueError: The view department.views.dpt_del didn't return an HttpResponse object. It returned None instead.
2019-01-20 00:02:48,059 INFO  /deploy/ 
2019-01-20 00:07:11,217 INFO  Kname: samba_conf was get. 
2019-01-20 00:07:11,218 INFO  Kname: samba_conf was get. 
2019-01-20 00:07:11,221 INFO  Kname: samba_conf was get. 
2019-01-20 00:07:22,096 INFO  False 
2019-01-20 00:07:22,158 INFO  Department :HR was added. 
2019-01-20 00:07:22,158 INFO  Kname: comment was set. 
2019-01-20 00:07:22,158 INFO  Kname: valid users was set. 
2019-01-20 00:07:22,159 INFO  CONFIGFILE: /data/smb.conf was saved. 
2019-01-20 00:07:22,201 WARNING  Department :HRwas added. 
2019-01-20 00:07:26,824 WARNING  Department :HRwas deleted. 
2019-01-20 00:07:26,866 WARNING  Department :HR was removed. 
2019-01-20 00:07:26,866 INFO  CONFIGFILE: /data/smb.conf was saved. 
2019-01-20 00:07:26,868 ERROR  Internal Server Error: /department/department_delete 
Traceback (most recent call last):
  File "/data/django/lib/python2.7/site-packages/django/core/handlers/base.py", line 151, in get_response
    % (callback.__module__, view_name))
ValueError: The view department.views.dpt_del didn't return an HttpResponse object. It returned None instead.
2019-01-20 00:07:29,585 INFO  /deploy/ 
2019-01-20 00:07:57,204 INFO  False 
2019-01-20 00:07:57,291 INFO  Department :HR was added. 
2019-01-20 00:07:57,292 INFO  Kname: comment was set. 
2019-01-20 00:07:57,293 INFO  Kname: valid users was set. 
2019-01-20 00:07:57,293 INFO  CONFIGFILE: /data/smb.conf was saved. 
2019-01-20 00:07:57,343 WARNING  Department :HRwas added. 
2019-01-20 00:11:51,380 INFO  Kname: samba_conf was get. 
2019-01-20 00:11:51,381 INFO  Kname: samba_conf was get. 
2019-01-20 00:11:51,383 INFO  Kname: samba_conf was get. 
2019-01-20 00:11:55,143 WARNING  Department :HRwas deleted. 
2019-01-20 00:11:55,182 WARNING  Department :HR was removed. 
2019-01-20 00:11:55,183 INFO  CONFIGFILE: /data/smb.conf was saved. 
2019-01-20 00:12:10,098 INFO  False 
2019-01-20 00:12:10,164 INFO  Department :HR was added. 
2019-01-20 00:12:10,164 INFO  Kname: comment was set. 
2019-01-20 00:12:10,164 INFO  Kname: valid users was set. 
2019-01-20 00:12:10,164 INFO  CONFIGFILE: /data/smb.conf was saved. 
2019-01-20 00:12:10,208 WARNING  Department :HRwas added. 
2019-01-20 00:12:21,706 INFO  /deploy/ 
2019-01-20 00:16:41,404 INFO  Kname: samba_conf was get. 
2019-01-20 00:16:41,405 INFO  Kname: samba_conf was get. 
2019-01-20 00:16:41,407 INFO  Kname: samba_conf was get. 
2019-01-20 00:16:43,750 WARNING  Department :HRwas deleted. 
2019-01-20 00:16:43,792 WARNING  Department :HR was removed. 
2019-01-20 00:16:43,792 INFO  CONFIGFILE: /data/smb.conf was saved. 
2019-01-20 00:16:58,453 INFO  False 
2019-01-20 00:16:58,512 INFO  Department :HR was added. 
2019-01-20 00:16:58,512 INFO  Kname: comment was set. 
2019-01-20 00:16:58,513 INFO  Kname: valid users was set. 
2019-01-20 00:16:58,513 INFO  CONFIGFILE: /data/smb.conf was saved. 
2019-01-20 00:16:58,559 WARNING  Department :HRwas added. 
2019-01-20 00:17:07,051 ERROR  Internal Server Error: /department/department_add 
Traceback (most recent call last):
  File "/data/django/lib/python2.7/site-packages/django/core/handlers/base.py", line 132, in get_response
    response = wrapped_callback(request, *callback_args, **callback_kwargs)
  File "/code/samba/web/department/views.py", line 44, in dpt_add
    if sa_dpt:
UnboundLocalError: local variable 'sa_dpt' referenced before assignment
2019-01-20 00:17:44,418 ERROR  Usage: groupdel [options] GROUP

Options:
  -h, --help                    display this help message and exit
  -R, --root CHROOT_DIR         directory to chroot into

1
 
2019-01-20 00:22:01,410 INFO  Kname: samba_conf was get. 
2019-01-20 00:22:01,411 INFO  Kname: samba_conf was get. 
2019-01-20 00:22:01,413 INFO  Kname: samba_conf was get. 
2019-01-20 00:22:01,458 ERROR  Usage: groupdel [options] GROUP

Options:
  -h, --help                    display this help message and exit
  -R, --root CHROOT_DIR         directory to chroot into

1
 
2019-01-20 00:22:17,970 INFO  Kname: samba_conf was get. 
2019-01-20 00:22:17,972 INFO  Kname: samba_conf was get. 
2019-01-20 00:22:17,973 INFO  Kname: samba_conf was get. 
2019-01-20 00:22:23,132 ERROR  Usage: groupdel [options] GROUP

Options:
  -h, --help                    display this help message and exit
  -R, --root CHROOT_DIR         directory to chroot into

1
 
2019-01-20 00:23:49,260 INFO  Kname: samba_conf was get. 
2019-01-20 00:23:49,261 INFO  Kname: samba_conf was get. 
2019-01-20 00:23:49,263 INFO  Kname: samba_conf was get. 
2019-01-20 00:24:03,407 INFO  1---------------------------------0 
2019-01-20 00:24:03,678 ERROR  Usage: groupdel [options] GROUP

Options:
  -h, --help                    display this help message and exit
  -R, --root CHROOT_DIR         directory to chroot into

1
 
2019-01-20 00:24:52,742 INFO  Kname: samba_conf was get. 
2019-01-20 00:24:52,744 INFO  Kname: samba_conf was get. 
2019-01-20 00:24:52,752 ERROR  Internal Server Error: /department/ 
Traceback (most recent call last):
  File "/data/django/lib/python2.7/site-packages/django/core/handlers/base.py", line 119, in get_response
    resolver_match = resolver.resolve(request.path_info)
  File "/data/django/lib/python2.7/site-packages/django/core/urlresolvers.py", line 366, in resolve
    for pattern in self.url_patterns:
  File "/data/django/lib/python2.7/site-packages/django/core/urlresolvers.py", line 402, in url_patterns
    patterns = getattr(self.urlconf_module, "urlpatterns", self.urlconf_module)
  File "/data/django/lib/python2.7/site-packages/django/core/urlresolvers.py", line 396, in urlconf_module
    self._urlconf_module = import_module(self.urlconf_name)
  File "/usr/lib64/python2.7/importlib/__init__.py", line 37, in import_module
    __import__(name)
  File "/code/samba/web/web/urls.py", line 18, in <module>
    import dashboard.urls,browse.urls,consumer.urls,deploy.urls,department.urls
  File "/code/samba/web/department/urls.py", line 2, in <module>
    import views
  File "/code/samba/web/department/views.py", line 163
    else if lock == '0':
          ^
SyntaxError: invalid syntax
2019-01-20 00:26:53,640 INFO  Kname: samba_conf was get. 
2019-01-20 00:26:59,436 ERROR  Internal Server Error: /department/department_lock 
Traceback (most recent call last):
  File "/data/django/lib/python2.7/site-packages/django/core/handlers/base.py", line 132, in get_response
    response = wrapped_callback(request, *callback_args, **callback_kwargs)
  File "/code/samba/web/department/views.py", line 164, in dpt_lock
    logger.info(gid+'-----------------------------'+dpt_name+'----'+lock)
TypeError: coercing to Unicode: need string or buffer, int found
2019-01-20 00:29:40,823 INFO  Kname: samba_conf was get. 
2019-01-20 00:29:40,825 INFO  Kname: samba_conf was get. 
2019-01-20 00:29:40,828 INFO  Kname: samba_conf was get. 
2019-01-20 00:29:44,958 INFO  1---------------------------------0 
2019-01-20 00:29:45,017 ERROR  Usage: groupadd [options] GROUP

Options:
  -f, --force                   exit successfully if the group already exists,
                                and cancel -g if the GID is already used
  -g, --gid GID                 use GID for the new group
  -h, --help                    display this help message and exit
  -K, --key KEY=VALUE           override /etc/login.defs defaults
  -o, --non-unique              allow to create groups with duplicate
                                (non-unique) GID
  -p, --password PASSWORD       use this encrypted password for the new group
  -r, --system                  create a system account
  -R, --root CHROOT_DIR         directory to chroot into

1
 
2019-01-20 00:30:12,316 ERROR  Internal Server Error: /department/department_edit 
Traceback (most recent call last):
  File "/data/django/lib/python2.7/site-packages/django/core/handlers/base.py", line 132, in get_response
    response = wrapped_callback(request, *callback_args, **callback_kwargs)
  File "/code/samba/web/department/views.py", line 91, in dpt_edit
    b = Sa_dpt.objects.get(id=gid)
  File "/data/django/lib/python2.7/site-packages/django/db/models/manager.py", line 127, in manager_method
    return getattr(self.get_queryset(), name)(*args, **kwargs)
  File "/data/django/lib/python2.7/site-packages/django/db/models/query.py", line 325, in get
    clone = self.filter(*args, **kwargs)
  File "/data/django/lib/python2.7/site-packages/django/db/models/query.py", line 679, in filter
    return self._filter_or_exclude(False, *args, **kwargs)
  File "/data/django/lib/python2.7/site-packages/django/db/models/query.py", line 697, in _filter_or_exclude
    clone.query.add_q(Q(*args, **kwargs))
  File "/data/django/lib/python2.7/site-packages/django/db/models/sql/query.py", line 1304, in add_q
    clause, require_inner = self._add_q(where_part, self.used_aliases)
  File "/data/django/lib/python2.7/site-packages/django/db/models/sql/query.py", line 1332, in _add_q
    allow_joins=allow_joins, split_subq=split_subq,
  File "/data/django/lib/python2.7/site-packages/django/db/models/sql/query.py", line 1203, in build_filter
    condition = self.build_lookup(lookups, col, value)
  File "/data/django/lib/python2.7/site-packages/django/db/models/sql/query.py", line 1096, in build_lookup
    return final_lookup(lhs, rhs)
  File "/data/django/lib/python2.7/site-packages/django/db/models/lookups.py", line 96, in __init__
    self.rhs = self.get_prep_lookup()
  File "/data/django/lib/python2.7/site-packages/django/db/models/lookups.py", line 134, in get_prep_lookup
    return self.lhs.output_field.get_prep_lookup(self.lookup_name, self.rhs)
  File "/data/django/lib/python2.7/site-packages/django/db/models/fields/__init__.py", line 727, in get_prep_lookup
    return self.get_prep_value(value)
  File "/data/django/lib/python2.7/site-packages/django/db/models/fields/__init__.py", line 985, in get_prep_value
    return int(value)
ValueError: invalid literal for int() with base 10: ''
2019-01-20 00:36:02,365 WARNING  Department :HRwas deleted. 
2019-01-20 00:36:02,410 WARNING  Department :HR was removed. 
2019-01-20 00:36:02,410 INFO  CONFIGFILE: /data/smb.conf was saved. 
2019-01-20 00:36:11,061 INFO  False 
2019-01-20 00:36:11,126 INFO  Department :HR was added. 
2019-01-20 00:36:11,127 INFO  Kname: comment was set. 
2019-01-20 00:36:11,127 INFO  Kname: valid users was set. 
2019-01-20 00:36:11,127 INFO  CONFIGFILE: /data/smb.conf was saved. 
2019-01-20 00:36:11,172 WARNING  Department :HRwas added. 
2019-01-20 00:36:14,478 INFO  /deploy/ 
2019-01-20 00:36:29,265 INFO  /deploy/ 
2019-01-20 00:37:12,398 INFO  /deploy/ 
2019-01-20 00:37:14,028 INFO  /deploy/ 
2019-01-20 01:07:25,180 INFO  Kname: samba_conf was get. 
2019-01-20 01:07:25,182 INFO  Kname: samba_conf was get. 
2019-01-20 01:07:25,184 INFO  Kname: samba_conf was get. 
2019-01-20 01:07:25,197 INFO  invalid literal for int() with base 10: '' 
2019-01-20 01:07:29,933 INFO  /deploy/ 
2019-01-20 01:07:54,550 INFO  /deploy/ 
2019-01-20 01:07:57,782 INFO  /deploy/ 
2019-01-20 01:08:11,128 INFO  1---------------------------------1 
2019-01-20 01:08:11,166 INFO  45---------------------------------1 
2019-01-20 01:08:11,253 ERROR  Usage: groupdel [options] GROUP

Options:
  -h, --help                    display this help message and exit
  -R, --root CHROOT_DIR         directory to chroot into

1
 
2019-01-20 01:08:11,333 ERROR  Usage: groupdel [options] GROUP

Options:
  -h, --help                    display this help message and exit
  -R, --root CHROOT_DIR         directory to chroot into

1
 
2019-01-20 01:08:23,478 INFO  1---------------------------------0 
2019-01-20 01:08:23,520 ERROR  Usage: groupadd [options] GROUP

Options:
  -f, --force                   exit successfully if the group already exists,
                                and cancel -g if the GID is already used
  -g, --gid GID                 use GID for the new group
  -h, --help                    display this help message and exit
  -K, --key KEY=VALUE           override /etc/login.defs defaults
  -o, --non-unique              allow to create groups with duplicate
                                (non-unique) GID
  -p, --password PASSWORD       use this encrypted password for the new group
  -r, --system                  create a system account
  -R, --root CHROOT_DIR         directory to chroot into

1
 
2019-01-20 01:08:27,367 INFO  45---------------------------------0 
2019-01-20 01:08:27,496 ERROR  Usage: groupadd [options] GROUP

Options:
  -f, --force                   exit successfully if the group already exists,
                                and cancel -g if the GID is already used
  -g, --gid GID                 use GID for the new group
  -h, --help                    display this help message and exit
  -K, --key KEY=VALUE           override /etc/login.defs defaults
  -o, --non-unique              allow to create groups with duplicate
                                (non-unique) GID
  -p, --password PASSWORD       use this encrypted password for the new group
  -r, --system                  create a system account
  -R, --root CHROOT_DIR         directory to chroot into

1
 
2019-01-20 01:08:55,068 INFO  /deploy/ 
2019-01-20 01:09:49,388 INFO  /deploy/ 
2019-01-20 01:10:03,239 INFO  False 
2019-01-20 01:10:03,312 INFO  Department :DEV was added. 
2019-01-20 01:10:03,312 INFO  Kname: comment was set. 
2019-01-20 01:10:03,313 INFO  Kname: valid users was set. 
2019-01-20 01:10:03,313 INFO  CONFIGFILE: /data/smb.conf was saved. 
2019-01-20 01:10:03,378 WARNING  Department :DEVwas added. 
2019-01-20 01:10:35,453 INFO  /deploy/ 
2019-01-20 01:10:49,260 INFO  /deploy/ 
2019-01-20 01:10:49,300 WARNING  Not Found: /deploy/set_deploy 
2019-01-20 01:11:43,585 WARNING  Department :DEVwas deleted. 
2019-01-20 01:11:43,628 WARNING  Department :DEV was removed. 
2019-01-20 01:11:43,629 INFO  CONFIGFILE: /data/smb.conf was saved. 
2019-01-20 01:12:04,439 INFO  /deploy/ 
2019-01-20 01:21:29,420 INFO  /deploy/ 
2019-01-20 01:23:14,201 INFO  /deploy/ 
2019-01-20 01:23:15,341 INFO  /deploy/ 
2019-01-20 01:23:37,041 INFO  /deploy/ 
2019-01-20 01:23:37,901 INFO  /deploy/ 
2019-01-20 01:24:06,222 INFO  /deploy/ 
2019-01-20 01:26:38,932 INFO  /deploy/ 
2019-01-20 01:26:43,632 WARNING  Not Found: /deploy/deploy_edit 
2019-01-20 01:26:43,683 INFO  /deploy/ 
2019-01-20 01:39:59,440 INFO  Kname: samba_conf was get. 
2019-01-20 01:39:59,441 INFO  Kname: samba_conf was get. 
2019-01-20 01:39:59,442 INFO  Kname: samba_conf was get. 
2019-01-20 01:39:59,443 INFO  /deploy/ 
2019-01-20 01:41:44,370 INFO  /deploy/ 
2019-01-20 01:41:45,451 INFO  /deploy/ 
2019-01-20 01:42:16,910 INFO  /deploy/ 
2019-01-20 01:42:17,418 INFO  /deploy/ 
2019-01-20 01:42:23,900 INFO  /deploy/ 
2019-01-20 01:46:12,356 INFO  Kname: samba_conf was get. 
2019-01-20 01:46:12,357 INFO  Kname: samba_conf was get. 
2019-01-20 01:46:12,357 INFO  Kname: samba_conf was get. 
2019-01-20 01:46:12,359 INFO  /deploy/ 
2019-01-20 01:46:13,139 INFO  /deploy/ 
2019-01-20 02:00:34,783 INFO  /deploy/ 
2019-01-20 02:10:30,783 INFO  Kname: samba_conf was get. 
2019-01-20 02:10:30,786 INFO  Kname: samba_conf was get. 
2019-01-20 02:10:30,787 INFO  Kname: samba_conf was get. 
2019-01-20 02:10:30,788 INFO  /deploy/ 
2019-01-20 02:10:31,631 INFO  /deploy/ 
2019-01-20 02:10:37,019 ERROR  Internal Server Error: /deploy/deploy_delete 
Traceback (most recent call last):
  File "/data/django/lib/python2.7/site-packages/django/core/handlers/base.py", line 132, in get_response
    response = wrapped_callback(request, *callback_args, **callback_kwargs)
  File "/code/samba/web/deploy/views.py", line 44, in deploy_del
    sconf = confighandler.Config_helper(conf)
NameError: global name 'confighandler' is not defined
2019-01-20 02:10:37,059 INFO  /deploy/ 
2019-01-20 02:11:10,871 INFO  1---------------------------------1 
2019-01-20 02:11:10,916 INFO  45---------------------------------1 
2019-01-20 02:11:10,946 ERROR  Usage: groupdel [options] GROUP

Options:
  -h, --help                    display this help message and exit
  -R, --root CHROOT_DIR         directory to chroot into

1
 
2019-01-20 02:11:10,980 ERROR  Usage: groupdel [options] GROUP

Options:
  -h, --help                    display this help message and exit
  -R, --root CHROOT_DIR         directory to chroot into

1
 
2019-01-20 02:11:18,226 INFO  1---------------------------------0 
2019-01-20 02:11:18,284 ERROR  Usage: groupadd [options] GROUP

Options:
  -f, --force                   exit successfully if the group already exists,
                                and cancel -g if the GID is already used
  -g, --gid GID                 use GID for the new group
  -h, --help                    display this help message and exit
  -K, --key KEY=VALUE           override /etc/login.defs defaults
  -o, --non-unique              allow to create groups with duplicate
                                (non-unique) GID
  -p, --password PASSWORD       use this encrypted password for the new group
  -r, --system                  create a system account
  -R, --root CHROOT_DIR         directory to chroot into

1
 
2019-01-20 02:11:22,918 INFO  45---------------------------------0 
2019-01-20 02:11:22,962 ERROR  Usage: groupadd [options] GROUP

Options:
  -f, --force                   exit successfully if the group already exists,
                                and cancel -g if the GID is already used
  -g, --gid GID                 use GID for the new group
  -h, --help                    display this help message and exit
  -K, --key KEY=VALUE           override /etc/login.defs defaults
  -o, --non-unique              allow to create groups with duplicate
                                (non-unique) GID
  -p, --password PASSWORD       use this encrypted password for the new group
  -r, --system                  create a system account
  -R, --root CHROOT_DIR         directory to chroot into

1
 
2019-01-20 02:12:30,511 INFO  /deploy/ 
2019-01-20 02:12:33,951 INFO  /deploy/ 
2019-01-20 02:13:07,140 INFO  /deploy/ 
2019-01-20 02:13:11,350 INFO  /deploy/ 
2019-01-20 02:13:19,671 INFO  /deploy/ 
2019-01-20 02:13:21,710 INFO  /deploy/ 
2019-01-20 02:13:30,859 INFO  /deploy/ 
2019-01-20 02:13:45,319 INFO  /deploy/ 
2019-01-20 02:13:57,160 INFO  /deploy/ 
2019-01-20 02:13:58,990 INFO  /deploy/ 
2019-01-20 02:14:04,511 INFO  /deploy/ 
2019-01-20 02:15:07,711 INFO  /deploy/ 
2019-01-20 02:15:09,391 INFO  /deploy/ 
2019-01-20 02:15:23,962 INFO  /deploy/ 
2019-01-20 02:15:49,161 WARNING  Not Found: /favicon.ico 
2019-01-20 02:16:00,513 INFO  False 
2019-01-20 02:16:00,578 INFO  Department :DEV was added. 
2019-01-20 02:16:00,578 INFO  Kname: comment was set. 
2019-01-20 02:16:00,578 INFO  Kname: valid users was set. 
2019-01-20 02:16:00,578 INFO  CONFIGFILE: /data/smb.conf was saved. 
2019-01-20 02:16:00,619 WARNING  Department :DEVwas added. 
2019-01-20 02:16:07,501 INFO  /deploy/ 
2019-01-24 19:44:51,367 INFO  Kname: samba_conf was get. 
2019-01-24 19:44:51,409 INFO  Kname: samba_conf was get. 
2019-01-24 19:44:51,421 INFO  Kname: samba_conf was get. 
2019-01-24 19:44:57,398 WARNING  Not Found: /favicon.ico 
2019-01-24 19:45:10,568 INFO  47---------------------------------1 
2019-01-24 19:45:10,609 ERROR  Usage: groupdel [options] GROUP

Options:
  -h, --help                    display this help message and exit
  -R, --root CHROOT_DIR         directory to chroot into

1
 
2019-01-24 19:45:17,638 INFO  47---------------------------------0 
2019-01-24 19:45:17,663 ERROR  Usage: groupadd [options] GROUP

Options:
  -f, --force                   exit successfully if the group already exists,
                                and cancel -g if the GID is already used
  -g, --gid GID                 use GID for the new group
  -h, --help                    display this help message and exit
  -K, --key KEY=VALUE           override /etc/login.defs defaults
  -o, --non-unique              allow to create groups with duplicate
                                (non-unique) GID
  -p, --password PASSWORD       use this encrypted password for the new group
  -r, --system                  create a system account
  -R, --root CHROOT_DIR         directory to chroot into

1
 
2019-01-24 19:45:36,902 INFO  /deploy/ 
2019-01-24 19:46:20,957 INFO  /deploy/ 
2019-01-24 19:46:21,208 ERROR  Internal Server Error: /deploy/deploy_edit 
Traceback (most recent call last):
  File "/data/django/lib/python2.7/site-packages/django/core/handlers/base.py", line 132, in get_response
    response = wrapped_callback(request, *callback_args, **callback_kwargs)
  File "/code/samba/web/deploy/views.py", line 59, in deploy_edit
    sconf = confighandler.Config_helper(conf)
NameError: global name 'confighandler' is not defined
2019-01-24 19:46:44,682 INFO  /deploy/ 
2019-01-24 19:46:44,898 ERROR  Internal Server Error: /deploy/deploy_edit 
Traceback (most recent call last):
  File "/data/django/lib/python2.7/site-packages/django/core/handlers/base.py", line 132, in get_response
    response = wrapped_callback(request, *callback_args, **callback_kwargs)
  File "/code/samba/web/deploy/views.py", line 59, in deploy_edit
    sconf = confighandler.Config_helper(conf)
NameError: global name 'confighandler' is not defined
2019-01-24 19:53:58,296 INFO  Kname: samba_conf was get. 
2019-01-24 19:53:58,299 INFO  Kname: samba_conf was get. 
2019-01-24 19:53:58,300 INFO  Kname: samba_conf was get. 
2019-01-24 19:53:58,302 INFO  /deploy/ 
2019-01-24 20:13:17,674 INFO  /deploy/ 
2019-01-24 20:23:57,494 INFO  /deploy/ 
2019-01-24 20:23:57,536 ERROR  Internal Server Error: /deploy/deploy_delete 
Traceback (most recent call last):
  File "/data/django/lib/python2.7/site-packages/django/core/handlers/base.py", line 132, in get_response
    response = wrapped_callback(request, *callback_args, **callback_kwargs)
  File "/code/samba/web/deploy/views.py", line 46, in deploy_del
    b = Sa_deploy.objects.get(id=sid)
  File "/data/django/lib/python2.7/site-packages/django/db/models/manager.py", line 127, in manager_method
    return getattr(self.get_queryset(), name)(*args, **kwargs)
  File "/data/django/lib/python2.7/site-packages/django/db/models/query.py", line 325, in get
    clone = self.filter(*args, **kwargs)
  File "/data/django/lib/python2.7/site-packages/django/db/models/query.py", line 679, in filter
    return self._filter_or_exclude(False, *args, **kwargs)
  File "/data/django/lib/python2.7/site-packages/django/db/models/query.py", line 697, in _filter_or_exclude
    clone.query.add_q(Q(*args, **kwargs))
  File "/data/django/lib/python2.7/site-packages/django/db/models/sql/query.py", line 1304, in add_q
    clause, require_inner = self._add_q(where_part, self.used_aliases)
  File "/data/django/lib/python2.7/site-packages/django/db/models/sql/query.py", line 1332, in _add_q
    allow_joins=allow_joins, split_subq=split_subq,
  File "/data/django/lib/python2.7/site-packages/django/db/models/sql/query.py", line 1203, in build_filter
    condition = self.build_lookup(lookups, col, value)
  File "/data/django/lib/python2.7/site-packages/django/db/models/sql/query.py", line 1096, in build_lookup
    return final_lookup(lhs, rhs)
  File "/data/django/lib/python2.7/site-packages/django/db/models/lookups.py", line 96, in __init__
    self.rhs = self.get_prep_lookup()
  File "/data/django/lib/python2.7/site-packages/django/db/models/lookups.py", line 134, in get_prep_lookup
    return self.lhs.output_field.get_prep_lookup(self.lookup_name, self.rhs)
  File "/data/django/lib/python2.7/site-packages/django/db/models/fields/__init__.py", line 727, in get_prep_lookup
    return self.get_prep_value(value)
  File "/data/django/lib/python2.7/site-packages/django/db/models/fields/__init__.py", line 985, in get_prep_value
    return int(value)
UnicodeEncodeError: 'decimal' codec can't encode characters in position 0-2: invalid decimal Unicode string
2019-01-24 20:23:59,782 INFO  /deploy/ 
2019-01-24 20:27:04,374 INFO  Kname: samba_conf was get. 
2019-01-24 20:27:04,377 INFO  Kname: samba_conf was get. 
2019-01-24 20:27:04,378 INFO  Kname: samba_conf was get. 
2019-01-24 20:27:04,380 INFO  /deploy/ 
2019-01-24 20:27:09,349 ERROR  Internal Server Error: /deploy/deploy_delete 
Traceback (most recent call last):
  File "/data/django/lib/python2.7/site-packages/django/core/handlers/base.py", line 132, in get_response
    response = wrapped_callback(request, *callback_args, **callback_kwargs)
  File "/code/samba/web/deploy/views.py", line 46, in deploy_del
    b = Sa_deploy.objects.get(key_name=key)
  File "/data/django/lib/python2.7/site-packages/django/db/models/manager.py", line 127, in manager_method
    return getattr(self.get_queryset(), name)(*args, **kwargs)
  File "/data/django/lib/python2.7/site-packages/django/db/models/query.py", line 338, in get
    (self.model._meta.object_name, num)
MultipleObjectsReturned: get() returned more than one Sa_deploy -- it returned 2!
2019-01-24 20:27:09,385 INFO  /deploy/ 
2019-01-24 20:27:12,628 INFO  /deploy/ 
2019-01-24 20:30:34,803 INFO  /deploy/ 
2019-01-24 20:30:38,672 ERROR  Internal Server Error: /deploy/deploy_delete 
Traceback (most recent call last):
  File "/data/django/lib/python2.7/site-packages/django/core/handlers/base.py", line 132, in get_response
    response = wrapped_callback(request, *callback_args, **callback_kwargs)
  File "/code/samba/web/deploy/views.py", line 46, in deploy_del
    b = Sa_deploy.objects.get(key_name=key)
  File "/data/django/lib/python2.7/site-packages/django/db/models/manager.py", line 127, in manager_method
    return getattr(self.get_queryset(), name)(*args, **kwargs)
  File "/data/django/lib/python2.7/site-packages/django/db/models/query.py", line 338, in get
    (self.model._meta.object_name, num)
MultipleObjectsReturned: get() returned more than one Sa_deploy -- it returned 2!
2019-01-24 20:30:38,709 INFO  /deploy/ 
2019-01-24 20:32:10,783 INFO  Kname: samba_conf was get. 
2019-01-24 20:32:10,786 INFO  Kname: samba_conf was get. 
2019-01-24 20:32:10,786 INFO  Kname: samba_conf was get. 
2019-01-24 20:32:10,788 INFO  /deploy/ 
2019-01-24 20:32:18,347 WARNING  Keyname:comment was removed. 
2019-01-24 20:32:18,347 INFO  CONFIGFILE: /data/smb.conf was saved. 
2019-01-24 20:32:18,348 ERROR  Internal Server Error: /deploy/deploy_delete 
Traceback (most recent call last):
  File "/data/django/lib/python2.7/site-packages/django/core/handlers/base.py", line 132, in get_response
    response = wrapped_callback(request, *callback_args, **callback_kwargs)
  File "/code/samba/web/deploy/views.py", line 50, in deploy_del
    return JsonResponse({'delete':True})
NameError: global name 'JsonResponse' is not defined
2019-01-24 20:32:18,375 INFO  /deploy/ 
2019-01-24 20:33:37,906 INFO  Kname: samba_conf was get. 
2019-01-24 20:33:37,909 INFO  Kname: samba_conf was get. 
2019-01-24 20:33:37,910 INFO  Kname: samba_conf was get. 
2019-01-24 20:33:37,911 INFO  /deploy/ 
2019-01-24 20:34:46,031 INFO  /deploy/ 
2019-01-24 20:34:46,066 WARNING  Keyname:comment was removed. 
2019-01-24 20:34:46,066 INFO  CONFIGFILE: /data/smb.conf was saved. 
2019-01-24 20:34:48,291 INFO  /deploy/ 
2019-01-24 20:35:11,766 INFO  /deploy/ 
2019-01-24 20:35:11,774 ERROR  Internal Server Error: /deploy/deploy_edit 
Traceback (most recent call last):
  File "/data/django/lib/python2.7/site-packages/django/core/handlers/base.py", line 132, in get_response
    response = wrapped_callback(request, *callback_args, **callback_kwargs)
  File "/code/samba/web/deploy/views.py", line 60, in deploy_edit
    sconf = confighandler.Config_helper(conf)
NameError: global name 'confighandler' is not defined
2019-01-24 20:35:13,565 INFO  /deploy/ 
2019-01-24 20:36:05,163 INFO  Kname: samba_conf was get. 
2019-01-24 20:36:05,165 INFO  Kname: samba_conf was get. 
2019-01-24 20:36:05,165 INFO  Kname: samba_conf was get. 
2019-01-24 20:36:05,167 INFO  /deploy/ 
2019-01-24 20:36:12,899 ERROR  Internal Server Error: /deploy/deploy_edit 
Traceback (most recent call last):
  File "/data/django/lib/python2.7/site-packages/django/core/handlers/base.py", line 132, in get_response
    response = wrapped_callback(request, *callback_args, **callback_kwargs)
  File "/code/samba/web/deploy/views.py", line 60, in deploy_edit
    sconf = confighandler.Config_helper(conf)
NameError: global name 'confighandler' is not defined
2019-01-24 20:36:12,988 INFO  /deploy/ 
2019-01-24 20:38:13,682 INFO  Kname: samba_conf was get. 
2019-01-24 20:38:13,684 INFO  Kname: samba_conf was get. 
2019-01-24 20:38:13,685 INFO  Kname: samba_conf was get. 
2019-01-24 20:38:13,687 INFO  /deploy/ 
2019-01-24 20:38:20,104 ERROR  Internal Server Error: /deploy/deploy_edit 
Traceback (most recent call last):
  File "/data/django/lib/python2.7/site-packages/django/core/handlers/base.py", line 132, in get_response
    response = wrapped_callback(request, *callback_args, **callback_kwargs)
  File "/code/samba/web/deploy/views.py", line 60, in deploy_edit
    sconf = confighandler.Config_helper(conf)
NameError: global name 'confighandler' is not defined
2019-01-24 20:38:20,365 INFO  /deploy/ 
2019-01-24 20:39:32,525 INFO  Kname: samba_conf was get. 
2019-01-24 20:39:32,527 INFO  Kname: samba_conf was get. 
2019-01-24 20:39:32,528 INFO  Kname: samba_conf was get. 
2019-01-24 20:39:32,529 INFO  /deploy/ 
2019-01-24 20:39:40,860 ERROR  Internal Server Error: /deploy/deploy_edit 
Traceback (most recent call last):
  File "/data/django/lib/python2.7/site-packages/django/core/handlers/base.py", line 132, in get_response
    response = wrapped_callback(request, *callback_args, **callback_kwargs)
  File "/code/samba/web/deploy/views.py", line 62, in deploy_edit
    b = Sa_deploy.objects.get(id=sid)
NameError: global name 'sid' is not defined
2019-01-24 20:39:40,901 INFO  /deploy/ 
2019-01-24 20:49:40,634 INFO  Kname: samba_conf was get. 
2019-01-24 20:49:40,644 INFO  Kname: samba_conf was get. 
2019-01-24 20:49:40,645 INFO  Kname: samba_conf was get. 
2019-01-24 20:49:40,646 INFO  /deploy/ 
2019-01-24 20:49:52,469 INFO  /deploy/ 
2019-01-24 20:49:52,479 ERROR  Internal Server Error: /deploy/deploy_edit 
Traceback (most recent call last):
  File "/data/django/lib/python2.7/site-packages/django/core/handlers/base.py", line 132, in get_response
    response = wrapped_callback(request, *callback_args, **callback_kwargs)
  File "/code/samba/web/deploy/views.py", line 62, in deploy_edit
    b = Sa_deploy.objects.get(key_name=key,section_name=section)
  File "/data/django/lib/python2.7/site-packages/django/db/models/manager.py", line 127, in manager_method
    return getattr(self.get_queryset(), name)(*args, **kwargs)
  File "/data/django/lib/python2.7/site-packages/django/db/models/query.py", line 334, in get
    self.model._meta.object_name
DoesNotExist: Sa_deploy matching query does not exist.
2019-01-24 20:49:55,682 INFO  /deploy/ 
2019-01-24 20:51:42,604 INFO  /deploy/ 
2019-01-24 20:51:42,614 ERROR  Internal Server Error: /deploy/deploy_edit 
Traceback (most recent call last):
  File "/data/django/lib/python2.7/site-packages/django/core/handlers/base.py", line 132, in get_response
    response = wrapped_callback(request, *callback_args, **callback_kwargs)
  File "/code/samba/web/deploy/views.py", line 62, in deploy_edit
    b = Sa_deploy.objects.get(key_name=key,section_name=section)
  File "/data/django/lib/python2.7/site-packages/django/db/models/manager.py", line 127, in manager_method
    return getattr(self.get_queryset(), name)(*args, **kwargs)
  File "/data/django/lib/python2.7/site-packages/django/db/models/query.py", line 334, in get
    self.model._meta.object_name
DoesNotExist: Sa_deploy matching query does not exist.
2019-01-24 21:12:00,410 INFO  Kname: samba_conf was get. 
2019-01-24 21:12:00,413 INFO  Kname: samba_conf was get. 
2019-01-24 21:12:00,413 INFO  Kname: samba_conf was get. 
2019-01-24 21:12:00,415 INFO  /deploy/ 
2019-01-24 21:12:07,270 ERROR  Internal Server Error: /deploy/deploy_edit 
Traceback (most recent call last):
  File "/data/django/lib/python2.7/site-packages/django/core/handlers/base.py", line 132, in get_response
    response = wrapped_callback(request, *callback_args, **callback_kwargs)
  File "/code/samba/web/deploy/views.py", line 71, in deploy_edit
    sconf.set(section,key,value)
  File "/usr/lib64/python2.7/ConfigParser.py", line 394, in set
    sectdict = self._sections[section]
AttributeError: Config_helper instance has no attribute '_sections'
2019-01-24 21:12:07,322 INFO  /deploy/ 
2019-01-24 21:17:58,874 INFO  Kname: samba_conf was get. 
2019-01-24 21:17:58,876 INFO  Kname: samba_conf was get. 
2019-01-24 21:17:58,877 INFO  Kname: samba_conf was get. 
2019-01-24 21:17:58,879 INFO  /deploy/ 
2019-01-24 21:18:05,059 ERROR  Internal Server Error: /deploy/deploy_edit 
Traceback (most recent call last):
  File "/data/django/lib/python2.7/site-packages/django/core/handlers/base.py", line 132, in get_response
    response = wrapped_callback(request, *callback_args, **callback_kwargs)
  File "/code/samba/web/deploy/views.py", line 72, in deploy_edit
    sconf.set(section,key,value)
  File "/usr/lib64/python2.7/ConfigParser.py", line 394, in set
    sectdict = self._sections[section]
AttributeError: Config_helper instance has no attribute '_sections'
2019-01-24 21:18:05,115 INFO  /deploy/ 
2019-01-24 21:21:24,863 INFO  /deploy/ 
2019-01-24 21:21:27,602 INFO  /deploy/ 
2019-01-24 21:23:27,773 INFO  Kname: samba_conf was get. 
2019-01-24 21:23:27,775 INFO  Kname: samba_conf was get. 
2019-01-24 21:23:27,775 INFO  Kname: samba_conf was get. 
2019-01-24 21:23:27,777 INFO  /deploy/ 
2019-01-24 21:23:35,230 ERROR  Internal Server Error: /deploy/deploy_edit 
Traceback (most recent call last):
  File "/data/django/lib/python2.7/site-packages/django/core/handlers/base.py", line 132, in get_response
    response = wrapped_callback(request, *callback_args, **callback_kwargs)
  File "/code/samba/web/deploy/views.py", line 73, in deploy_edit
    sconf.set(section,key,value)
  File "/usr/lib64/python2.7/ConfigParser.py", line 394, in set
    sectdict = self._sections[section]
AttributeError: Config_helper instance has no attribute '_sections'
2019-01-24 21:23:35,264 INFO  /deploy/ 
2019-01-24 21:25:17,629 INFO  /deploy/ 
2019-01-24 21:35:47,686 INFO  Kname: samba_conf was get. 
2019-01-24 21:35:47,688 INFO  Kname: samba_conf was get. 
2019-01-24 21:35:47,689 INFO  Kname: samba_conf was get. 
2019-01-24 21:35:47,690 INFO  /deploy/ 
2019-01-24 21:35:59,623 INFO  /deploy/ 
2019-01-24 21:35:59,831 INFO  Kname: comment was set. 
2019-01-24 21:35:59,831 INFO  CONFIGFILE: /data/smb.conf was saved. 
2019-01-24 21:35:59,832 ERROR  Internal Server Error: /deploy/deploy_edit 
Traceback (most recent call last):
  File "/data/django/lib/python2.7/site-packages/django/core/handlers/base.py", line 132, in get_response
    response = wrapped_callback(request, *callback_args, **callback_kwargs)
  File "/code/samba/web/deploy/views.py", line 75, in deploy_edit
    return JsonResponse(json.dumps({'change':True}))
NameError: global name 'json' is not defined
2019-01-24 21:36:05,852 INFO  /deploy/ 
2019-01-24 21:36:07,062 INFO  /deploy/ 
2019-01-24 21:37:04,866 INFO  Kname: samba_conf was get. 
2019-01-24 21:37:04,869 INFO  Kname: samba_conf was get. 
2019-01-24 21:37:04,870 INFO  Kname: samba_conf was get. 
2019-01-24 21:37:04,871 INFO  /deploy/ 
2019-01-24 21:37:11,586 INFO  Kname: comment was set. 
2019-01-24 21:37:11,587 INFO  CONFIGFILE: /data/smb.conf was saved. 
2019-01-24 21:37:11,762 INFO  /deploy/ 
2019-01-24 21:37:13,987 INFO  /deploy/ 
2019-01-24 21:39:38,944 INFO  Kname: samba_conf was get. 
2019-01-24 21:39:38,946 INFO  Kname: samba_conf was get. 
2019-01-24 21:39:38,947 INFO  Kname: samba_conf was get. 
2019-01-24 21:39:38,948 INFO  /deploy/ 
2019-01-24 21:39:44,690 INFO  Kname: comment was set. 
2019-01-24 21:39:44,690 INFO  CONFIGFILE: /data/smb.conf was saved. 
2019-01-24 21:39:44,709 INFO  /deploy/ 
2019-01-24 21:39:46,479 INFO  /deploy/ 
2019-01-24 21:39:58,247 INFO  /deploy/ 
2019-01-24 21:39:58,291 ERROR  No section: u'IT' 
2019-01-24 21:39:58,292 INFO  CONFIGFILE: /data/smb.conf was saved. 
2019-01-24 21:39:59,974 INFO  /deploy/ 
2019-01-24 21:40:01,722 INFO  /deploy/ 
2019-01-24 21:40:05,784 WARNING  Keyname:comment was removed. 
2019-01-24 21:40:05,785 INFO  CONFIGFILE: /data/smb.conf was saved. 
2019-01-24 21:40:05,808 INFO  /deploy/ 
2019-01-24 21:40:07,360 INFO  /deploy/ 
2019-01-24 21:40:11,030 ERROR  No section: u'IT' 
2019-01-24 21:40:11,030 INFO  CONFIGFILE: /data/smb.conf was saved. 
2019-01-24 21:40:11,057 INFO  /deploy/ 
2019-01-24 21:40:12,515 INFO  /deploy/ 
2019-01-24 21:40:20,262 INFO  /deploy/ 
2019-01-24 21:40:20,488 INFO  Kname: comment was set. 
2019-01-24 21:40:20,488 INFO  CONFIGFILE: /data/smb.conf was saved. 
2019-01-24 21:40:58,666 INFO  /deploy/ 
2019-01-24 21:41:00,903 INFO  /deploy/ 
2019-01-24 21:41:17,663 INFO  /deploy/ 
2019-01-24 21:41:17,703 INFO  Kname: comment was set. 
2019-01-24 21:41:17,704 INFO  CONFIGFILE: /data/smb.conf was saved. 
2019-01-24 21:41:19,424 INFO  /deploy/ 
2019-01-24 21:41:45,439 INFO  /deploy/ 
2019-01-24 21:41:45,470 INFO  Kname: comment was set. 
2019-01-24 21:41:45,471 INFO  CONFIGFILE: /data/smb.conf was saved. 
2019-01-24 21:42:11,654 INFO  /deploy/ 
2019-01-24 21:42:30,533 INFO  /deploy/ 
2019-01-24 21:42:31,091 ERROR  No section: u'IT' 
2019-01-24 21:42:31,091 INFO  CONFIGFILE: /data/smb.conf was saved. 
2019-01-24 21:42:47,674 INFO  /deploy/ 
2019-01-24 21:42:48,261 ERROR  No section: u'IT' 
2019-01-24 21:42:48,262 INFO  CONFIGFILE: /data/smb.conf was saved. 
2019-01-24 21:44:44,522 INFO  /deploy/ 
2019-01-24 21:45:36,513 WARNING  Not Found: /favicon.ico 
2019-01-24 21:45:39,964 WARNING  Not Found: /favicon.ico 
2019-01-24 21:48:25,723 INFO  1---------------------------------1 
2019-01-24 21:48:25,751 ERROR  Usage: groupdel [options] GROUP

Options:
  -h, --help                    display this help message and exit
  -R, --root CHROOT_DIR         directory to chroot into

1
 
2019-01-24 21:48:25,772 INFO  45---------------------------------1 
2019-01-24 21:48:25,775 INFO  47---------------------------------1 
2019-01-24 21:48:25,801 ERROR  Usage: groupdel [options] GROUP

Options:
  -h, --help                    display this help message and exit
  -R, --root CHROOT_DIR         directory to chroot into

1
 
2019-01-24 21:48:25,825 ERROR  Usage: groupdel [options] GROUP

Options:
  -h, --help                    display this help message and exit
  -R, --root CHROOT_DIR         directory to chroot into

1
 
2019-01-24 21:48:33,358 INFO  1---------------------------------0 
2019-01-24 21:48:33,387 ERROR  Usage: groupadd [options] GROUP

Options:
  -f, --force                   exit successfully if the group already exists,
                                and cancel -g if the GID is already used
  -g, --gid GID                 use GID for the new group
  -h, --help                    display this help message and exit
  -K, --key KEY=VALUE           override /etc/login.defs defaults
  -o, --non-unique              allow to create groups with duplicate
                                (non-unique) GID
  -p, --password PASSWORD       use this encrypted password for the new group
  -r, --system                  create a system account
  -R, --root CHROOT_DIR         directory to chroot into

1
 
2019-01-24 21:48:36,758 INFO  45---------------------------------0 
2019-01-24 21:48:36,793 ERROR  Usage: groupadd [options] GROUP

Options:
  -f, --force                   exit successfully if the group already exists,
                                and cancel -g if the GID is already used
  -g, --gid GID                 use GID for the new group
  -h, --help                    display this help message and exit
  -K, --key KEY=VALUE           override /etc/login.defs defaults
  -o, --non-unique              allow to create groups with duplicate
                                (non-unique) GID
  -p, --password PASSWORD       use this encrypted password for the new group
  -r, --system                  create a system account
  -R, --root CHROOT_DIR         directory to chroot into

1
 
2019-01-24 21:48:39,732 INFO  47---------------------------------0 
2019-01-24 21:48:39,812 ERROR  Usage: groupadd [options] GROUP

Options:
  -f, --force                   exit successfully if the group already exists,
                                and cancel -g if the GID is already used
  -g, --gid GID                 use GID for the new group
  -h, --help                    display this help message and exit
  -K, --key KEY=VALUE           override /etc/login.defs defaults
  -o, --non-unique              allow to create groups with duplicate
                                (non-unique) GID
  -p, --password PASSWORD       use this encrypted password for the new group
  -r, --system                  create a system account
  -R, --root CHROOT_DIR         directory to chroot into

1
 
2019-01-24 21:49:26,377 WARNING  Not Found: /favicon.ico 
2019-01-24 21:49:27,992 WARNING  Not Found: /favicon.ico 
2019-01-24 21:49:28,916 INFO  /deploy/ 
2019-01-24 21:49:29,219 WARNING  Not Found: /favicon.ico 
2019-01-24 21:49:33,811 INFO  /deploy/ 
2019-01-24 21:54:39,439 INFO  /deploy/ 
2019-01-24 21:55:03,012 ERROR  groupdel: group 'IT' does not exist
1
 
2019-01-24 21:55:03,060 WARNING  Department :IT was removed. 
2019-01-24 21:55:03,061 INFO  CONFIGFILE: /data/smb.conf was saved. 
2019-01-24 21:55:07,477 INFO  /deploy/ 
2019-01-24 21:55:14,189 WARNING  Department :DEVwas deleted. 
2019-01-24 21:55:14,261 WARNING  Department :DEV was removed. 
2019-01-24 21:55:14,261 INFO  CONFIGFILE: /data/smb.conf was saved. 
2019-01-24 21:55:16,009 INFO  /deploy/ 
2019-01-24 21:57:57,191 WARNING  Not Found: /favicon.ico 
2019-01-24 21:58:03,933 INFO  /deploy/ 
2019-01-24 21:58:33,748 INFO  /deploy/ 
2019-01-24 21:58:35,659 INFO  /deploy/ 
2019-01-24 21:58:38,235 INFO  /deploy/ 
2019-01-24 21:59:33,475 INFO  /deploy/ 
2019-01-24 21:59:35,826 INFO  /deploy/ 
2019-01-24 21:59:37,085 INFO  /deploy/ 
2019-01-24 21:59:38,116 INFO  /deploy/ 
2019-01-24 22:01:27,127 WARNING  Not Found: /favicon.ico 
2019-01-24 22:01:57,323 ERROR  Internal Server Error: /department/department_add 
Traceback (most recent call last):
  File "/data/django/lib/python2.7/site-packages/django/core/handlers/base.py", line 132, in get_response
    response = wrapped_callback(request, *callback_args, **callback_kwargs)
  File "/code/samba/web/department/views.py", line 44, in dpt_add
    if sa_dpt:
UnboundLocalError: local variable 'sa_dpt' referenced before assignment
2019-01-24 22:02:23,685 INFO  False 
2019-01-24 22:02:23,780 INFO  Department :IT was added. 
2019-01-24 22:02:23,781 INFO  Kname: comment was set. 
2019-01-24 22:02:23,781 INFO  Kname: valid users was set. 
2019-01-24 22:02:23,781 INFO  CONFIGFILE: /data/smb.conf was saved. 
2019-01-24 22:02:23,856 WARNING  Department :ITwas added. 
2019-01-24 22:02:34,329 INFO  /deploy/ 
2019-01-24 22:03:11,415 INFO  /deploy/ 
2019-01-24 22:03:34,524 INFO  /deploy/ 
2019-01-24 22:10:22,271 INFO  Kname: samba_conf was get. 
2019-01-24 22:10:22,272 INFO  Kname: samba_conf was get. 
2019-01-24 22:10:22,273 INFO  Kname: samba_conf was get. 
2019-01-24 22:10:23,256 INFO  /deploy/ 
2019-01-24 22:11:56,137 INFO  /deploy/ 
2019-01-24 22:14:26,163 WARNING  Not Found: /favicon.ico 
2019-01-24 22:17:08,269 WARNING  Not Found: /favicon.ico 
2019-01-24 22:17:13,759 INFO  /deploy/ 
2019-01-24 22:17:19,990 INFO  /deploy/ 
2019-01-24 22:22:49,478 INFO  /deploy/ 
2019-01-24 22:26:40,675 WARNING  Department :HRwas deleted. 
2019-01-24 22:26:40,714 WARNING  Department :HR was removed. 
2019-01-24 22:26:40,715 INFO  CONFIGFILE: /data/smb.conf was saved. 
2019-01-24 22:26:43,629 INFO  /deploy/ 
2019-01-24 22:26:49,796 WARNING  Department :ITwas deleted. 
2019-01-24 22:26:49,839 WARNING  Department :IT was removed. 
2019-01-24 22:26:49,840 INFO  CONFIGFILE: /data/smb.conf was saved. 
2019-01-24 22:26:51,113 INFO  /deploy/ 
2019-01-24 22:27:00,599 INFO  /deploy/ 
2019-01-24 22:27:09,938 INFO  /deploy/ 
2019-01-24 22:27:17,051 INFO  False 
2019-01-24 22:27:17,113 INFO  Department :HR was added. 
2019-01-24 22:27:17,113 INFO  Kname: comment was set. 
2019-01-24 22:27:17,113 INFO  Kname: valid users was set. 
2019-01-24 22:27:17,114 INFO  CONFIGFILE: /data/smb.conf was saved. 
2019-01-24 22:27:17,157 WARNING  Department :HRwas added. 
2019-01-24 22:27:19,289 INFO  /deploy/ 
2019-01-24 22:27:23,957 WARNING  Department :HRwas deleted. 
2019-01-24 22:27:24,003 WARNING  Department :HR was removed. 
2019-01-24 22:27:24,003 INFO  CONFIGFILE: /data/smb.conf was saved. 
2019-01-24 22:27:25,208 INFO  /deploy/ 
2019-01-24 22:27:27,128 INFO  /deploy/ 
2019-01-24 22:30:26,890 INFO  /deploy/ 
2019-01-24 22:30:36,451 INFO  False 
2019-01-24 22:30:36,802 INFO  Department :HR was added. 
2019-01-24 22:30:36,802 INFO  Kname: comment was set. 
2019-01-24 22:30:36,802 INFO  Kname: valid users was set. 
2019-01-24 22:30:36,803 INFO  CONFIGFILE: /data/smb.conf was saved. 
2019-01-24 22:30:36,859 WARNING  Department :HRwas added. 
2019-01-24 22:30:38,319 INFO  /deploy/ 
2019-01-24 22:31:37,194 INFO  Kname: samba_conf was get. 
2019-01-24 22:31:37,195 INFO  Kname: samba_conf was get. 
2019-01-24 22:31:37,196 INFO  Kname: samba_conf was get. 
2019-01-24 22:31:39,349 INFO  /deploy/ 
2019-01-24 22:33:50,091 ERROR  userdel: user 'Jerry' does not exist
1
 
2019-01-24 22:33:50,099 ERROR  1
 
2019-01-24 22:33:51,427 ERROR  user Jerry does not exist in the passdb
1
 
2019-01-24 22:33:55,390 ERROR  userdel: user 'Marry' does not exist
1
 
2019-01-24 22:33:55,396 ERROR  1
 
2019-01-24 22:33:55,421 ERROR  user Marry does not exist in the passdb
1
 
2019-01-24 22:34:16,815 INFO  USER wangbo1was add to db. 
2019-01-24 22:34:16,925 INFO  User was created. 
2019-01-24 22:34:17,701 INFO  SAMBA USER:wangbo1was added. 
2019-01-24 22:34:41,489 ERROR  userdel: user 'Tom' does not exist
1
 
2019-01-24 22:34:41,494 ERROR  1
 
2019-01-24 22:34:41,521 ERROR  user Tom does not exist in the passdb
1
 
<<<<<<< HEAD
2019-01-15 20:19:49,785 INFO  SAMBA USER:wangbo1  was deleted. 
2019-01-15 20:54:35,212 INFO  Kname: samba_conf was get. 
2019-01-15 20:54:35,215 INFO  Kname: samba_conf was get. 
2019-01-15 20:54:35,215 INFO  Kname: samba_conf was get. 
2019-01-15 20:54:58,466 INFO  USER wangbo1was add to db. 
2019-01-15 20:54:58,542 INFO  User was created. 
2019-01-15 20:54:59,045 INFO  SAMBA USER:wangbo1was added. 
2019-01-15 20:54:59,047 ERROR  Internal Server Error: /consumer/add_user 
Traceback (most recent call last):
  File "/data/django/lib/python2.7/site-packages/django/core/handlers/base.py", line 132, in get_response
    response = wrapped_callback(request, *callback_args, **callback_kwargs)
  File "/code/samba/web/consumer/views.py", line 49, in add_user
    return JsonResponse(json.dumps({"success":True}))
  File "/data/django/lib/python2.7/site-packages/django/http/response.py", line 532, in __init__
    raise TypeError('In order to allow non-dict objects to be '
TypeError: In order to allow non-dict objects to be serialized set the safe parameter to False
2019-01-15 20:55:11,836 ERROR  Internal Server Error: /consumer/reset_pwd 
Traceback (most recent call last):
  File "/data/django/lib/python2.7/site-packages/django/core/handlers/base.py", line 132, in get_response
    response = wrapped_callback(request, *callback_args, **callback_kwargs)
  File "/code/samba/web/consumer/views.py", line 76, in reset_pwd
    wsuser.wsuser(name).wudel()
NameError: global name 'name' is not defined
2019-01-15 20:59:40,041 INFO  Kname: samba_conf was get. 
2019-01-15 20:59:40,045 INFO  Kname: samba_conf was get. 
2019-01-15 20:59:40,045 INFO  Kname: samba_conf was get. 
2019-01-15 20:59:49,507 INFO  SAMBA USER:wangbo1  was deleted. 
2019-01-15 20:59:49,589 INFO  SAMBA USER:wangbo1was added. 
2019-01-15 20:59:49,632 INFO  SAMBA USER:wangbo1was enabled. 
2019-01-15 20:59:49,655 ERROR  Internal Server Error: /consumer/reset_pwd 
Traceback (most recent call last):
  File "/data/django/lib/python2.7/site-packages/django/core/handlers/base.py", line 132, in get_response
    response = wrapped_callback(request, *callback_args, **callback_kwargs)
  File "/code/samba/web/consumer/views.py", line 81, in reset_pwd
    return JsonResponse(json.dumps({"success":True}))
  File "/data/django/lib/python2.7/site-packages/django/http/response.py", line 532, in __init__
    raise TypeError('In order to allow non-dict objects to be '
TypeError: In order to allow non-dict objects to be serialized set the safe parameter to False
2019-01-15 21:10:39,531 INFO  Kname: samba_conf was get. 
2019-01-15 21:10:39,535 INFO  Kname: samba_conf was get. 
2019-01-15 21:10:39,536 INFO  Kname: samba_conf was get. 
2019-01-15 21:10:44,998 INFO  SAMBA USER:wangbo1was stoped. 
2019-01-15 21:10:44,999 ERROR  Internal Server Error: /consumer/lock_user 
Traceback (most recent call last):
  File "/data/django/lib/python2.7/site-packages/django/core/handlers/base.py", line 132, in get_response
    response = wrapped_callback(request, *callback_args, **callback_kwargs)
  File "/code/samba/web/consumer/views.py", line 99, in user_lock
    return JsonResponse(json.dumps({"success":True}))
  File "/data/django/lib/python2.7/site-packages/django/http/response.py", line 532, in __init__
    raise TypeError('In order to allow non-dict objects to be '
TypeError: In order to allow non-dict objects to be serialized set the safe parameter to False
2019-01-15 21:22:51,716 INFO  Kname: samba_conf was get. 
2019-01-15 21:22:51,718 INFO  Kname: samba_conf was get. 
2019-01-15 21:22:51,719 INFO  Kname: samba_conf was get. 
2019-01-15 21:29:14,010 INFO  Kname: samba_conf was get. 
2019-01-15 21:29:14,015 INFO  Kname: samba_conf was get. 
2019-01-15 21:29:14,015 INFO  Kname: samba_conf was get. 
2019-01-15 22:03:01,818 INFO  Kname: samba_conf was get. 
2019-01-15 22:03:01,819 INFO  Kname: samba_conf was get. 
2019-01-15 22:03:01,820 INFO  Kname: samba_conf was get. 
2019-01-15 22:03:14,364 INFO  SAMBA USER:wangbo1was enabled. 
2019-01-15 22:03:14,407 ERROR  Internal Server Error: /consumer/lock_user 
Traceback (most recent call last):
  File "/data/django/lib/python2.7/site-packages/django/core/handlers/base.py", line 132, in get_response
    response = wrapped_callback(request, *callback_args, **callback_kwargs)
  File "/code/samba/web/consumer/views.py", line 99, in user_lock
    return JsonResponse(json.dumps({"success":True}))
  File "/data/django/lib/python2.7/site-packages/django/http/response.py", line 532, in __init__
    raise TypeError('In order to allow non-dict objects to be '
TypeError: In order to allow non-dict objects to be serialized set the safe parameter to False
2019-01-15 22:31:33,298 INFO  Kname: samba_conf was get. 
2019-01-15 22:31:33,301 INFO  Kname: samba_conf was get. 
2019-01-15 22:31:33,301 INFO  Kname: samba_conf was get. 
2019-01-15 22:41:21,914 INFO  Kname: samba_conf was get. 
2019-01-15 22:41:21,915 INFO  Kname: samba_conf was get. 
2019-01-15 22:41:21,916 INFO  Kname: samba_conf was get. 
2019-01-15 22:42:36,008 INFO  Kname: samba_conf was get. 
2019-01-15 22:42:36,009 INFO  Kname: samba_conf was get. 
2019-01-15 22:42:36,010 INFO  Kname: samba_conf was get. 
2019-01-15 23:00:40,579 INFO  Kname: samba_conf was get. 
2019-01-15 23:00:40,580 INFO  Kname: samba_conf was get. 
2019-01-15 23:00:40,583 INFO  Kname: samba_conf was get. 
2019-01-15 23:00:46,594 WARNING  Not Found: /department/lock_department 
2019-01-15 23:00:46,658 WARNING  Not Found: /department/lock_department 
2019-01-15 23:05:01,723 WARNING  Not Found: /department/delete_department 
2019-01-15 23:05:05,314 WARNING  Not Found: /department/edit_department 
2019-01-15 23:21:19,103 WARNING  Not Found: /department/lock_department 
2019-01-15 23:21:57,702 INFO  Kname: samba_conf was get. 
2019-01-15 23:21:57,703 INFO  Kname: samba_conf was get. 
2019-01-15 23:21:57,704 INFO  Kname: samba_conf was get. 
2019-01-15 23:22:08,631 WARNING  Not Found: /department/lock_department 
2019-02-04 13:16:32,193 INFO  Kname: samba_conf was get. 
2019-02-04 13:16:32,197 INFO  Kname: samba_conf was get. 
2019-02-04 13:16:32,199 INFO  Kname: samba_conf was get. 
2019-02-04 13:16:37,561 INFO  /deploy/ 
2019-02-04 13:16:44,195 INFO  /deploy/ 
2019-02-04 13:16:47,978 WARNING  Not Found: /department/delete_department 
2019-02-04 13:16:51,895 INFO  /deploy/ 
2019-02-04 13:17:00,602 INFO  ---------------------- 
2019-02-04 13:17:00,602 INFO  13 
2019-02-04 13:17:01,020 ERROR  userdel：未找到 wangbo1 的主目录“/home/wangbo1”
 
2019-02-04 13:17:01,026 ERROR  1
 
2019-02-04 13:17:01,164 INFO  SAMBA USER:wangbo1  was deleted. 
=======
2019-01-24 22:35:12,060 INFO  USER Tomwas add to db. 
2019-01-24 22:35:12,134 INFO  User was created. 
2019-01-24 22:35:12,219 INFO  SAMBA USER:Tomwas added. 
2019-01-24 22:35:18,040 INFO  /deploy/ 
2019-01-24 22:35:34,092 INFO  False 
2019-01-24 22:35:34,154 INFO  Department :IT was added. 
2019-01-24 22:35:34,154 INFO  Kname: comment was set. 
2019-01-24 22:35:34,154 INFO  Kname: valid users was set. 
2019-01-24 22:35:34,155 INFO  CONFIGFILE: /data/smb.conf was saved. 
2019-01-24 22:35:34,192 WARNING  Department :ITwas added. 
2019-01-24 22:35:36,740 INFO  /deploy/ 
2019-01-24 22:39:05,342 INFO  /deploy/ 
2019-01-24 22:39:08,171 INFO  /deploy/ 
2019-01-24 22:40:50,394 INFO  /deploy/ 
2019-01-24 22:41:05,504 INFO  /deploy/ 
>>>>>>> caa64a57497c7b4228410a7c0f05e943a70a6921
