2018-09-03 15:55:22,208 INFO  Kname: samba_conf was get. 
2018-09-03 15:55:22,209 INFO  Kname: samba_conf was get. 
2018-09-03 15:55:22,210 INFO  Kname: samba_conf was get. 
2018-09-03 15:55:25,598 INFO  /deploy/ 
2018-09-03 16:02:49,209 INFO  Kname: samba_conf was get. 
2018-09-03 16:02:49,211 INFO  Kname: samba_conf was get. 
2018-09-03 16:02:49,212 INFO  Kname: samba_conf was get. 
2018-09-03 16:38:24,261 INFO  Kname: samba_conf was get. 
2018-09-03 16:38:24,264 INFO  Kname: samba_conf was get. 
2018-09-03 16:38:24,264 INFO  Kname: samba_conf was get. 
2018-09-03 16:40:06,004 INFO  /deploy/ 
2018-09-03 16:46:42,384 INFO  Kname: samba_conf was get. 
2018-09-03 16:46:42,386 INFO  Kname: samba_conf was get. 
2018-09-03 16:46:42,387 INFO  Kname: samba_conf was get. 
2018-09-03 16:47:09,170 INFO  Kname: samba_conf was get. 
2018-09-03 16:47:09,172 INFO  Kname: samba_conf was get. 
2018-09-03 16:47:09,173 INFO  Kname: samba_conf was get. 
2018-09-03 16:53:44,384 INFO  Kname: samba_conf was get. 
2018-09-03 16:53:44,387 INFO  Kname: samba_conf was get. 
2018-09-03 16:53:44,388 INFO  Kname: samba_conf was get. 
2018-09-03 17:31:09,877 INFO  /deploy/ 
2018-09-03 18:30:53,538 INFO  Kname: samba_conf was get. 
2018-09-03 18:30:53,539 INFO  Kname: samba_conf was get. 
2018-09-03 18:30:53,540 INFO  Kname: samba_conf was get. 
2018-09-04 09:12:10,449 INFO  Kname: samba_conf was get. 
2018-09-04 09:12:10,450 INFO  Kname: samba_conf was get. 
2018-09-04 09:12:10,450 INFO  Kname: samba_conf was get. 
2018-09-04 09:12:10,820 WARNING  Not Found: /favicon.ico 
2018-09-04 10:43:31,963 WARNING  Not Found: /login.cgi 
2018-09-04 10:43:35,002 WARNING  Not Found: /login.cgi 
2018-09-04 10:43:36,792 WARNING  Not Found: /login.cgi 
2018-09-04 14:15:22,753 INFO  Kname: samba_conf was get. 
2018-09-04 14:15:22,754 INFO  Kname: samba_conf was get. 
2018-09-04 14:15:22,755 INFO  Kname: samba_conf was get. 
2018-09-04 14:15:23,128 WARNING  Not Found: /favicon.ico 
2018-09-04 14:21:45,033 INFO  /deploy/ 
2018-09-04 14:45:18,151 WARNING  Not Found: /http:/112.124.42.80:63435/ 
2018-09-04 15:03:31,085 INFO  /deploy/ 
2018-09-04 16:42:38,945 INFO  /deploy/ 
2018-09-04 16:42:51,652 INFO  /deploy/ 
2018-09-04 16:42:53,179 INFO  /deploy/ 
2018-09-04 16:42:57,566 INFO  /deploy/ 
2018-09-04 16:46:39,508 INFO  /deploy/ 
2018-09-04 16:49:10,876 INFO  /deploy/ 
2018-09-05 09:09:03,922 INFO  Kname: samba_conf was get. 
2018-09-05 09:09:03,924 INFO  Kname: samba_conf was get. 
2018-09-05 09:09:03,925 INFO  Kname: samba_conf was get. 
2018-09-05 09:09:04,267 WARNING  Not Found: /favicon.ico 
2018-09-05 09:11:22,407 INFO  /deploy/ 
2018-09-05 09:11:47,930 INFO  /deploy/ 
2018-09-05 10:50:39,554 WARNING  Not Found: /otsmobile/app/mds/mgw.htm 
2018-09-05 11:23:43,317 INFO  Kname: samba_conf was get. 
2018-09-05 11:23:43,318 INFO  Kname: samba_conf was get. 
2018-09-05 11:23:43,318 INFO  Kname: samba_conf was get. 
2018-09-05 11:47:19,133 INFO  Kname: samba_conf was get. 
2018-09-05 11:47:19,136 INFO  Kname: samba_conf was get. 
2018-09-05 11:47:19,137 INFO  Kname: samba_conf was get. 
2018-09-05 11:56:04,480 INFO  Kname: samba_conf was get. 
2018-09-05 11:56:04,483 INFO  Kname: samba_conf was get. 
2018-09-05 11:56:04,483 INFO  Kname: samba_conf was get. 
2018-09-05 12:58:06,785 WARNING  Not Found: /path/to/file 
2018-09-05 12:58:41,742 ERROR  Internal Server Error: /consumer 
Traceback (most recent call last):
  File "/data/django/lib/python2.7/site-packages/django/core/handlers/base.py", line 108, in get_response
    response = middleware_method(request)
  File "/data/django/lib/python2.7/site-packages/django/middleware/common.py", line 84, in process_request
    "settings.") % (new_url[0], new_url[1]))
RuntimeError: You called this URL via POST, but the URL doesn't end in a slash and you have APPEND_SLASH set. Django can't redirect to the slash URL while maintaining POST data. Change your form to point to 118.89.49.101/consumer/ (note the trailing slash), or set APPEND_SLASH=False in your Django settings.
2018-09-05 13:27:03,380 ERROR  Internal Server Error: /consumer 
Traceback (most recent call last):
  File "/data/django/lib/python2.7/site-packages/django/core/handlers/base.py", line 108, in get_response
    response = middleware_method(request)
  File "/data/django/lib/python2.7/site-packages/django/middleware/common.py", line 84, in process_request
    "settings.") % (new_url[0], new_url[1]))
RuntimeError: You called this URL via POST, but the URL doesn't end in a slash and you have APPEND_SLASH set. Django can't redirect to the slash URL while maintaining POST data. Change your form to point to 118.89.49.101/consumer/ (note the trailing slash), or set APPEND_SLASH=False in your Django settings.
2018-09-05 13:35:29,550 INFO  Kname: samba_conf was get. 
2018-09-05 13:35:29,553 INFO  Kname: samba_conf was get. 
2018-09-05 13:35:29,554 INFO  Kname: samba_conf was get. 
2018-09-05 13:36:45,262 ERROR  Internal Server Error: /consumer 
Traceback (most recent call last):
  File "/data/django/lib/python2.7/site-packages/django/core/handlers/base.py", line 108, in get_response
    response = middleware_method(request)
  File "/data/django/lib/python2.7/site-packages/django/middleware/common.py", line 84, in process_request
    "settings.") % (new_url[0], new_url[1]))
RuntimeError: You called this URL via POST, but the URL doesn't end in a slash and you have APPEND_SLASH set. Django can't redirect to the slash URL while maintaining POST data. Change your form to point to 118.89.49.101/consumer/ (note the trailing slash), or set APPEND_SLASH=False in your Django settings.
2018-09-05 13:37:53,537 ERROR  Internal Server Error: /consumer 
Traceback (most recent call last):
  File "/data/django/lib/python2.7/site-packages/django/core/handlers/base.py", line 108, in get_response
    response = middleware_method(request)
  File "/data/django/lib/python2.7/site-packages/django/middleware/common.py", line 84, in process_request
    "settings.") % (new_url[0], new_url[1]))
RuntimeError: You called this URL via POST, but the URL doesn't end in a slash and you have APPEND_SLASH set. Django can't redirect to the slash URL while maintaining POST data. Change your form to point to 118.89.49.101/consumer/ (note the trailing slash), or set APPEND_SLASH=False in your Django settings.
2018-09-05 13:38:53,635 ERROR  Internal Server Error: /consumer 
Traceback (most recent call last):
  File "/data/django/lib/python2.7/site-packages/django/core/handlers/base.py", line 108, in get_response
    response = middleware_method(request)
  File "/data/django/lib/python2.7/site-packages/django/middleware/common.py", line 84, in process_request
    "settings.") % (new_url[0], new_url[1]))
RuntimeError: You called this URL via POST, but the URL doesn't end in a slash and you have APPEND_SLASH set. Django can't redirect to the slash URL while maintaining POST data. Change your form to point to 118.89.49.101/consumer/ (note the trailing slash), or set APPEND_SLASH=False in your Django settings.
2018-09-05 13:39:12,283 ERROR  Internal Server Error: /consumer 
Traceback (most recent call last):
  File "/data/django/lib/python2.7/site-packages/django/core/handlers/base.py", line 108, in get_response
    response = middleware_method(request)
  File "/data/django/lib/python2.7/site-packages/django/middleware/common.py", line 84, in process_request
    "settings.") % (new_url[0], new_url[1]))
RuntimeError: You called this URL via POST, but the URL doesn't end in a slash and you have APPEND_SLASH set. Django can't redirect to the slash URL while maintaining POST data. Change your form to point to 118.89.49.101/consumer/ (note the trailing slash), or set APPEND_SLASH=False in your Django settings.
2018-09-05 13:40:32,795 ERROR  Internal Server Error: /consumer 
Traceback (most recent call last):
  File "/data/django/lib/python2.7/site-packages/django/core/handlers/base.py", line 108, in get_response
    response = middleware_method(request)
  File "/data/django/lib/python2.7/site-packages/django/middleware/common.py", line 84, in process_request
    "settings.") % (new_url[0], new_url[1]))
RuntimeError: You called this URL via POST, but the URL doesn't end in a slash and you have APPEND_SLASH set. Django can't redirect to the slash URL while maintaining POST data. Change your form to point to 118.89.49.101/consumer/ (note the trailing slash), or set APPEND_SLASH=False in your Django settings.
2018-09-05 13:51:59,363 INFO  Kname: samba_conf was get. 
2018-09-05 13:51:59,364 INFO  Kname: samba_conf was get. 
2018-09-05 13:51:59,364 INFO  Kname: samba_conf was get. 
2018-09-05 13:52:14,500 INFO  /deploy/ 
2018-09-05 14:35:48,274 INFO  /deploy/ 
2018-09-05 14:57:22,221 INFO  Kname: samba_conf was get. 
2018-09-05 14:57:22,222 INFO  Kname: samba_conf was get. 
2018-09-05 14:57:22,223 INFO  Kname: samba_conf was get. 
2018-09-05 15:44:52,145 INFO  Kname: samba_conf was get. 
2018-09-05 15:44:52,147 INFO  Kname: samba_conf was get. 
2018-09-05 15:44:52,148 INFO  Kname: samba_conf was get. 
2018-09-05 15:49:38,342 WARNING  Not Found: /path/to/file 
2018-09-05 15:54:22,814 WARNING  Not Found: /login.cgi 
2018-09-05 16:04:18,996 WARNING  Not Found: /path/to/file 
2018-09-05 16:04:27,661 WARNING  Not Found: /path/to/file 
2018-09-05 16:08:49,618 WARNING  Not Found: /path/to/file 
2018-09-05 16:16:32,439 WARNING  Not Found: /path/to/file 
2018-09-05 16:17:08,470 ERROR  Internal Server Error: /consumer 
Traceback (most recent call last):
  File "/data/django/lib/python2.7/site-packages/django/core/handlers/base.py", line 108, in get_response
    response = middleware_method(request)
  File "/data/django/lib/python2.7/site-packages/django/middleware/common.py", line 84, in process_request
    "settings.") % (new_url[0], new_url[1]))
RuntimeError: You called this URL via POST, but the URL doesn't end in a slash and you have APPEND_SLASH set. Django can't redirect to the slash URL while maintaining POST data. Change your form to point to 118.89.49.101/consumer/ (note the trailing slash), or set APPEND_SLASH=False in your Django settings.
2018-09-05 16:35:01,563 ERROR  Internal Server Error: /consumer 
Traceback (most recent call last):
  File "/data/django/lib/python2.7/site-packages/django/core/handlers/base.py", line 108, in get_response
    response = middleware_method(request)
  File "/data/django/lib/python2.7/site-packages/django/middleware/common.py", line 84, in process_request
    "settings.") % (new_url[0], new_url[1]))
RuntimeError: You called this URL via POST, but the URL doesn't end in a slash and you have APPEND_SLASH set. Django can't redirect to the slash URL while maintaining POST data. Change your form to point to 118.89.49.101/consumer/ (note the trailing slash), or set APPEND_SLASH=False in your Django settings.
2018-09-05 16:47:31,720 WARNING  Not Found: /login.cgi 
2018-09-05 16:58:31,815 INFO  /deploy/ 
2018-09-05 16:58:45,649 WARNING  Not Found: /browserconfig.xml 
2018-09-05 17:06:20,677 INFO  /deploy/ 
2018-09-05 17:09:52,312 INFO  Kname: samba_conf was get. 
2018-09-05 17:09:52,314 INFO  Kname: samba_conf was get. 
2018-09-05 17:09:52,315 INFO  Kname: samba_conf was get. 
2018-09-05 17:11:02,527 INFO  /deploy/ 
2018-09-05 17:11:14,351 INFO  /deploy/ 
2018-09-05 17:11:41,669 INFO  /deploy/ 
2018-09-05 17:11:42,300 INFO  /deploy/ 
2018-09-05 17:34:39,999 ERROR  Internal Server Error: /consumer 
Traceback (most recent call last):
  File "/data/django/lib/python2.7/site-packages/django/core/handlers/base.py", line 108, in get_response
    response = middleware_method(request)
  File "/data/django/lib/python2.7/site-packages/django/middleware/common.py", line 84, in process_request
    "settings.") % (new_url[0], new_url[1]))
RuntimeError: You called this URL via POST, but the URL doesn't end in a slash and you have APPEND_SLASH set. Django can't redirect to the slash URL while maintaining POST data. Change your form to point to 118.89.49.101/consumer/ (note the trailing slash), or set APPEND_SLASH=False in your Django settings.
2018-09-05 17:46:46,722 ERROR  Internal Server Error: /consumer 
Traceback (most recent call last):
  File "/data/django/lib/python2.7/site-packages/django/core/handlers/base.py", line 108, in get_response
    response = middleware_method(request)
  File "/data/django/lib/python2.7/site-packages/django/middleware/common.py", line 84, in process_request
    "settings.") % (new_url[0], new_url[1]))
RuntimeError: You called this URL via POST, but the URL doesn't end in a slash and you have APPEND_SLASH set. Django can't redirect to the slash URL while maintaining POST data. Change your form to point to 118.89.49.101/consumer/ (note the trailing slash), or set APPEND_SLASH=False in your Django settings.
2018-09-05 17:54:24,566 WARNING  Forbidden (CSRF cookie not set.): / 
2018-09-05 17:54:24,635 WARNING  Not Found: /webdav/ 
2018-09-05 17:54:24,769 WARNING  Not Found: /help.php 
2018-09-05 17:54:24,844 WARNING  Not Found: /java.php 
2018-09-05 17:54:24,967 WARNING  Not Found: /_query.php 
2018-09-05 17:54:25,104 WARNING  Not Found: /test.php 
2018-09-05 17:54:25,179 WARNING  Not Found: /db_cts.php 
2018-09-05 17:54:26,053 WARNING  Not Found: /db_pma.php 
2018-09-05 17:54:26,126 WARNING  Not Found: /logon.php 
2018-09-05 17:54:26,229 WARNING  Not Found: /help-e.php 
2018-09-05 17:54:26,338 WARNING  Not Found: /license.php 
2018-09-05 17:54:26,436 WARNING  Not Found: /log.php 
2018-09-05 17:54:26,525 WARNING  Not Found: /hell.php 
2018-09-05 17:54:26,628 WARNING  Not Found: /pmd_online.php 
2018-09-05 17:54:26,734 WARNING  Not Found: /x.php 
2018-09-05 17:54:26,812 WARNING  Not Found: /shell.php 
2018-09-05 17:54:26,891 WARNING  Not Found: /desktop.ini.php 
2018-09-05 17:54:27,014 WARNING  Not Found: /z.php 
2018-09-05 17:54:27,139 WARNING  Not Found: /lala.php 
2018-09-05 17:54:27,217 WARNING  Not Found: /lala-dpr.php 
2018-09-05 17:54:27,292 WARNING  Not Found: /wpo.php 
2018-09-05 17:54:27,390 WARNING  Not Found: /text.php 
2018-09-05 17:54:27,487 WARNING  Not Found: /wp-config.php 
2018-09-05 17:54:27,584 WARNING  Not Found: /muhstik.php 
2018-09-05 17:54:27,668 WARNING  Not Found: /muhstik2.php 
2018-09-05 17:54:27,785 WARNING  Not Found: /muhstiks.php 
2018-09-05 17:54:33,987 WARNING  Not Found: /lol.php 
2018-09-05 17:54:34,106 WARNING  Not Found: /uploader.php 
2018-09-05 17:54:37,992 WARNING  Not Found: /cmx.php 
2018-09-05 17:54:38,066 WARNING  Not Found: /cmv.php 
2018-09-05 17:54:38,149 WARNING  Not Found: /cmdd.php 
2018-09-05 17:54:38,261 WARNING  Not Found: /knal.php 
2018-09-05 17:54:38,410 WARNING  Not Found: /cmd.php 
2018-09-05 17:54:38,504 WARNING  Not Found: /shell.php 
2018-09-05 17:54:38,597 WARNING  Not Found: /appserv.php 
2018-09-05 17:54:38,701 WARNING  Not Found: /wuwu11.php 
2018-09-05 17:54:38,840 WARNING  Not Found: /xw.php 
2018-09-05 17:54:38,954 WARNING  Not Found: /xw1.php 
2018-09-05 17:54:39,121 WARNING  Not Found: /9678.php 
2018-09-05 17:54:42,078 WARNING  Not Found: /xx.php 
2018-09-05 17:54:42,199 WARNING  Not Found: /s.php 
2018-09-05 17:54:42,327 WARNING  Not Found: /w.php 
2018-09-05 17:54:42,415 WARNING  Not Found: /sheep.php 
2018-09-05 17:54:42,511 WARNING  Not Found: /db.init.php 
2018-09-05 17:54:42,593 WARNING  Not Found: /db_session.init.php 
2018-09-05 17:54:42,672 WARNING  Not Found: /db__.init.php 
2018-09-05 17:54:42,751 WARNING  Not Found: /wp-admins.php 
2018-09-05 17:54:42,837 WARNING  Not Found: /m.php 
2018-09-05 17:54:42,952 WARNING  Not Found: /db_dataml.php 
2018-09-05 17:54:43,029 WARNING  Not Found: /db_desql.php 
2018-09-05 17:54:43,119 WARNING  Not Found: /mx.php 
2018-09-05 17:54:43,236 WARNING  Not Found: /wshell.php 
2018-09-05 17:54:43,329 WARNING  Not Found: /xshell.php 
2018-09-05 17:54:43,403 WARNING  Not Found: /qq.php 
2018-09-05 17:54:43,518 WARNING  Not Found: /conflg.php 
2018-09-05 17:54:43,621 WARNING  Not Found: /lindex.php 
2018-09-05 17:54:43,728 WARNING  Not Found: /phpstudy.php 
2018-09-05 17:54:43,842 WARNING  Not Found: /phpStudy.php 
2018-09-05 17:54:43,959 WARNING  Not Found: /weixiao.php 
2018-09-05 17:54:44,076 WARNING  Not Found: /feixiang.php 
2018-09-05 17:54:44,196 WARNING  Not Found: /ak47.php 
2018-09-05 17:54:45,992 WARNING  Not Found: /ak48.php 
2018-09-05 17:54:46,071 WARNING  Not Found: /xiao.php 
2018-09-05 17:54:46,160 WARNING  Not Found: /yao.php 
2018-09-05 17:54:46,250 WARNING  Not Found: /defect.php 
2018-09-05 17:54:46,349 WARNING  Not Found: /webslee.php 
2018-09-05 17:54:46,451 WARNING  Not Found: /q.php 
2018-09-05 17:54:46,536 WARNING  Not Found: /pe.php 
2018-09-05 17:54:46,631 WARNING  Not Found: /hm.php 
2018-09-05 17:54:46,759 WARNING  Not Found: /cainiao.php 
2018-09-05 17:54:46,894 WARNING  Not Found: /zuoshou.php 
2018-09-05 17:54:46,994 WARNING  Not Found: /zuo.php 
2018-09-05 17:54:47,084 WARNING  Not Found: /aotu.php 
2018-09-05 17:54:47,195 WARNING  Not Found: /cmd.php 
2018-09-05 17:54:47,292 WARNING  Not Found: /bak.php 
2018-09-05 17:54:47,384 WARNING  Not Found: /system.php 
2018-09-05 17:54:47,468 WARNING  Not Found: /l7.php 
2018-09-05 17:54:47,579 WARNING  Not Found: /l8.php 
2018-09-05 17:54:47,670 WARNING  Not Found: /qaq.php 
2018-09-05 17:54:47,777 WARNING  Not Found: /q.php 
2018-09-05 17:54:47,882 WARNING  Not Found: /56.php 
2018-09-05 17:54:47,986 WARNING  Not Found: /mz.php 
2018-09-05 17:54:48,096 WARNING  Not Found: /xx.php 
2018-09-05 17:54:48,207 WARNING  Not Found: /qaq.php 
2018-09-05 17:54:48,306 WARNING  Not Found: /qaq.php 
2018-09-05 17:54:48,401 WARNING  Not Found: /yumo.php 
2018-09-05 17:54:48,482 WARNING  Not Found: /min.php 
2018-09-05 17:54:48,586 WARNING  Not Found: /wan.php 
2018-09-05 17:54:48,709 WARNING  Not Found: /wanan.php 
2018-09-05 17:54:48,810 WARNING  Not Found: /ssaa.php 
2018-09-05 17:54:48,923 WARNING  Not Found: /qq.php 
2018-09-05 17:54:49,041 WARNING  Not Found: /aw.php 
2018-09-05 17:54:50,272 WARNING  Not Found: /hh.php 
2018-09-05 17:54:50,363 WARNING  Not Found: /ak.php 
2018-09-05 17:54:50,474 WARNING  Not Found: /ip.php 
2018-09-05 17:54:50,551 WARNING  Not Found: /infoo.php 
2018-09-05 17:54:50,645 WARNING  Not Found: /qq.php 
2018-09-05 17:54:50,747 WARNING  Not Found: /qwe.php 
2018-09-05 17:54:50,864 WARNING  Not Found: /1213.php 
2018-09-05 17:54:50,960 WARNING  Not Found: /post.php 
2018-09-05 17:54:51,058 WARNING  Not Found: /h1.php 
2018-09-05 17:54:51,142 WARNING  Not Found: /test.php 
2018-09-05 17:54:51,231 WARNING  Not Found: /3.php 
2018-09-05 17:54:51,331 WARNING  Not Found: /phpinfi.php 
2018-09-05 17:54:51,439 WARNING  Not Found: /aaaa.php 
2018-09-05 17:54:51,525 WARNING  Not Found: /9510.php 
2018-09-05 17:54:51,624 WARNING  Not Found: /python.php 
2018-09-05 17:54:51,727 WARNING  Not Found: /default.php 
2018-09-05 17:54:51,861 WARNING  Not Found: /sean.php 
2018-09-05 17:54:51,974 WARNING  Not Found: /app.php 
2018-09-05 17:54:54,287 WARNING  Not Found: /tiandi.php 
2018-09-05 17:54:54,397 WARNING  Not Found: /xiaoma.php 
2018-09-05 17:54:54,519 WARNING  Not Found: /xiaomae.php 
2018-09-05 17:54:54,630 WARNING  Not Found: /xiaomar.php 
2018-09-05 17:54:54,729 WARNING  Not Found: /qq.php 
2018-09-05 17:54:54,840 WARNING  Not Found: /data.php 
2018-09-05 17:54:54,954 WARNING  Not Found: /log.php 
2018-09-05 17:54:55,044 WARNING  Not Found: /fack.php 
2018-09-05 17:54:55,143 WARNING  Not Found: /angge.php 
2018-09-05 17:54:55,246 WARNING  Not Found: /index.php 
2018-09-05 17:54:55,354 WARNING  Not Found: /phpmyadmin/index.php 
2018-09-05 17:54:55,459 WARNING  Not Found: /phpMyAdmin/index.php 
2018-09-05 17:54:55,530 WARNING  Not Found: /pmd/index.php 
2018-09-05 17:54:55,671 WARNING  Not Found: /pma/index.php 
2018-09-05 17:54:55,790 WARNING  Not Found: /PMA/index.php 
2018-09-05 17:54:55,904 WARNING  Not Found: /PMA2/index.php 
2018-09-05 17:54:55,989 WARNING  Not Found: /pmamy/index.php 
2018-09-05 17:54:56,096 WARNING  Not Found: /pmamy2/index.php 
2018-09-05 17:54:56,198 WARNING  Not Found: /mysql/index.php 
2018-09-05 17:54:56,311 WARNING  Not Found: /admin/index.php 
2018-09-05 17:54:56,433 WARNING  Not Found: /db/index.php 
2018-09-05 17:54:56,552 WARNING  Not Found: /dbadmin/index.php 
2018-09-05 17:54:56,648 WARNING  Not Found: /web/phpMyAdmin/index.php 
2018-09-05 17:54:56,750 WARNING  Not Found: /admin/pma/index.php 
2018-09-05 17:54:56,835 WARNING  Not Found: /admin/PMA/index.php 
2018-09-05 17:54:56,923 WARNING  Not Found: /admin/mysql/index.php 
2018-09-05 17:54:57,010 WARNING  Not Found: /admin/mysql2/index.php 
2018-09-05 17:54:57,102 WARNING  Not Found: /admin/phpmyadmin/index.php 
2018-09-05 17:54:57,188 WARNING  Not Found: /admin/phpMyAdmin/index.php 
2018-09-05 17:54:57,997 WARNING  Not Found: /admin/phpmyadmin2/index.php 
2018-09-05 17:54:58,078 WARNING  Not Found: /mysqladmin/index.php 
2018-09-05 17:54:58,172 WARNING  Not Found: /mysql-admin/index.php 
2018-09-05 17:54:58,265 WARNING  Not Found: /phpadmin/index.php 
2018-09-05 17:54:58,380 WARNING  Not Found: /phpmyadmin0/index.php 
2018-09-05 17:54:58,452 WARNING  Not Found: /phpmyadmin1/index.php 
2018-09-05 17:54:58,554 WARNING  Not Found: /phpmyadmin2/index.php 
2018-09-05 17:54:58,660 WARNING  Not Found: /myadmin/index.php 
2018-09-05 17:54:58,741 WARNING  Not Found: /myadmin2/index.php 
2018-09-05 17:54:58,839 WARNING  Not Found: /xampp/phpmyadmin/index.php 
2018-09-05 17:54:58,927 WARNING  Not Found: /phpMyadmin_bak/index.php 
2018-09-05 17:54:59,011 WARNING  Not Found: /www/phpMyAdmin/index.php 
2018-09-05 17:54:59,128 WARNING  Not Found: /tools/phpMyAdmin/index.php 
2018-09-05 17:54:59,238 WARNING  Not Found: /phpmyadmin-old/index.php 
2018-09-05 17:54:59,366 WARNING  Not Found: /phpMyAdminold/index.php 
2018-09-05 17:54:59,485 WARNING  Not Found: /phpMyAdmin.old/index.php 
2018-09-05 17:54:59,922 WARNING  Not Found: /pma-old/index.php 
2018-09-05 17:55:00,035 WARNING  Not Found: /claroline/phpMyAdmin/index.php 
2018-09-05 17:55:00,143 WARNING  Not Found: /typo3/phpmyadmin/index.php 
2018-09-05 17:55:00,230 WARNING  Not Found: /phpma/index.php 
2018-09-05 17:55:00,317 WARNING  Not Found: /phpmyadmin/phpmyadmin/index.php 
2018-09-05 17:55:00,421 WARNING  Not Found: /phpMyAdmin/phpMyAdmin/index.php 
2018-09-05 18:22:19,147 WARNING  Not Found: /phpmyadmin 
2018-09-05 18:22:19,243 WARNING  Not Found: /phpmyadmin 
2018-09-05 18:26:57,960 INFO  Kname: samba_conf was get. 
2018-09-05 18:26:57,963 INFO  Kname: samba_conf was get. 
2018-09-05 18:26:57,964 INFO  Kname: samba_conf was get. 
2018-09-05 18:44:58,904 WARNING  Not Found: /login.cgi 
2018-09-05 18:51:33,891 ERROR  Internal Server Error: /consumer 
Traceback (most recent call last):
  File "/data/django/lib/python2.7/site-packages/django/core/handlers/base.py", line 108, in get_response
    response = middleware_method(request)
  File "/data/django/lib/python2.7/site-packages/django/middleware/common.py", line 84, in process_request
    "settings.") % (new_url[0], new_url[1]))
RuntimeError: You called this URL via POST, but the URL doesn't end in a slash and you have APPEND_SLASH set. Django can't redirect to the slash URL while maintaining POST data. Change your form to point to 118.89.49.101/consumer/ (note the trailing slash), or set APPEND_SLASH=False in your Django settings.
2018-09-06 09:02:49,429 INFO  Kname: samba_conf was get. 
2018-09-06 09:02:49,431 INFO  Kname: samba_conf was get. 
2018-09-06 09:02:49,431 INFO  Kname: samba_conf was get. 
2018-09-06 09:02:49,710 WARNING  Not Found: /favicon.ico 
2018-09-06 09:17:19,175 INFO  Kname: samba_conf was get. 
2018-09-06 09:17:19,176 INFO  Kname: samba_conf was get. 
2018-09-06 09:17:19,176 INFO  Kname: samba_conf was get. 
2018-09-06 09:26:34,574 WARNING  Forbidden (CSRF cookie not set.): / 
2018-09-06 09:28:35,135 WARNING  Forbidden (CSRF cookie not set.): / 
2018-09-06 09:30:36,112 WARNING  Forbidden (CSRF cookie not set.): / 
2018-09-06 09:32:36,916 WARNING  Forbidden (CSRF cookie not set.): / 
2018-09-06 09:34:37,463 WARNING  Forbidden (CSRF cookie not set.): / 
2018-09-06 09:36:38,250 WARNING  Forbidden (CSRF cookie not set.): / 
2018-09-06 09:38:38,815 WARNING  Forbidden (CSRF cookie not set.): / 
2018-09-06 09:40:39,616 WARNING  Forbidden (CSRF cookie not set.): / 
2018-09-06 09:42:40,172 WARNING  Forbidden (CSRF cookie not set.): / 
2018-09-06 09:44:40,706 WARNING  Forbidden (CSRF cookie not set.): / 
2018-09-06 09:46:41,259 WARNING  Forbidden (CSRF cookie not set.): / 
2018-09-06 09:48:41,810 WARNING  Forbidden (CSRF cookie not set.): / 
2018-09-06 09:50:42,443 WARNING  Forbidden (CSRF cookie not set.): / 
2018-09-06 09:52:43,033 WARNING  Forbidden (CSRF cookie not set.): / 
2018-09-06 09:54:43,574 WARNING  Forbidden (CSRF cookie not set.): / 
2018-09-06 09:56:44,164 WARNING  Forbidden (CSRF cookie not set.): / 
2018-09-06 09:58:00,693 ERROR  Internal Server Error: /consumer 
Traceback (most recent call last):
  File "/data/django/lib/python2.7/site-packages/django/core/handlers/base.py", line 108, in get_response
    response = middleware_method(request)
  File "/data/django/lib/python2.7/site-packages/django/middleware/common.py", line 84, in process_request
    "settings.") % (new_url[0], new_url[1]))
RuntimeError: You called this URL via POST, but the URL doesn't end in a slash and you have APPEND_SLASH set. Django can't redirect to the slash URL while maintaining POST data. Change your form to point to 118.89.49.101/consumer/ (note the trailing slash), or set APPEND_SLASH=False in your Django settings.
2018-09-06 09:58:45,116 WARNING  Forbidden (CSRF cookie not set.): / 
2018-09-06 10:00:45,731 WARNING  Forbidden (CSRF cookie not set.): / 
2018-09-06 10:02:46,786 WARNING  Forbidden (CSRF cookie not set.): / 
2018-09-06 10:04:47,412 WARNING  Forbidden (CSRF cookie not set.): / 
2018-09-06 10:06:48,197 WARNING  Forbidden (CSRF cookie not set.): / 
2018-09-06 10:08:48,936 WARNING  Forbidden (CSRF cookie not set.): / 
2018-09-06 10:10:49,546 WARNING  Forbidden (CSRF cookie not set.): / 
2018-09-06 10:12:50,094 WARNING  Forbidden (CSRF cookie not set.): / 
2018-09-06 10:14:52,526 WARNING  Forbidden (CSRF cookie not set.): / 
2018-09-06 10:16:55,175 WARNING  Forbidden (CSRF cookie not set.): / 
2018-09-06 10:43:46,751 INFO  Kname: samba_conf was get. 
2018-09-06 10:43:46,753 INFO  Kname: samba_conf was get. 
2018-09-06 10:43:46,753 INFO  Kname: samba_conf was get. 
2018-09-06 12:32:59,489 WARNING  Not Found: /shell 
2018-09-06 12:38:09,468 WARNING  Not Found: /path/to/file 
2018-09-06 13:41:20,882 INFO  Kname: samba_conf was get. 
2018-09-06 13:41:20,883 INFO  Kname: samba_conf was get. 
2018-09-06 13:41:20,883 INFO  Kname: samba_conf was get. 
2018-09-06 14:06:52,155 WARNING  Not Found: /path/to/file 
2018-09-06 14:07:06,897 WARNING  Not Found: /path/to/file 
2018-09-06 14:07:10,217 WARNING  Not Found: /path/to/file 
2018-09-06 14:47:47,272 INFO  /deploy/ 
2018-09-06 14:50:52,520 WARNING  Not Found: /phpmyadmin/scripts/setup.php 
2018-09-06 16:43:36,063 WARNING  Not Found: /graphs/ 
2018-09-06 17:15:01,583 INFO  Kname: samba_conf was get. 
2018-09-06 17:15:01,584 INFO  Kname: samba_conf was get. 
2018-09-06 17:15:01,584 INFO  Kname: samba_conf was get. 
2018-09-06 18:03:51,841 WARNING  Not Found: /favicon.ico 
2018-09-06 18:04:00,178 WARNING  Not Found: /favicon.ico 
2018-09-06 18:04:56,828 INFO  Kname: samba_conf was get. 
2018-09-06 18:04:56,829 INFO  Kname: samba_conf was get. 
2018-09-06 18:04:56,830 INFO  Kname: samba_conf was get. 
2018-09-06 18:08:25,512 INFO  Kname: samba_conf was get. 
2018-09-06 18:08:25,513 INFO  Kname: samba_conf was get. 
2018-09-06 18:08:25,514 INFO  Kname: samba_conf was get. 
2018-09-07 09:14:44,049 INFO  Kname: samba_conf was get. 
2018-09-07 09:14:44,050 INFO  Kname: samba_conf was get. 
2018-09-07 09:14:44,051 INFO  Kname: samba_conf was get. 
2018-09-07 09:14:44,290 WARNING  Not Found: /favicon.ico 
2018-09-07 09:14:57,357 INFO  /deploy/ 
2018-09-07 09:14:59,044 INFO  /deploy/ 
2018-09-07 09:15:12,552 WARNING  Not Found: /path/to/file 
2018-09-07 09:15:39,806 INFO  /deploy/ 
2018-09-07 09:26:10,642 INFO  Kname: samba_conf was get. 
2018-09-07 09:26:10,644 INFO  Kname: samba_conf was get. 
2018-09-07 09:26:10,645 INFO  Kname: samba_conf was get. 
2018-09-07 09:32:31,968 INFO  Kname: samba_conf was get. 
2018-09-07 09:32:31,969 INFO  Kname: samba_conf was get. 
2018-09-07 09:32:31,970 INFO  Kname: samba_conf was get. 
2018-09-07 09:34:41,777 INFO  Kname: samba_conf was get. 
2018-09-07 09:34:41,779 INFO  Kname: samba_conf was get. 
2018-09-07 09:34:41,780 INFO  Kname: samba_conf was get. 
2018-09-07 09:34:46,665 INFO  /deploy/ 
2018-09-07 09:39:10,134 INFO  /deploy/ 
2018-09-07 09:39:19,135 INFO  /deploy/ 
2018-09-07 09:39:23,768 INFO  /deploy/ 
2018-09-07 09:39:26,945 INFO  /deploy/ 
2018-09-07 09:39:46,289 INFO  /deploy/ 
2018-09-07 09:40:14,882 INFO  /deploy/ 
2018-09-07 09:43:35,653 WARNING  Not Found: /favicon.ico 
2018-09-07 12:14:47,759 WARNING  Not Found: /login.cgi 
2018-09-07 12:20:45,857 WARNING  Not Found: /http:/112.124.42.80:63435/ 
2018-09-07 13:37:30,225 WARNING  Not Found: /user.php 
2018-09-07 14:31:25,376 INFO  Kname: samba_conf was get. 
2018-09-07 14:31:25,377 INFO  Kname: samba_conf was get. 
2018-09-07 14:31:25,378 INFO  Kname: samba_conf was get. 
2018-09-07 17:01:09,367 WARNING  Not Found: /favicon.ico 
2018-09-07 17:57:27,473 WARNING  Not Found: /@research.aegis.network 
2018-09-11 16:13:51,414 INFO  Kname: samba_conf was get. 
2018-09-11 16:13:51,415 INFO  Kname: samba_conf was get. 
2018-09-11 16:13:51,416 INFO  Kname: samba_conf was get. 
2018-09-11 16:13:51,782 WARNING  Not Found: /favicon.ico 
2018-09-11 16:14:04,779 INFO  /deploy/ 
2018-09-11 16:14:10,459 INFO  /deploy/ 
2018-09-11 16:14:12,205 INFO  /deploy/ 
2018-09-11 16:15:20,625 INFO  /deploy/ 
2018-09-11 16:15:26,258 INFO  /deploy/ 
2018-09-11 16:21:03,288 WARNING  Not Found: /path/to/file 
2018-09-12 21:20:27,534 INFO  Kname: samba_conf was get. 
2018-09-12 21:20:27,536 INFO  Kname: samba_conf was get. 
2018-09-12 21:20:27,537 INFO  Kname: samba_conf was get. 
2018-09-12 21:20:35,606 WARNING  Not Found: /favicon.ico 
2018-09-12 21:21:10,287 INFO  /deploy/ 
2018-09-12 21:22:00,236 WARNING  Not Found: /favicon.ico 
2018-09-12 21:22:06,598 WARNING  Not Found: /favicon.ico 
2018-09-12 21:22:09,001 WARNING  Not Found: /favicon.ico 
2018-09-12 21:22:10,896 WARNING  Not Found: /favicon.ico 
2018-09-12 21:22:16,489 WARNING  Not Found: /favicon.ico 
2018-09-12 21:22:20,875 WARNING  Not Found: /favicon.ico 
2018-09-12 21:22:22,470 INFO  /deploy/ 
2018-09-12 21:22:22,626 WARNING  Not Found: /favicon.ico 
2018-09-12 21:24:39,953 INFO  /deploy/ 
2018-09-12 21:28:58,083 INFO  /deploy/ 
2018-09-12 21:29:15,401 WARNING  Not Found: /path/to/file 
2018-09-12 21:33:40,932 INFO  Kname: samba_conf was get. 
2018-09-12 21:33:40,933 INFO  Kname: samba_conf was get. 
2018-09-12 21:33:40,934 INFO  Kname: samba_conf was get. 
2018-09-12 21:34:15,398 INFO  /deploy/ 
2018-09-14 18:17:49,995 INFO  Kname: samba_conf was get. 
2018-09-14 18:17:49,996 INFO  Kname: samba_conf was get. 
2018-09-14 18:17:49,996 INFO  Kname: samba_conf was get. 
2018-09-14 18:17:50,343 WARNING  Not Found: /favicon.ico 
2018-09-14 18:18:26,204 INFO  /deploy/ 
2018-09-17 17:16:47,584 INFO  Kname: samba_conf was get. 
2018-09-17 17:16:47,585 INFO  Kname: samba_conf was get. 
2018-09-17 17:16:47,586 INFO  Kname: samba_conf was get. 
2018-09-17 17:16:47,972 WARNING  Not Found: /favicon.ico 
2018-11-23 14:10:36,800 INFO  Kname: samba_conf was get. 
2018-11-23 14:10:36,858 INFO  Kname: samba_conf was get. 
2018-11-23 14:10:36,861 INFO  Kname: samba_conf was get. 
2018-11-23 14:10:39,461 WARNING  Not Found: /favicon.ico 
2018-11-23 14:10:52,971 WARNING  Not Found: /path/to/file 
2018-11-23 14:11:55,045 INFO  /deploy/ 
2018-11-23 14:12:01,542 INFO  /deploy/ 
2018-11-23 14:12:14,214 INFO  /deploy/ 
2019-01-06 15:54:36,972 INFO  Kname: samba_conf was get. 
2019-01-06 15:54:37,057 INFO  Kname: samba_conf was get. 
2019-01-06 15:54:37,060 INFO  Kname: samba_conf was get. 
2019-01-06 15:54:40,947 WARNING  Not Found: /favicon.ico 
2019-01-06 15:54:54,912 WARNING  Not Found: /favicon.ico 
2019-01-06 15:54:57,762 WARNING  Not Found: /favicon.ico 
2019-01-06 15:56:58,997 INFO  /deploy/ 
2019-01-06 15:56:59,717 WARNING  Not Found: /favicon.ico 
2019-01-06 15:57:54,438 WARNING  Not Found: /path/to/file 
2019-01-06 15:59:43,503 WARNING  Not Found: /favicon.ico 
2019-01-06 15:59:44,679 INFO  /deploy/ 
2019-01-06 15:59:48,633 WARNING  Not Found: /favicon.ico 
2019-01-06 16:17:33,116 INFO  /deploy/ 
2019-01-06 16:17:53,633 INFO  /deploy/ 
2019-01-06 16:18:02,742 INFO  /deploy/ 
2019-01-06 16:20:17,278 WARNING  Not Found: /favicon.ico 
2019-01-06 16:20:23,826 WARNING  Not Found: /favicon.ico 
2019-01-06 16:20:41,142 INFO  /deploy/ 
2019-01-06 16:25:55,478 WARNING  Not Found: /apple-touch-icon-precomposed.png 
2019-01-06 16:25:55,789 WARNING  Not Found: /apple-touch-icon.png 
2019-01-06 16:25:55,993 WARNING  Not Found: /favicon.ico 
2019-01-06 16:25:56,188 WARNING  Not Found: /apple-touch-icon-precomposed.png 
2019-01-06 16:25:56,354 WARNING  Not Found: /apple-touch-icon.png 
2019-01-06 16:25:56,543 WARNING  Not Found: /favicon.ico 
2019-01-06 16:25:57,473 WARNING  Not Found: /apple-touch-icon-precomposed.png 
2019-01-06 16:25:57,659 WARNING  Not Found: /apple-touch-icon.png 
2019-01-06 16:25:57,898 WARNING  Not Found: /favicon.ico 
2019-01-06 16:25:58,039 WARNING  Not Found: /apple-touch-icon-precomposed.png 
2019-01-06 16:25:58,271 WARNING  Not Found: /apple-touch-icon.png 
2019-01-06 16:25:58,754 WARNING  Not Found: /favicon.ico 
2019-01-06 16:27:04,499 WARNING  Not Found: /apple-touch-icon-precomposed.png 
2019-01-06 16:27:04,754 WARNING  Not Found: /apple-touch-icon.png 
2019-01-06 16:28:00,074 INFO  /deploy/ 
2019-01-06 16:28:39,619 WARNING  Not Found: /browse/ee 
2019-01-06 16:28:39,829 WARNING  Not Found: /favicon.ico 
2019-01-06 16:29:11,794 INFO  /deploy/ 
2019-01-06 16:29:29,777 INFO  /deploy/ 
2019-01-06 16:31:33,977 INFO  /deploy/ 
2019-01-06 16:33:29,351 INFO  /deploy/ 
2019-01-06 16:33:38,819 INFO  /deploy/ 
2019-01-06 16:33:45,158 INFO  /deploy/ 
2019-01-06 16:34:01,971 INFO  /deploy/ 
2019-01-06 16:34:53,460 INFO  /deploy/ 
2019-01-06 16:35:04,731 INFO  /deploy/ 
2019-01-06 16:36:09,468 INFO  /deploy/ 
2019-01-06 16:46:30,529 INFO  /deploy/ 
2019-01-06 16:51:47,092 INFO  /deploy/ 
2019-01-06 16:52:17,832 INFO  /deploy/ 
2019-01-06 16:54:44,693 INFO  /deploy/ 
2019-01-06 16:55:45,073 INFO  /deploy/ 
2019-01-06 16:55:47,563 INFO  /deploy/ 
2019-01-06 16:57:32,314 INFO  /deploy/ 
2019-01-06 16:58:30,574 INFO  /deploy/ 
2019-01-06 17:02:12,261 INFO  /deploy/ 
2019-01-06 17:02:50,130 INFO  /deploy/ 
2019-01-06 17:04:55,631 INFO  /deploy/ 
2019-01-06 17:06:38,215 INFO  /deploy/ 
2019-01-06 17:07:17,456 INFO  /deploy/ 
2019-01-06 17:07:40,120 INFO  /deploy/ 
2019-01-06 17:08:25,682 INFO  /deploy/ 
2019-01-06 17:09:15,227 INFO  /deploy/ 
2019-01-06 17:10:18,449 INFO  /deploy/ 
2019-01-06 17:10:49,602 INFO  /deploy/ 
2019-01-06 17:11:24,338 INFO  /deploy/ 
2019-01-06 17:11:24,463 INFO  /deploy/ 
2019-01-06 17:11:24,782 INFO  /deploy/ 
2019-01-06 17:12:29,128 INFO  /deploy/ 
2019-01-06 17:13:05,344 INFO  /deploy/ 
2019-01-06 17:13:41,752 INFO  /deploy/ 
2019-01-06 17:17:13,990 INFO  /deploy/ 
2019-01-06 17:17:17,778 INFO  /deploy/ 
2019-01-06 17:18:53,303 ERROR  Internal Server Error: /consumer 
Traceback (most recent call last):
  File "/data/django/lib/python2.7/site-packages/django/core/handlers/base.py", line 108, in get_response
    response = middleware_method(request)
  File "/data/django/lib/python2.7/site-packages/django/middleware/common.py", line 84, in process_request
    "settings.") % (new_url[0], new_url[1]))
RuntimeError: You called this URL via POST, but the URL doesn't end in a slash and you have APPEND_SLASH set. Django can't redirect to the slash URL while maintaining POST data. Change your form to point to 118.89.49.101:8081/consumer/ (note the trailing slash), or set APPEND_SLASH=False in your Django settings.
2019-01-06 17:19:28,289 WARNING  Not Found: /home 
2019-01-06 17:19:28,419 WARNING  Not Found: /favicon.ico 
2019-01-06 17:19:31,628 WARNING  Not Found: /home 
2019-01-06 17:19:41,088 INFO  /deploy/ 
2019-01-06 17:19:43,466 INFO  /deploy/ 
2019-01-06 17:20:45,554 INFO  /deploy/ 
2019-01-06 17:21:53,676 INFO  /deploy/ 
2019-01-06 17:22:00,494 INFO  /deploy/ 
2019-01-06 17:22:12,626 WARNING  Not Found: /path/to/file 
2019-01-06 17:29:56,927 INFO  /deploy/ 
2019-01-06 17:31:58,137 INFO  /deploy/ 
2019-01-06 17:32:07,703 INFO  /deploy/ 
2019-01-06 17:36:24,689 INFO  /deploy/ 
2019-01-06 17:36:54,168 INFO  /deploy/ 
2019-01-06 17:37:03,808 INFO  /deploy/ 
2019-01-06 17:37:13,248 INFO  /deploy/ 
2019-01-06 20:36:12,705 INFO  Kname: samba_conf was get. 
2019-01-06 20:36:12,724 INFO  Kname: samba_conf was get. 
2019-01-06 20:36:12,727 INFO  Kname: samba_conf was get. 
2019-01-06 20:36:15,066 WARNING  Not Found: /favicon.ico 
2019-01-06 20:37:41,251 INFO  /deploy/ 
2019-01-06 20:37:43,801 INFO  /deploy/ 
2019-01-06 20:38:41,046 INFO  /deploy/ 
2019-01-06 20:39:44,051 WARNING  Not Found: /path/to/file 
2019-01-06 20:50:41,201 INFO  /deploy/ 
2019-01-06 21:06:43,052 INFO  Kname: samba_conf was get. 
2019-01-06 21:06:43,053 INFO  Kname: samba_conf was get. 
2019-01-06 21:06:43,054 INFO  Kname: samba_conf was get. 
2019-01-06 21:06:45,578 WARNING  Not Found: /favicon.ico 
2019-01-06 21:06:52,931 WARNING  Not Found: /favicon.ico 
2019-01-06 21:06:54,574 WARNING  Not Found: /favicon.ico 
2019-01-06 21:09:35,086 INFO  /deploy/ 
2019-01-06 21:09:35,352 WARNING  Not Found: /favicon.ico 
2019-01-06 21:16:50,680 WARNING  Not Found: /path/to/file 
2019-01-06 21:24:53,410 WARNING  Not Found: /path/to/file 
2019-01-06 21:46:08,414 WARNING  Not Found: /path/to/file 
2019-01-06 21:46:30,319 INFO  /deploy/ 
2019-01-06 21:47:26,631 WARNING  Not Found: /favicon.ico 
2019-01-06 21:53:17,082 INFO  /deploy/ 
2019-01-06 21:53:38,290 INFO  /deploy/ 
2019-01-06 21:54:06,709 WARNING  Not Found: /path/to/file 
2019-01-06 21:54:12,259 WARNING  Not Found: /path/to/file 
2019-01-06 21:54:17,251 WARNING  Not Found: /path/to/file 
2019-01-06 22:06:46,384 WARNING  Not Found: /apple-touch-icon-precomposed.png 
2019-01-06 22:06:46,543 WARNING  Not Found: /apple-touch-icon.png 
2019-01-06 22:06:46,683 WARNING  Not Found: /favicon.ico 
2019-01-06 22:06:46,820 WARNING  Not Found: /apple-touch-icon-precomposed.png 
2019-01-06 22:06:46,967 WARNING  Not Found: /apple-touch-icon.png 
2019-01-06 22:06:47,104 WARNING  Not Found: /favicon.ico 
2019-01-06 22:06:47,384 WARNING  Not Found: /apple-touch-icon-precomposed.png 
2019-01-06 22:06:47,564 WARNING  Not Found: /apple-touch-icon.png 
2019-01-06 22:06:47,705 WARNING  Not Found: /favicon.ico 
2019-01-06 22:06:47,845 WARNING  Not Found: /apple-touch-icon-precomposed.png 
2019-01-06 22:06:48,008 WARNING  Not Found: /apple-touch-icon.png 
2019-01-06 22:06:48,167 WARNING  Not Found: /favicon.ico 
2019-01-06 22:12:22,752 WARNING  Not Found: /apple-touch-icon-precomposed.png 
2019-01-06 22:12:22,917 WARNING  Not Found: /apple-touch-icon.png 
2019-01-06 22:13:15,928 INFO  /deploy/ 
2019-01-06 22:13:21,478 INFO  /deploy/ 
2019-01-06 22:13:55,073 INFO  /deploy/ 
2019-01-06 22:14:11,347 INFO  /deploy/ 
2019-01-06 22:24:58,497 INFO  /deploy/ 
2019-01-06 22:26:07,356 INFO  /deploy/ 
2019-01-06 22:27:10,430 WARNING  Not Found: /path/to/file 
2019-01-06 22:27:22,190 INFO  /deploy/ 
2019-01-06 22:28:01,343 INFO  /deploy/ 
2019-01-06 22:28:15,673 INFO  /deploy/ 
2019-01-06 22:29:00,954 INFO  /deploy/ 
2019-01-06 22:29:40,632 INFO  /deploy/ 
2019-01-06 22:29:43,265 INFO  /deploy/ 
2019-01-06 22:30:38,601 WARNING  Not Found: /path/to/file 
2019-01-06 22:30:49,887 INFO  /deploy/ 
2019-01-06 22:49:48,123 INFO  /deploy/ 
2019-01-06 22:50:39,103 INFO  /deploy/ 
2019-01-06 22:51:01,870 INFO  /deploy/ 
2019-01-06 22:51:51,780 INFO  /deploy/ 
2019-01-06 22:52:42,236 INFO  /deploy/ 
2019-01-06 22:54:44,626 INFO  /deploy/ 
2019-01-06 22:55:17,612 INFO  /deploy/ 
2019-01-06 22:56:35,032 INFO  /deploy/ 
2019-01-06 22:56:52,138 INFO  /deploy/ 
2019-01-06 22:57:02,333 INFO  /deploy/ 
2019-01-06 22:57:06,837 WARNING  Not Found: /favicon.ico 
2019-01-06 22:57:38,252 INFO  /deploy/ 
2019-01-06 22:58:33,893 INFO  /deploy/ 
2019-01-06 22:58:58,794 INFO  /deploy/ 
2019-01-06 22:59:51,459 INFO  /deploy/ 
2019-01-07 19:01:21,932 INFO  Kname: samba_conf was get. 
2019-01-07 19:01:21,933 INFO  Kname: samba_conf was get. 
2019-01-07 19:01:21,934 INFO  Kname: samba_conf was get. 
2019-01-07 19:01:25,469 WARNING  Not Found: /favicon.ico 
2019-01-07 19:01:30,614 WARNING  Not Found: /favicon.ico 
2019-01-07 19:01:42,769 WARNING  Not Found: /favicon.ico 
2019-01-07 19:01:55,090 INFO  /deploy/ 
2019-01-07 19:01:55,283 WARNING  Not Found: /favicon.ico 
2019-01-07 19:02:04,611 WARNING  Not Found: /favicon.ico 
2019-01-07 19:02:45,105 INFO  /deploy/ 
2019-01-07 19:03:03,029 INFO  /deploy/ 
2019-01-07 19:03:05,987 INFO  /deploy/ 
2019-01-07 19:12:36,434 WARNING  Forbidden (CSRF cookie not set.): / 
2019-01-07 19:12:36,508 WARNING  Not Found: /webdav/ 
2019-01-07 19:12:38,470 WARNING  Not Found: /help.php 
2019-01-07 19:12:38,515 WARNING  Not Found: /java.php 
2019-01-07 19:12:38,548 WARNING  Not Found: /_query.php 
2019-01-07 19:12:38,591 WARNING  Not Found: /test.php 
2019-01-07 19:12:38,632 WARNING  Not Found: /db_cts.php 
2019-01-07 19:12:38,689 WARNING  Not Found: /db_pma.php 
2019-01-07 19:12:38,740 WARNING  Not Found: /logon.php 
2019-01-07 19:12:38,773 WARNING  Not Found: /help-e.php 
2019-01-07 19:12:38,843 WARNING  Not Found: /license.php 
2019-01-07 19:12:38,893 WARNING  Not Found: /log.php 
2019-01-07 19:12:39,361 WARNING  Not Found: /hell.php 
2019-01-07 19:12:39,468 WARNING  Not Found: /pmd_online.php 
2019-01-07 19:12:39,589 WARNING  Not Found: /x.php 
2019-01-07 19:12:39,685 WARNING  Not Found: /shell.php 
2019-01-07 19:12:39,748 WARNING  Not Found: /htdocs.php 
2019-01-07 19:12:39,807 WARNING  Not Found: /desktop.ini.php 
2019-01-07 19:12:39,867 WARNING  Not Found: /z.php 
2019-01-07 19:12:39,958 WARNING  Not Found: /lala.php 
2019-01-07 19:12:40,769 WARNING  Not Found: /lala-dpr.php 
2019-01-07 19:12:40,847 WARNING  Not Found: /wpc.php 
2019-01-07 19:12:40,909 WARNING  Not Found: /wpo.php 
2019-01-07 19:12:40,989 WARNING  Not Found: /text.php 
2019-01-07 19:12:41,073 WARNING  Not Found: /wp-config.php 
2019-01-07 19:12:41,183 WARNING  Not Found: /muhstik.php 
2019-01-07 19:12:42,469 WARNING  Not Found: /muhstik2.php 
2019-01-07 19:12:42,501 WARNING  Not Found: /muhstiks.php 
2019-01-07 19:12:42,534 WARNING  Not Found: /muhstik-dpr.php 
2019-01-07 19:12:42,595 WARNING  Not Found: /lol.php 
2019-01-07 19:12:42,642 WARNING  Not Found: /uploader.php 
2019-01-07 19:12:42,695 WARNING  Not Found: /cmd.php 
2019-01-07 19:12:42,735 WARNING  Not Found: /cmx.php 
2019-01-07 19:12:42,778 WARNING  Not Found: /cmv.php 
2019-01-07 19:12:42,835 WARNING  Not Found: /cmdd.php 
2019-01-07 19:12:43,306 WARNING  Not Found: /knal.php 
2019-01-07 19:12:43,365 WARNING  Not Found: /cmd.php 
2019-01-07 19:12:43,452 WARNING  Not Found: /shell.php 
2019-01-07 19:12:43,561 WARNING  Not Found: /appserv.php 
2019-01-07 19:12:43,662 WARNING  Not Found: /scripts/setup.php 
2019-01-07 19:12:43,739 WARNING  Not Found: /phpmyadmin/scripts/setup.php 
2019-01-07 19:12:43,803 WARNING  Not Found: /phpMyAdmin/scripts/setup.php 
2019-01-07 19:12:43,872 WARNING  Not Found: /phpmyadmin/scripts/db___.init.php 
2019-01-07 19:12:43,952 WARNING  Not Found: /phpMyAdmin/scripts/db___.init.php 
2019-01-07 19:12:44,069 WARNING  Not Found: /plugins/weathermap/editor.php 
2019-01-07 19:12:44,157 WARNING  Not Found: /cacti/plugins/weathermap/editor.php 
2019-01-07 19:12:44,213 WARNING  Not Found: /wuwu11.php 
2019-01-07 19:12:44,257 WARNING  Not Found: /xw.php 
2019-01-07 19:12:44,314 WARNING  Not Found: /xw1.php 
2019-01-07 19:12:44,411 WARNING  Not Found: /9678.php 
2019-01-07 19:12:44,493 WARNING  Not Found: /wc.php 
2019-01-07 19:12:44,591 WARNING  Not Found: /xx.php 
2019-01-07 19:12:44,719 WARNING  Not Found: /s.php 
2019-01-07 19:12:44,791 WARNING  Not Found: /w.php 
2019-01-07 19:12:44,879 WARNING  Not Found: /sheep.php 
2019-01-07 19:12:44,960 WARNING  Not Found: /qaq.php 
2019-01-07 19:12:45,060 WARNING  Not Found: /db.init.php 
2019-01-07 19:12:45,159 WARNING  Not Found: /db_session.init.php 
2019-01-07 19:12:45,230 WARNING  Not Found: /db__.init.php 
2019-01-07 19:12:45,338 WARNING  Not Found: /wp-admins.php 
2019-01-07 19:12:45,425 WARNING  Not Found: /m.php 
2019-01-07 19:12:45,524 WARNING  Not Found: /db_dataml.php 
2019-01-07 19:12:45,624 WARNING  Not Found: /db_desql.php 
2019-01-07 19:12:45,741 WARNING  Not Found: /mx.php 
2019-01-07 19:12:45,827 WARNING  Not Found: /wshell.php 
2019-01-07 19:12:45,913 WARNING  Not Found: /xshell.php 
2019-01-07 19:12:45,982 WARNING  Not Found: /qq.php 
2019-01-07 19:12:46,075 WARNING  Not Found: /conflg.php 
2019-01-07 19:12:46,181 WARNING  Not Found: /conflg.php 
2019-01-07 19:12:46,256 WARNING  Not Found: /lindex.php 
2019-01-07 19:12:46,378 WARNING  Not Found: /phpstudy.php 
2019-01-07 19:12:46,494 WARNING  Not Found: /phpStudy.php 
2019-01-07 19:12:46,580 WARNING  Not Found: /weixiao.php 
2019-01-07 19:12:46,657 WARNING  Not Found: /feixiang.php 
2019-01-07 19:12:46,752 WARNING  Not Found: /ak47.php 
2019-01-07 19:12:50,467 WARNING  Not Found: /xiao.php 
2019-01-07 19:12:50,496 WARNING  Not Found: /yao.php 
2019-01-07 19:12:50,525 WARNING  Not Found: /defect.php 
2019-01-07 19:12:50,560 WARNING  Not Found: /webslee.php 
2019-01-07 19:12:50,598 WARNING  Not Found: /q.php 
2019-01-07 19:12:50,629 WARNING  Not Found: /pe.php 
2019-01-07 19:12:50,662 WARNING  Not Found: /hm.php 
2019-01-07 19:12:50,713 WARNING  Not Found: /cainiao.php 
2019-01-07 19:12:50,757 WARNING  Not Found: /zuoshou.php 
2019-01-07 19:12:50,804 WARNING  Not Found: /zuo.php 
2019-01-07 19:12:50,872 WARNING  Not Found: /aotu.php 
2019-01-07 19:12:50,961 WARNING  Not Found: /aotu7.php 
2019-01-07 19:12:51,073 WARNING  Not Found: /cmd.php 
2019-01-07 19:12:51,155 WARNING  Not Found: /bak.php 
2019-01-07 19:12:51,267 WARNING  Not Found: /system.php 
2019-01-07 19:12:51,329 WARNING  Not Found: /l6.php 
2019-01-07 19:12:51,423 WARNING  Not Found: /l7.php 
2019-01-07 19:12:51,534 WARNING  Not Found: /l8.php 
2019-01-07 19:12:51,660 WARNING  Not Found: /q.php 
2019-01-07 19:12:51,729 WARNING  Not Found: /56.php 
2019-01-07 19:12:51,778 WARNING  Not Found: /mz.php 
2019-01-07 19:12:51,832 WARNING  Not Found: /xx.php 
2019-01-07 19:12:52,524 WARNING  Not Found: /yumo.php 
2019-01-07 19:12:52,618 WARNING  Not Found: /min.php 
2019-01-07 19:12:52,698 WARNING  Not Found: /wan.php 
2019-01-07 19:12:52,814 WARNING  Not Found: /wanan.php 
2019-01-07 19:12:54,466 WARNING  Not Found: /ssaa.php 
2019-01-07 19:12:54,497 WARNING  Not Found: /qq.php 
2019-01-07 19:12:54,534 WARNING  Not Found: /aw.php 
2019-01-07 19:12:54,566 WARNING  Not Found: /12.php 
2019-01-07 19:12:54,596 WARNING  Not Found: /hh.php 
2019-01-07 19:12:54,631 WARNING  Not Found: /ak.php 
2019-01-07 19:12:54,668 WARNING  Not Found: /ip.php 
2019-01-07 19:12:54,721 WARNING  Not Found: /infoo.php 
2019-01-07 19:12:54,759 WARNING  Not Found: /qq.php 
2019-01-07 19:12:54,809 WARNING  Not Found: /qwe.php 
2019-01-07 19:12:56,084 WARNING  Not Found: /1213.php 
2019-01-07 19:12:56,163 WARNING  Not Found: /post.php 
2019-01-07 19:12:56,229 WARNING  Not Found: /aaaa.php 
2019-01-07 19:12:56,299 WARNING  Not Found: /h1.php 
2019-01-07 19:12:56,410 WARNING  Not Found: /test.php 
2019-01-07 19:12:56,544 WARNING  Not Found: /3.php 
2019-01-07 19:12:56,670 WARNING  Not Found: /phpinfi.php 
2019-01-07 19:12:56,775 WARNING  Not Found: /9510.php 
2019-01-07 19:12:56,851 WARNING  Not Found: /python.php 
2019-01-07 19:12:56,919 WARNING  Not Found: /default.php 
2019-01-07 19:12:57,016 WARNING  Not Found: /sean.php 
2019-01-07 19:12:57,120 WARNING  Not Found: /app.php 
2019-01-07 19:12:57,186 WARNING  Not Found: /help.php 
2019-01-07 19:12:57,240 WARNING  Not Found: /tiandi.php 
2019-01-07 19:12:57,327 WARNING  Not Found: /miao.php 
2019-01-07 19:12:57,404 WARNING  Not Found: /xz.php 
2019-01-07 19:12:57,516 WARNING  Not Found: /linuxse.php 
2019-01-07 19:12:58,186 WARNING  Not Found: /zuoindex.php 
2019-01-07 19:12:58,292 WARNING  Not Found: /zshmindex.php 
2019-01-07 19:12:58,373 WARNING  Not Found: /tomcat.php 
2019-01-07 19:12:58,442 WARNING  Not Found: /ceshi.php 
2019-01-07 19:12:58,525 WARNING  Not Found: /1hou.php 
2019-01-07 19:12:58,614 WARNING  Not Found: /ou2.php 
2019-01-07 19:12:58,691 WARNING  Not Found: /zuos.php 
2019-01-07 19:12:58,784 WARNING  Not Found: /zuoss.php 
2019-01-07 19:12:58,877 WARNING  Not Found: /zuoshss.php 
2019-01-07 19:12:58,915 WARNING  Not Found: /boots.php 
2019-01-07 19:12:58,959 WARNING  Not Found: /she.php 
2019-01-07 19:12:59,018 WARNING  Not Found: /s.php 
2019-01-07 19:12:59,090 WARNING  Not Found: /qw.php 
2019-01-07 19:12:59,138 WARNING  Not Found: /test.php 
2019-01-07 19:12:59,203 WARNING  Not Found: /caonma.php 
2019-01-07 19:13:02,479 WARNING  Not Found: /wcp.php 
2019-01-07 19:13:02,507 WARNING  Not Found: /u.php 
2019-01-07 19:13:02,542 WARNING  Not Found: /uuu.php 
2019-01-07 19:13:02,575 WARNING  Not Found: /sss.php 
2019-01-07 19:13:02,603 WARNING  Not Found: /1.php 
2019-01-07 19:13:02,637 WARNING  Not Found: /2.php 
2019-01-07 19:13:02,687 WARNING  Not Found: /core.php 
2019-01-07 19:13:02,753 WARNING  Not Found: /qaz.php 
2019-01-07 19:13:02,807 WARNING  Not Found: /sha.php 
2019-01-07 19:13:02,860 WARNING  Not Found: /ppx.php 
2019-01-07 19:13:02,958 WARNING  Not Found: /1.php 
2019-01-07 19:13:03,053 WARNING  Not Found: /confg.php 
2019-01-07 19:13:03,114 WARNING  Not Found: /conf1g.php 
2019-01-07 19:13:03,191 WARNING  Not Found: /confg.php 
2019-01-07 19:13:03,239 WARNING  Not Found: /confg.php 
2019-01-07 19:13:03,360 WARNING  Not Found: /confg.php 
2019-01-07 19:13:03,456 WARNING  Not Found: /ver.php 
2019-01-07 19:13:04,118 WARNING  Not Found: /hack.php 
2019-01-07 19:13:04,227 WARNING  Not Found: /qa.php 
2019-01-07 19:13:04,323 WARNING  Not Found: /Ss.php 
2019-01-07 19:13:04,405 WARNING  Not Found: /xxx.php 
2019-01-07 19:13:04,507 WARNING  Not Found: /92.php 
2019-01-07 19:13:04,624 WARNING  Not Found: /z.php 
2019-01-07 19:13:04,733 WARNING  Not Found: /x.php 
2019-01-07 19:13:04,823 WARNING  Not Found: /dexgp.php 
2019-01-07 19:13:06,475 WARNING  Not Found: /nuoxi.php 
2019-01-07 19:13:06,504 WARNING  Not Found: /godkey.php 
2019-01-07 19:13:06,535 WARNING  Not Found: /okokok.php 
2019-01-07 19:13:06,570 WARNING  Not Found: /erwa.php 
2019-01-07 19:13:06,598 WARNING  Not Found: /pma.php 
2019-01-07 19:13:06,626 WARNING  Not Found: /ruyi.php 
2019-01-07 19:13:06,655 WARNING  Not Found: /51314.php 
2019-01-07 19:13:06,710 WARNING  Not Found: /5201314.php 
2019-01-07 19:13:06,756 WARNING  Not Found: /fusheng.php 
2019-01-07 19:13:06,799 WARNING  Not Found: /general.php 
2019-01-07 19:13:06,848 WARNING  Not Found: /repeat.php 
2019-01-07 19:13:06,933 WARNING  Not Found: /ldw.php 
2019-01-07 19:13:07,061 WARNING  Not Found: /api.php 
2019-01-07 19:13:07,137 WARNING  Not Found: /s1.php 
2019-01-07 19:13:07,217 WARNING  Not Found: /xiaodai.php 
2019-01-07 19:13:07,297 WARNING  Not Found: /hello.php 
2019-01-07 19:13:07,374 WARNING  Not Found: /hello.php 
2019-01-07 19:13:07,472 WARNING  Not Found: /admn.php 
2019-01-07 19:13:07,584 WARNING  Not Found: /hell.php 
2019-01-07 19:13:07,671 WARNING  Not Found: /xp.php 
2019-01-07 19:13:07,835 WARNING  Not Found: /1.php 
2019-01-07 19:13:08,361 WARNING  Not Found: /2.php 
2019-01-07 19:13:08,476 WARNING  Not Found: /p.php 
2019-01-07 19:13:08,588 WARNING  Not Found: /1.php 
2019-01-07 19:13:08,691 WARNING  Not Found: /a.php 
2019-01-07 19:13:08,786 WARNING  Not Found: /m.php 
2019-01-07 19:13:09,859 WARNING  Not Found: /conf.php 
2019-01-07 19:13:09,936 WARNING  Not Found: /123.php 
2019-01-07 19:13:10,008 WARNING  Not Found: /HX.php 
2019-01-07 19:13:10,055 WARNING  Not Found: /diy.php 
2019-01-07 19:13:10,103 WARNING  Not Found: /666.php 
2019-01-07 19:13:10,172 WARNING  Not Found: /777.php 
2019-01-07 19:13:10,236 WARNING  Not Found: /qwq.php 
2019-01-07 19:13:10,326 WARNING  Not Found: /qwqw.php 
2019-01-07 19:13:10,407 WARNING  Not Found: /.php 
2019-01-07 19:13:10,483 WARNING  Not Found: /infos.php 
2019-01-07 19:13:10,576 WARNING  Not Found: /x.php 
2019-01-07 19:13:10,700 WARNING  Not Found: /lucky.php 
2019-01-07 19:13:10,818 WARNING  Not Found: /htfr.php 
2019-01-07 19:13:14,468 WARNING  Not Found: /zzk.php 
2019-01-07 19:13:14,500 WARNING  Not Found: /toor.php 
2019-01-07 19:13:14,530 WARNING  Not Found: /uu.php 
2019-01-07 19:13:14,561 WARNING  Not Found: /aa.php 
2019-01-07 19:13:14,592 WARNING  Not Found: /wb.php 
2019-01-07 19:13:14,619 WARNING  Not Found: /yj.php 
2019-01-07 19:13:14,650 WARNING  Not Found: /z.php 
2019-01-07 19:13:14,690 WARNING  Not Found: /7.php 
2019-01-07 19:13:14,750 WARNING  Not Found: /xiaoma.php 
2019-01-07 19:13:14,776 WARNING  Not Found: /xiaomae.php 
2019-01-07 19:13:14,820 WARNING  Not Found: /xiaomar.php 
2019-01-07 19:13:14,876 WARNING  Not Found: /qq.php 
2019-01-07 19:13:14,970 WARNING  Not Found: /data.php 
2019-01-07 19:13:15,098 WARNING  Not Found: /log.php 
2019-01-07 19:13:15,171 WARNING  Not Found: /fack.php 
2019-01-07 19:13:15,240 WARNING  Not Found: /angge.php 
2019-01-07 19:13:15,305 WARNING  Not Found: /cxfm666.php 
2019-01-07 19:13:15,411 WARNING  Not Found: /db.php 
2019-01-07 19:13:15,541 WARNING  Not Found: /hacly.php 
2019-01-07 19:13:15,658 WARNING  Not Found: /xiaomo.php 
2019-01-07 19:13:15,742 WARNING  Not Found: /xiaoyu.php 
2019-01-07 19:13:15,807 WARNING  Not Found: /xiaohei.php 
2019-01-07 19:13:15,872 WARNING  Not Found: /j.php 
2019-01-07 19:13:15,951 WARNING  Not Found: /qq5262.php 
2019-01-07 19:13:16,081 WARNING  Not Found: /lost.php 
2019-01-07 19:13:16,192 WARNING  Not Found: /php.php 
2019-01-07 19:13:16,293 WARNING  Not Found: /win.php 
2019-01-07 19:13:16,399 WARNING  Not Found: /win1.php 
2019-01-07 19:13:16,503 WARNING  Not Found: /linux.php 
2019-01-07 19:13:16,634 WARNING  Not Found: /linux1.php 
2019-01-07 19:13:16,718 WARNING  Not Found: /MCLi.php 
2019-01-07 19:13:16,793 WARNING  Not Found: /MCLi.php 
2019-01-07 19:13:18,479 WARNING  Not Found: /zxc0.php 
2019-01-07 19:13:18,508 WARNING  Not Found: /zxc1.php 
2019-01-07 19:13:18,536 WARNING  Not Found: /zxc2.php 
2019-01-07 19:13:18,567 WARNING  Not Found: /indexa.php 
2019-01-07 19:13:18,597 WARNING  Not Found: /lx.php 
2019-01-07 19:13:18,627 WARNING  Not Found: /api.php 
2019-01-07 19:13:18,657 WARNING  Not Found: /index1.php 
2019-01-07 19:13:18,700 WARNING  Not Found: /info.php 
2019-01-07 19:13:18,731 WARNING  Not Found: /info1.php 
2019-01-07 19:13:18,761 WARNING  Not Found: /aaaaaa1.php 
2019-01-07 19:13:18,795 WARNING  Not Found: /up.php 
2019-01-07 19:13:18,851 WARNING  Not Found: /test123.php 
2019-01-07 19:13:18,910 WARNING  Not Found: /fb.php 
2019-01-07 19:13:19,013 WARNING  Not Found: /paylog.php 
2019-01-07 19:13:19,085 WARNING  Not Found: /51.php 
2019-01-07 19:13:19,151 WARNING  Not Found: /cadre.php 
2019-01-07 19:13:19,243 WARNING  Not Found: /mm.php 
2019-01-07 19:13:19,310 WARNING  Not Found: /test.php 
2019-01-07 19:13:19,376 WARNING  Not Found: /1q.php 
2019-01-07 19:13:19,468 WARNING  Not Found: /1111.php 
2019-01-07 19:13:20,182 WARNING  Not Found: /errors.php 
2019-01-07 19:13:20,253 WARNING  Not Found: /index.php 
2019-01-07 19:13:20,358 WARNING  Not Found: /phpmyadmin/index.php 
2019-01-07 19:13:20,435 WARNING  Not Found: /phpMyAdmin/index.php 
2019-01-07 19:13:20,526 WARNING  Not Found: /pmd/index.php 
2019-01-07 19:13:20,609 WARNING  Not Found: /pma/index.php 
2019-01-07 19:13:20,729 WARNING  Not Found: /PMA/index.php 
2019-01-07 19:13:21,832 WARNING  Not Found: /PMA2/index.php 
2019-01-07 19:13:22,231 WARNING  Not Found: /pmamy/index.php 
2019-01-07 19:13:22,314 WARNING  Not Found: /pmamy2/index.php 
2019-01-07 19:13:22,418 WARNING  Not Found: /mysql/index.php 
2019-01-07 19:13:22,508 WARNING  Not Found: /admin/index.php 
2019-01-07 19:13:22,619 WARNING  Not Found: /db/index.php 
2019-01-07 19:13:22,697 WARNING  Not Found: /dbadmin/index.php 
2019-01-07 19:13:22,769 WARNING  Not Found: /web/phpMyAdmin/index.php 
2019-01-07 19:13:22,851 WARNING  Not Found: /admin/pma/index.php 
2019-01-07 19:13:26,464 WARNING  Not Found: /admin/PMA/index.php 
2019-01-07 19:13:26,503 WARNING  Not Found: /admin/mysql/index.php 
2019-01-07 19:13:26,555 WARNING  Not Found: /admin/mysql2/index.php 
2019-01-07 19:13:26,597 WARNING  Not Found: /admin/phpmyadmin/index.php 
2019-01-07 19:13:26,641 WARNING  Not Found: /admin/phpMyAdmin/index.php 
2019-01-07 19:13:26,701 WARNING  Not Found: /admin/phpmyadmin2/index.php 
2019-01-07 19:13:26,753 WARNING  Not Found: /mysqladmin/index.php 
2019-01-07 19:13:26,814 WARNING  Not Found: /mysql-admin/index.php 
2019-01-07 19:13:26,871 WARNING  Not Found: /mysql_admin/index.php 
2019-01-07 19:13:26,914 WARNING  Not Found: /phpadmin/index.php 
2019-01-07 19:13:27,031 WARNING  Not Found: /phpAdmin/index.php 
2019-01-07 19:13:27,107 WARNING  Not Found: /phpmyadmin0/index.php 
2019-01-07 19:13:27,197 WARNING  Not Found: /phpmyadmin1/index.php 
2019-01-07 19:13:27,265 WARNING  Not Found: /phpmyadmin2/index.php 
2019-01-07 19:13:27,328 WARNING  Not Found: /phpMyAdmin-4.4.0/index.php 
2019-01-07 19:13:27,393 WARNING  Not Found: /myadmin/index.php 
2019-01-07 19:13:27,503 WARNING  Not Found: /myadmin2/index.php 
2019-01-07 19:13:28,227 WARNING  Not Found: /xampp/phpmyadmin/index.php 
2019-01-07 19:13:28,335 WARNING  Not Found: /phpMyadmin_bak/index.php 
2019-01-07 19:13:28,467 WARNING  Not Found: /www/phpMyAdmin/index.php 
2019-01-07 19:13:28,597 WARNING  Not Found: /tools/phpMyAdmin/index.php 
2019-01-07 19:13:28,683 WARNING  Not Found: /phpmyadmin-old/index.php 
2019-01-07 19:13:28,788 WARNING  Not Found: /phpMyAdminold/index.php 
2019-01-07 19:13:28,891 WARNING  Not Found: /phpMyAdmin.old/index.php 
2019-01-07 19:13:30,466 WARNING  Not Found: /pma-old/index.php 
2019-01-07 19:13:30,497 WARNING  Not Found: /claroline/phpMyAdmin/index.php 
2019-01-07 19:13:30,526 WARNING  Not Found: /typo3/phpmyadmin/index.php 
2019-01-07 19:13:30,556 WARNING  Not Found: /phpma/index.php 
2019-01-07 19:13:30,593 WARNING  Not Found: /phpmyadmin/phpmyadmin/index.php 
2019-01-07 19:13:30,636 WARNING  Not Found: /phpMyAdmin/phpMyAdmin/index.php 
2019-01-07 19:13:30,675 WARNING  Not Found: /phpMyAbmin/index.php 
2019-01-07 19:13:30,746 WARNING  Not Found: /phpMyAdmin__/index.php 
2019-01-07 19:13:30,797 WARNING  Not Found: /phpMyAdmin+++---/index.php 
2019-01-07 19:13:30,854 WARNING  Not Found: /v/index.php 
2019-01-07 19:13:30,930 WARNING  Not Found: /phpmyadm1n/index.php 
2019-01-07 19:13:31,066 WARNING  Not Found: /phpMyAdm1n/index.php 
2019-01-07 19:13:31,129 WARNING  Not Found: /shaAdmin/index.php 
2019-01-07 19:13:31,224 WARNING  Not Found: /phpMyadmi/index.php 
2019-01-07 19:13:31,311 WARNING  Not Found: /phpMyAdmion/index.php 
2019-01-07 19:13:31,396 WARNING  Not Found: /MyAdmin/index.php 
2019-01-07 19:13:31,486 WARNING  Not Found: /phpMyAdmin1/index.php 
2019-01-07 19:13:31,605 WARNING  Not Found: /phpMyAdmin123/index.php 
2019-01-07 19:13:31,704 WARNING  Not Found: /pwd/index.php 
2019-01-07 19:13:31,762 WARNING  Not Found: /phpMyAdmina/index.php 
2019-01-07 19:13:31,818 WARNING  Not Found: /phpMydmin/index.php 
2019-01-07 19:13:31,879 WARNING  Not Found: /program/index.php 
2019-01-07 19:13:31,969 WARNING  Not Found: /shopdb/index.php 
2019-01-07 19:13:32,648 WARNING  Not Found: /phppma/index.php 
2019-01-07 19:13:32,720 WARNING  Not Found: /phpmy/index.php 
2019-01-07 19:13:32,773 WARNING  Not Found: /mysql/admin/index.php 
2019-01-07 19:13:32,845 WARNING  Not Found: /mysql/dbadmin/index.php 
2019-01-07 19:13:32,897 WARNING  Not Found: /mysql/sqlmanager/index.php 
2019-01-07 19:13:32,951 WARNING  Not Found: /mysql/mysqlmanager/index.php 
2019-01-07 19:13:33,034 WARNING  Not Found: /wp-content/plugins/portable-phpmyadmin/wp-pma-mod/index.php 
2019-01-07 19:13:33,125 WARNING  Not Found: /manager/html 
2019-01-07 19:16:11,893 WARNING  Not Found: /favicon.ico 
2019-01-07 19:20:26,345 INFO  /deploy/ 
2019-01-07 19:20:56,001 INFO  Kname: samba_conf was get. 
2019-01-07 19:20:56,002 INFO  Kname: samba_conf was get. 
2019-01-07 19:20:56,003 INFO  Kname: samba_conf was get. 
2019-01-07 19:21:01,251 INFO  /deploy/ 
2019-01-07 19:22:08,537 INFO  Kname: samba_conf was get. 
2019-01-07 19:22:08,539 INFO  Kname: samba_conf was get. 
2019-01-07 19:22:08,539 INFO  Kname: samba_conf was get. 
2019-01-07 19:25:35,275 INFO  /deploy/ 
2019-01-07 19:27:57,286 INFO  /deploy/ 
2019-01-07 19:28:31,763 INFO  /deploy/ 
2019-01-07 19:36:29,560 WARNING  Not Found: /favicon.ico 
2019-01-07 19:36:56,928 INFO  /deploy/ 
2019-01-07 20:14:51,392 INFO  /deploy/ 
2019-01-07 20:14:54,702 INFO  /deploy/ 
2019-01-07 20:16:04,981 INFO  /deploy/ 
2019-01-07 20:16:22,189 WARNING  Not Found: /path/to/file 
2019-01-07 20:16:56,327 INFO  /deploy/ 
2019-01-07 20:17:01,926 WARNING  Not Found: /path/to/file 
2019-01-07 20:17:12,937 INFO  /deploy/ 
2019-01-07 20:18:58,693 INFO  /deploy/ 
2019-01-07 20:19:33,888 INFO  /deploy/ 
2019-01-07 20:24:22,646 INFO  Kname: samba_conf was get. 
2019-01-07 20:24:22,647 INFO  Kname: samba_conf was get. 
2019-01-07 20:24:22,648 INFO  Kname: samba_conf was get. 
2019-01-07 20:24:53,154 INFO  /deploy/ 
2019-01-07 22:15:14,483 INFO  /deploy/ 
2019-01-08 22:39:36,554 INFO  Kname: samba_conf was get. 
2019-01-08 22:39:36,581 INFO  Kname: samba_conf was get. 
2019-01-08 22:39:36,584 INFO  Kname: samba_conf was get. 
2019-01-08 22:40:11,439 INFO  /deploy/ 
2019-01-09 21:20:36,079 INFO  Kname: samba_conf was get. 
2019-01-09 21:20:36,080 INFO  Kname: samba_conf was get. 
2019-01-09 21:20:36,081 INFO  Kname: samba_conf was get. 
2019-01-09 21:23:49,144 INFO  /deploy/ 
2019-01-09 21:24:44,195 INFO  /deploy/ 
2019-01-09 21:25:06,930 INFO  /deploy/ 
2019-01-09 21:26:41,551 INFO  /deploy/ 
2019-01-09 22:18:10,122 WARNING  Not Found: /dashboard 
2019-01-09 22:18:20,973 WARNING  Not Found: /dashboard 
2019-01-09 22:19:41,799 WARNING  Forbidden (CSRF token missing or incorrect.): / 
2019-01-09 22:19:48,169 WARNING  Forbidden (CSRF token missing or incorrect.): / 
2019-01-09 22:23:54,746 WARNING  Forbidden (CSRF token missing or incorrect.): / 
2019-01-09 22:31:44,413 WARNING  Forbidden (CSRF token missing or incorrect.): / 
2019-01-09 22:36:29,774 WARNING  Forbidden (CSRF token missing or incorrect.): / 
2019-01-09 22:37:31,611 WARNING  Forbidden (CSRF token missing or incorrect.): / 
2019-01-09 22:40:39,181 WARNING  Forbidden (CSRF token missing or incorrect.): / 
2019-01-09 22:40:41,614 WARNING  Forbidden (CSRF token missing or incorrect.): / 
2019-01-09 22:40:48,818 WARNING  Forbidden (CSRF token missing or incorrect.): / 
2019-01-09 22:40:50,255 WARNING  Forbidden (CSRF token missing or incorrect.): / 
2019-01-09 22:42:31,787 WARNING  Forbidden (CSRF token missing or incorrect.): / 
2019-01-09 22:47:57,870 WARNING  Forbidden (CSRF token missing or incorrect.): / 
2019-01-09 22:50:26,322 WARNING  Forbidden (CSRF token missing or incorrect.): / 
2019-01-09 22:55:30,586 WARNING  Forbidden (CSRF token missing or incorrect.): / 
2019-01-09 22:56:04,267 WARNING  Forbidden (CSRF token missing or incorrect.): / 
2019-01-09 22:56:19,666 WARNING  Forbidden (CSRF token missing or incorrect.): / 
2019-01-09 23:04:08,906 WARNING  Forbidden (CSRF token missing or incorrect.): / 
2019-01-09 23:04:15,169 WARNING  Forbidden (CSRF token missing or incorrect.): / 
2019-01-09 23:04:21,847 WARNING  Forbidden (CSRF token missing or incorrect.): / 
2019-01-09 23:06:47,545 WARNING  Forbidden (CSRF token missing or incorrect.): / 
2019-01-09 23:25:25,615 WARNING  Forbidden (CSRF token missing or incorrect.): / 
2019-01-09 23:31:25,951 WARNING  Forbidden (CSRF token missing or incorrect.): / 
2019-01-09 23:32:46,119 WARNING  Forbidden (CSRF token missing or incorrect.): / 
2019-01-09 23:33:04,713 WARNING  Forbidden (CSRF token missing or incorrect.): / 
2019-01-09 23:44:50,278 WARNING  Not Found: /UserInfo/NewRegister 
2019-01-09 23:52:41,144 WARNING  Forbidden (CSRF token missing or incorrect.): / 
2019-01-09 23:52:47,981 WARNING  Forbidden (CSRF token missing or incorrect.): / 
2019-01-09 23:52:59,287 WARNING  Forbidden (CSRF token missing or incorrect.): / 
2019-01-09 23:53:03,544 WARNING  Forbidden (CSRF token missing or incorrect.): / 
2019-01-09 23:53:09,506 INFO  /deploy/ 
2019-01-11 22:23:47,967 INFO  Kname: samba_conf was get. 
2019-01-11 22:23:47,968 INFO  Kname: samba_conf was get. 
2019-01-11 22:23:47,969 INFO  Kname: samba_conf was get. 
2019-01-11 22:24:00,403 WARNING  Not Found: /apple-touch-icon-precomposed.png 
2019-01-11 22:24:05,955 WARNING  Not Found: /apple-touch-icon.png 
2019-01-11 22:24:06,913 WARNING  Not Found: /apple-touch-icon-precomposed.png 
2019-01-11 22:24:12,185 WARNING  Not Found: /apple-touch-icon.png 
2019-01-11 22:24:20,721 WARNING  Forbidden (CSRF token missing or incorrect.): / 
2019-01-11 22:25:13,010 WARNING  Forbidden (CSRF token missing or incorrect.): / 
2019-01-11 22:29:34,814 WARNING  Forbidden (CSRF token missing or incorrect.): / 
2019-01-11 22:29:43,291 WARNING  Forbidden (CSRF token missing or incorrect.): / 
2019-01-11 22:36:11,462 WARNING  Not Found: /public/index.php 
2019-01-11 22:36:15,136 WARNING  Not Found: /public/index.php 
2019-01-11 22:36:18,763 WARNING  Not Found: /public/index.php 
2019-01-11 22:52:42,056 WARNING  Not Found: /index.php 
2019-01-11 23:43:37,578 WARNING  Forbidden (CSRF token missing or incorrect.): / 
2019-01-11 23:48:05,209 WARNING  Forbidden (CSRF token missing or incorrect.): / 
2019-01-12 09:11:25,689 INFO  Kname: samba_conf was get. 
2019-01-12 09:11:25,690 INFO  Kname: samba_conf was get. 
2019-01-12 09:11:25,691 INFO  Kname: samba_conf was get. 
2019-01-12 09:11:37,724 WARNING  Not Found: /favicon.ico 
2019-01-12 09:19:27,961 INFO  Kname: samba_conf was get. 
2019-01-12 09:19:27,963 INFO  Kname: samba_conf was get. 
2019-01-12 09:19:27,964 INFO  Kname: samba_conf was get. 
2019-01-12 09:19:31,086 INFO  /deploy/ 
2019-01-12 09:24:09,946 WARNING  Not Found: /getuser/path/file 
2019-01-12 09:25:49,706 WARNING  Not Found: /getuser/path/file 
2019-01-12 09:40:16,827 WARNING  Forbidden (CSRF token missing or incorrect.): / 
2019-01-12 10:17:02,874 WARNING  Forbidden (CSRF token missing or incorrect.): / 
2019-01-12 10:22:20,852 WARNING  Forbidden (CSRF token missing or incorrect.): / 
2019-01-12 10:22:43,879 WARNING  Forbidden (CSRF token missing or incorrect.): / 
2019-01-12 10:24:20,795 WARNING  Forbidden (CSRF token missing or incorrect.): / 
2019-01-12 10:24:20,808 WARNING  Forbidden (CSRF token missing or incorrect.): / 
2019-01-12 10:25:18,262 WARNING  Forbidden (CSRF token missing or incorrect.): / 
2019-01-12 10:34:36,205 WARNING  Forbidden (CSRF token missing or incorrect.): / 
2019-01-12 10:35:15,680 WARNING  Forbidden (CSRF token missing or incorrect.): / 
2019-01-12 10:38:05,238 INFO  /deploy/ 
2019-01-12 10:39:34,844 INFO  /deploy/ 
2019-01-12 10:40:53,032 INFO  /deploy/ 
2019-01-12 10:41:13,527 INFO  /deploy/ 
2019-01-12 10:41:29,723 INFO  /deploy/ 
2019-01-12 10:44:01,579 INFO  /deploy/ 
2019-01-12 10:44:10,490 WARNING  Not Found: /path/to/file 
2019-01-12 10:51:47,284 ERROR  Internal Server Error: /consumer 
Traceback (most recent call last):
  File "/data/django/lib/python2.7/site-packages/django/core/handlers/base.py", line 108, in get_response
    response = middleware_method(request)
  File "/data/django/lib/python2.7/site-packages/django/middleware/common.py", line 84, in process_request
    "settings.") % (new_url[0], new_url[1]))
RuntimeError: You called this URL via POST, but the URL doesn't end in a slash and you have APPEND_SLASH set. Django can't redirect to the slash URL while maintaining POST data. Change your form to point to 118.89.49.101:8081/consumer/ (note the trailing slash), or set APPEND_SLASH=False in your Django settings.
2019-01-12 11:32:54,829 WARNING  Not Found: /http:/www.baidu.com/cache/global/img/gs.gif 
2019-01-12 11:43:58,663 WARNING  Not Found: /HNAP1/ 
2019-01-12 12:25:18,326 INFO  Kname: samba_conf was get. 
2019-01-12 12:25:18,327 INFO  Kname: samba_conf was get. 
2019-01-12 12:25:18,328 INFO  Kname: samba_conf was get. 
2019-01-12 12:30:41,163 INFO  /deploy/ 
2019-01-12 12:47:22,447 ERROR  Internal Server Error: /consumer/ 
Traceback (most recent call last):
  File "/data/django/lib/python2.7/site-packages/django/core/handlers/base.py", line 132, in get_response
    response = wrapped_callback(request, *callback_args, **callback_kwargs)
  File "/code/samba/web/consumer/views.py", line 24, in consumer
    return JsonResponse(json.dumps({"users":user,"dpment":dpment,"role":role}))
  File "/usr/lib64/python2.7/json/__init__.py", line 243, in dumps
    return _default_encoder.encode(obj)
  File "/usr/lib64/python2.7/json/encoder.py", line 207, in encode
    chunks = self.iterencode(o, _one_shot=True)
  File "/usr/lib64/python2.7/json/encoder.py", line 270, in iterencode
    return _iterencode(o, 0)
  File "/usr/lib64/python2.7/json/encoder.py", line 184, in default
    raise TypeError(repr(o) + " is not JSON serializable")
TypeError: [{'stat': True, 'role_name': u'admin', u'id': 1, 'desc': u'\u7cfb\u7edf\u7ba1\u7406\u5458'}, {'stat': True, 'role_name': u'manager', u'id': 2, 'desc': u'\u90e8\u95e8\u7ba1\u7406\u5458'}, {'stat': True, 'role_name': u'user', u'id': 3, 'desc': u'\u7528\u6237'}] is not JSON serializable
2019-01-12 12:51:07,318 WARNING  Forbidden (CSRF token missing or incorrect.): / 
2019-01-12 13:38:57,992 INFO  Kname: samba_conf was get. 
2019-01-12 13:38:57,993 INFO  Kname: samba_conf was get. 
2019-01-12 13:38:57,993 INFO  Kname: samba_conf was get. 
2019-01-12 14:07:12,495 ERROR  Internal Server Error: /consumer 
Traceback (most recent call last):
  File "/data/django/lib/python2.7/site-packages/django/core/handlers/base.py", line 108, in get_response
    response = middleware_method(request)
  File "/data/django/lib/python2.7/site-packages/django/middleware/common.py", line 84, in process_request
    "settings.") % (new_url[0], new_url[1]))
RuntimeError: You called this URL via POST, but the URL doesn't end in a slash and you have APPEND_SLASH set. Django can't redirect to the slash URL while maintaining POST data. Change your form to point to 118.89.49.101:8081/consumer/ (note the trailing slash), or set APPEND_SLASH=False in your Django settings.
2019-01-12 14:17:36,458 ERROR  Internal Server Error: /consumer 
Traceback (most recent call last):
  File "/data/django/lib/python2.7/site-packages/django/core/handlers/base.py", line 108, in get_response
    response = middleware_method(request)
  File "/data/django/lib/python2.7/site-packages/django/middleware/common.py", line 84, in process_request
    "settings.") % (new_url[0], new_url[1]))
RuntimeError: You called this URL via POST, but the URL doesn't end in a slash and you have APPEND_SLASH set. Django can't redirect to the slash URL while maintaining POST data. Change your form to point to 118.89.49.101:8081/consumer/ (note the trailing slash), or set APPEND_SLASH=False in your Django settings.
2019-01-12 14:38:39,473 INFO  Kname: samba_conf was get. 
2019-01-12 14:38:39,474 INFO  Kname: samba_conf was get. 
2019-01-12 14:38:39,475 INFO  Kname: samba_conf was get. 
2019-01-12 14:38:56,448 WARNING  Not Found: /path/to/file 
2019-01-12 14:39:55,876 WARNING  Not Found: /path/to/file 
2019-01-12 14:40:25,571 WARNING  Not Found: /path/to/file 
2019-01-12 14:46:24,352 WARNING  Not Found: /path/to/file 
2019-01-12 14:48:25,336 WARNING  Not Found: /consumer/user_delete 
2019-01-12 15:12:59,489 WARNING  Not Found: /consumer/user_delete 
2019-01-12 15:40:50,623 INFO  /deploy/ 
2019-01-12 15:40:53,975 INFO  /deploy/ 
2019-01-12 15:49:02,141 INFO  /deploy/ 
2019-01-12 15:49:04,940 INFO  /deploy/ 
2019-01-12 15:49:50,400 WARNING  Not Found: /department/edit_department 
2019-01-12 15:50:25,719 INFO  /deploy/ 
2019-01-12 15:56:39,065 INFO  /deploy/ 
2019-01-12 15:59:45,709 WARNING  Not Found: /consumer/user_delete 
2019-01-12 16:01:43,510 INFO  /deploy/ 
2019-01-12 16:02:02,403 INFO  /deploy/ 
2019-01-12 16:04:49,447 INFO  /deploy/ 
2019-01-12 16:15:09,075 INFO  /deploy/ 
2019-01-12 16:15:10,504 INFO  /deploy/ 
2019-01-12 16:19:01,582 INFO  /deploy/ 
2019-01-12 16:20:50,141 INFO  /deploy/ 
2019-01-12 16:21:13,100 INFO  /deploy/ 
2019-01-12 16:21:13,860 INFO  /deploy/ 
2019-01-12 16:21:46,143 INFO  /deploy/ 
2019-01-12 16:21:47,021 INFO  /deploy/ 
2019-01-12 16:22:06,423 INFO  /deploy/ 
2019-01-12 16:25:25,843 INFO  /deploy/ 
2019-01-12 16:26:05,904 INFO  /deploy/ 
2019-01-12 16:28:28,061 INFO  /deploy/ 
2019-01-12 16:28:35,311 INFO  /deploy/ 
2019-01-12 16:44:01,357 INFO  /deploy/ 
2019-01-12 16:44:07,460 INFO  /deploy/ 
2019-01-12 16:44:44,198 WARNING  Not Found: /department/lock_department 
2019-01-12 16:44:55,001 WARNING  Not Found: /department/lock_department 
2019-01-12 16:48:16,167 WARNING  Not Found: /department/delete_department 
2019-01-12 16:48:21,162 WARNING  Not Found: /department/edit_department 
2019-01-12 16:50:15,329 WARNING  Not Found: /department/lock_department 
2019-01-12 16:50:55,156 INFO  /deploy/ 
2019-01-12 16:51:24,905 WARNING  Not Found: /department/delete_department 
2019-01-12 16:51:59,617 INFO  /deploy/ 
2019-01-12 16:52:10,058 INFO  /deploy/ 
2019-01-12 16:52:12,217 INFO  /deploy/ 
2019-01-12 16:55:02,784 INFO  /deploy/ 
2019-01-12 16:57:23,326 INFO  /deploy/ 
2019-01-12 17:08:08,675 INFO  /deploy/ 
2019-01-12 17:11:00,342 INFO  /deploy/ 
2019-01-12 17:11:00,430 INFO  /deploy/ 
2019-01-12 17:11:00,658 INFO  /deploy/ 
2019-01-12 17:12:26,990 INFO  /deploy/ 
2019-01-12 17:12:27,127 INFO  /deploy/ 
2019-01-12 17:13:05,990 INFO  /deploy/ 
2019-01-12 17:14:28,752 INFO  /deploy/ 
2019-01-12 17:16:39,505 INFO  /deploy/ 
2019-01-12 17:17:20,539 INFO  /deploy/ 
2019-01-12 17:17:20,731 INFO  /deploy/ 
2019-01-12 17:17:28,464 INFO  /deploy/ 
2019-01-12 17:19:32,686 INFO  /deploy/ 
2019-01-12 17:26:44,776 WARNING  Not Found: /department/delete_department 
2019-01-12 17:27:58,653 INFO  /deploy/ 
2019-01-12 17:27:58,726 INFO  /deploy/ 
2019-01-12 17:29:56,790 INFO  /deploy/ 
2019-01-12 17:30:54,458 INFO  /deploy/ 
2019-01-12 17:30:57,799 WARNING  Not Found: /deploy/set_deploy 
2019-01-12 17:30:59,188 INFO  /deploy/ 
2019-01-12 17:31:07,807 INFO  /deploy/ 
2019-01-12 17:31:11,781 WARNING  Not Found: /deploy/set_deploy 
2019-01-12 17:31:13,444 INFO  /deploy/ 
2019-01-12 17:31:18,762 WARNING  Not Found: /deploy/set_deploy 
2019-01-12 17:31:20,179 INFO  /deploy/ 
2019-01-12 17:31:42,108 WARNING  Not Found: /department/delete_department 
2019-01-12 17:31:48,806 WARNING  Not Found: /department/delete_department 
2019-01-12 17:32:01,096 INFO  /deploy/ 
2019-01-12 17:32:06,776 WARNING  Not Found: /deploy/set_deploy 
2019-01-12 17:32:08,133 INFO  /deploy/ 
2019-01-12 17:32:19,716 WARNING  Not Found: /deploy/set_deploy 
2019-01-12 17:32:22,527 INFO  /deploy/ 
2019-01-12 17:32:29,967 WARNING  Not Found: /deploy/set_deploy 
2019-01-12 17:32:31,726 INFO  /deploy/ 
2019-01-12 17:34:38,482 INFO  /deploy/ 
2019-01-12 17:34:42,319 WARNING  Not Found: /deploy/set_deploy 
2019-01-12 17:35:35,288 INFO  /deploy/ 
2019-01-12 17:35:38,528 WARNING  Not Found: /deploy/set_deploy 
2019-01-12 17:36:12,400 INFO  /deploy/ 
2019-01-12 17:36:16,798 WARNING  Not Found: /deploy/set_deploy 
2019-01-12 17:36:18,361 INFO  /deploy/ 
2019-01-12 17:41:36,773 INFO  /deploy/ 
2019-01-12 17:41:38,374 INFO  /deploy/ 
2019-01-12 17:41:42,145 INFO  /deploy/ 
2019-01-12 17:41:49,487 INFO  /deploy/ 
2019-01-12 17:42:29,549 INFO  /deploy/ 
2019-01-12 17:44:38,813 INFO  /deploy/ 
2019-01-12 17:44:42,816 WARNING  Not Found: /deploy/set_deploy 
2019-01-12 17:44:47,631 INFO  /deploy/ 
2019-01-12 17:44:53,541 WARNING  Not Found: /deploy/set_deploy 
2019-01-12 17:44:54,932 INFO  /deploy/ 
2019-01-12 17:48:21,324 INFO  /deploy/ 
2019-01-12 17:49:08,664 INFO  /deploy/ 
2019-01-12 17:50:42,381 INFO  /deploy/ 
2019-01-12 17:50:57,121 INFO  /deploy/ 
2019-01-12 17:51:04,422 INFO  /deploy/ 
2019-01-12 17:51:36,782 INFO  /deploy/ 
2019-01-12 17:52:17,562 WARNING  Not Found: /deploy/set_deploy 
2019-01-12 17:52:21,282 INFO  /deploy/ 
2019-01-12 17:52:27,502 WARNING  Not Found: /department/delete_department 
2019-01-12 17:52:33,702 WARNING  Not Found: /department/delete_department 
2019-01-12 17:52:38,862 WARNING  Not Found: /department/lock_department 
2019-01-12 17:57:30,305 INFO  /deploy/ 
2019-01-12 17:57:30,426 INFO  /deploy/ 
2019-01-12 17:58:09,254 INFO  /deploy/ 
2019-01-12 17:58:12,603 INFO  /deploy/ 
2019-01-12 17:59:48,370 INFO  /deploy/ 
2019-01-12 18:00:17,015 INFO  /deploy/ 
2019-01-12 18:02:02,094 WARNING  Not Found: /department/delete_department 
2019-01-12 18:02:20,007 WARNING  Not Found: /department/lock_department 
2019-01-12 18:02:36,645 WARNING  Not Found: /department/lock_department 
2019-01-12 18:02:39,611 INFO  /deploy/ 
2019-01-12 18:02:43,491 INFO  /deploy/ 
2019-01-12 18:13:30,350 WARNING  Not Found: /department/lock_department 
2019-01-12 18:19:20,637 INFO  /deploy/ 
2019-01-12 18:19:27,679 INFO  /deploy/ 
2019-01-12 22:24:41,512 INFO  Kname: samba_conf was get. 
2019-01-12 22:24:41,513 INFO  Kname: samba_conf was get. 
2019-01-12 22:24:41,514 INFO  Kname: samba_conf was get. 
2019-01-12 22:24:50,977 WARNING  Not Found: /consumer/user_delete 
2019-01-12 22:25:09,669 WARNING  Not Found: /consumer/user_delete 
2019-01-12 22:25:16,350 WARNING  Not Found: /department/lock_department 
2019-01-12 22:25:22,922 WARNING  Not Found: /consumer/user_delete 
2019-01-12 22:25:28,997 WARNING  Not Found: /consumer/user_delete 
2019-01-12 22:25:31,738 INFO  /deploy/ 
2019-01-12 22:25:41,475 WARNING  Not Found: /deploy/set_deploy 
2019-01-12 22:25:43,774 INFO  /deploy/ 
2019-01-12 22:25:50,914 WARNING  Not Found: /consumer/user_delete 
2019-01-12 22:26:40,547 WARNING  Not Found: /consumer/lock_user 
2019-01-12 22:26:56,075 WARNING  Forbidden (CSRF token missing or incorrect.): / 
2019-01-12 22:27:02,662 WARNING  Not Found: /consumer/edit_user 
2019-01-12 22:27:09,116 WARNING  Not Found: /consumer/user_delete 
2019-01-12 22:33:15,253 INFO  Kname: samba_conf was get. 
2019-01-12 22:33:15,255 INFO  Kname: samba_conf was get. 
2019-01-12 22:33:15,256 INFO  Kname: samba_conf was get. 
2019-01-12 22:33:15,259 WARNING  Not Found: /consumer/user_delete 
2019-01-12 22:34:14,948 INFO  Kname: samba_conf was get. 
2019-01-12 22:34:14,949 INFO  Kname: samba_conf was get. 
2019-01-12 22:34:14,950 INFO  Kname: samba_conf was get. 
2019-01-12 22:34:19,233 WARNING  Not Found: /consumer/user_delete 
2019-01-12 22:34:58,321 INFO  Kname: samba_conf was get. 
2019-01-12 22:34:58,322 INFO  Kname: samba_conf was get. 
2019-01-12 22:34:58,323 INFO  Kname: samba_conf was get. 
2019-01-12 22:35:02,405 WARNING  Not Found: /consumer/lock_user 
2019-01-12 22:35:59,375 WARNING  Not Found: /consumer/edit_user 
2019-01-12 22:36:04,696 WARNING  Not Found: /consumer/lock_user 
2019-01-12 22:36:11,875 WARNING  Not Found: /consumer/user_delete 
2019-01-12 22:36:17,423 WARNING  Not Found: /consumer/user_delete 
2019-01-12 22:37:21,139 INFO  Kname: samba_conf was get. 
2019-01-12 22:37:21,141 INFO  Kname: samba_conf was get. 
2019-01-12 22:37:21,141 INFO  Kname: samba_conf was get. 
2019-01-12 22:37:21,144 WARNING  Not Found: /consumer/lock_user 
2019-01-12 22:37:27,763 WARNING  Forbidden (CSRF token missing or incorrect.): / 
2019-01-12 22:37:32,824 WARNING  Not Found: /consumer/user_delete 
2019-01-13 10:20:13,008 INFO  Kname: samba_conf was get. 
2019-01-13 10:20:13,010 INFO  Kname: samba_conf was get. 
2019-01-13 10:20:13,010 INFO  Kname: samba_conf was get. 
2019-01-13 10:20:20,431 WARNING  Not Found: /department/lock_department 
2019-01-13 10:20:33,731 WARNING  Not Found: /department/delete_department 
2019-01-13 10:20:45,011 INFO  /deploy/ 
2019-01-13 11:29:42,702 INFO  Kname: samba_conf was get. 
2019-01-13 11:29:42,704 ERROR  Internal Server Error: / 
Traceback (most recent call last):
  File "/data/django/lib/python2.7/site-packages/django/core/handlers/base.py", line 119, in get_response
    resolver_match = resolver.resolve(request.path_info)
  File "/data/django/lib/python2.7/site-packages/django/core/urlresolvers.py", line 366, in resolve
    for pattern in self.url_patterns:
  File "/data/django/lib/python2.7/site-packages/django/core/urlresolvers.py", line 402, in url_patterns
    patterns = getattr(self.urlconf_module, "urlpatterns", self.urlconf_module)
  File "/data/django/lib/python2.7/site-packages/django/core/urlresolvers.py", line 396, in urlconf_module
    self._urlconf_module = import_module(self.urlconf_name)
  File "/usr/lib64/python2.7/importlib/__init__.py", line 37, in import_module
    __import__(name)
  File "/code/samba/web/web/urls.py", line 18, in <module>
    import dashboard.urls,browse.urls,consumer.urls,deploy.urls,department.urls
  File "/code/samba/web/consumer/urls.py", line 10, in <module>
    url(r'reset_pwd$',views.reset_pwd),
AttributeError: 'module' object has no attribute 'reset_pwd'
2019-01-13 11:29:44,677 ERROR  Internal Server Error: /favicon.ico 
Traceback (most recent call last):
  File "/data/django/lib/python2.7/site-packages/django/core/handlers/base.py", line 108, in get_response
    response = middleware_method(request)
  File "/data/django/lib/python2.7/site-packages/django/middleware/common.py", line 74, in process_request
    if (not urlresolvers.is_valid_path(request.path_info, urlconf) and
  File "/data/django/lib/python2.7/site-packages/django/core/urlresolvers.py", line 647, in is_valid_path
    resolve(path, urlconf)
  File "/data/django/lib/python2.7/site-packages/django/core/urlresolvers.py", line 522, in resolve
    return get_resolver(urlconf).resolve(path)
  File "/data/django/lib/python2.7/site-packages/django/core/urlresolvers.py", line 366, in resolve
    for pattern in self.url_patterns:
  File "/data/django/lib/python2.7/site-packages/django/core/urlresolvers.py", line 402, in url_patterns
    patterns = getattr(self.urlconf_module, "urlpatterns", self.urlconf_module)
  File "/data/django/lib/python2.7/site-packages/django/core/urlresolvers.py", line 396, in urlconf_module
    self._urlconf_module = import_module(self.urlconf_name)
  File "/usr/lib64/python2.7/importlib/__init__.py", line 37, in import_module
    __import__(name)
  File "/code/samba/web/web/urls.py", line 18, in <module>
    import dashboard.urls,browse.urls,consumer.urls,deploy.urls,department.urls
  File "/code/samba/web/consumer/urls.py", line 10, in <module>
    url(r'reset_pwd$',views.reset_pwd),
AttributeError: 'module' object has no attribute 'reset_pwd'
2019-01-13 11:30:14,321 ERROR  Internal Server Error: / 
Traceback (most recent call last):
  File "/data/django/lib/python2.7/site-packages/django/core/handlers/base.py", line 119, in get_response
    resolver_match = resolver.resolve(request.path_info)
  File "/data/django/lib/python2.7/site-packages/django/core/urlresolvers.py", line 366, in resolve
    for pattern in self.url_patterns:
  File "/data/django/lib/python2.7/site-packages/django/core/urlresolvers.py", line 402, in url_patterns
    patterns = getattr(self.urlconf_module, "urlpatterns", self.urlconf_module)
  File "/data/django/lib/python2.7/site-packages/django/core/urlresolvers.py", line 396, in urlconf_module
    self._urlconf_module = import_module(self.urlconf_name)
  File "/usr/lib64/python2.7/importlib/__init__.py", line 37, in import_module
    __import__(name)
  File "/code/samba/web/web/urls.py", line 18, in <module>
    import dashboard.urls,browse.urls,consumer.urls,deploy.urls,department.urls
  File "/code/samba/web/consumer/urls.py", line 11, in <module>
    url(r'unlock_user$',views.user_unlock)
AttributeError: 'module' object has no attribute 'user_unlock'
2019-01-13 11:30:15,017 ERROR  Internal Server Error: /favicon.ico 
Traceback (most recent call last):
  File "/data/django/lib/python2.7/site-packages/django/core/handlers/base.py", line 108, in get_response
    response = middleware_method(request)
  File "/data/django/lib/python2.7/site-packages/django/middleware/common.py", line 74, in process_request
    if (not urlresolvers.is_valid_path(request.path_info, urlconf) and
  File "/data/django/lib/python2.7/site-packages/django/core/urlresolvers.py", line 647, in is_valid_path
    resolve(path, urlconf)
  File "/data/django/lib/python2.7/site-packages/django/core/urlresolvers.py", line 522, in resolve
    return get_resolver(urlconf).resolve(path)
  File "/data/django/lib/python2.7/site-packages/django/core/urlresolvers.py", line 366, in resolve
    for pattern in self.url_patterns:
  File "/data/django/lib/python2.7/site-packages/django/core/urlresolvers.py", line 402, in url_patterns
    patterns = getattr(self.urlconf_module, "urlpatterns", self.urlconf_module)
  File "/data/django/lib/python2.7/site-packages/django/core/urlresolvers.py", line 396, in urlconf_module
    self._urlconf_module = import_module(self.urlconf_name)
  File "/usr/lib64/python2.7/importlib/__init__.py", line 37, in import_module
    __import__(name)
  File "/code/samba/web/web/urls.py", line 18, in <module>
    import dashboard.urls,browse.urls,consumer.urls,deploy.urls,department.urls
  File "/code/samba/web/consumer/urls.py", line 11, in <module>
    url(r'unlock_user$',views.user_unlock)
AttributeError: 'module' object has no attribute 'user_unlock'
2019-01-13 11:31:47,036 INFO  Kname: samba_conf was get. 
2019-01-13 11:31:47,037 INFO  Kname: samba_conf was get. 
2019-01-13 11:31:47,528 WARNING  Not Found: /favicon.ico 
2019-01-13 11:31:57,876 INFO  /deploy/ 
2019-01-13 11:32:00,515 INFO  /deploy/ 
2019-01-13 11:32:17,245 WARNING  Not Found: /consumer/edit_user 
2019-01-13 11:32:22,488 WARNING  Not Found: /consumer/edit_user 
2019-01-13 11:32:37,559 WARNING  Not Found: /consumer/lock_user 
2019-01-13 20:23:36,933 INFO  Kname: samba_conf was get. 
2019-01-13 20:23:36,935 ERROR  Internal Server Error: / 
Traceback (most recent call last):
  File "/data/django/lib/python2.7/site-packages/django/core/handlers/base.py", line 119, in get_response
    resolver_match = resolver.resolve(request.path_info)
  File "/data/django/lib/python2.7/site-packages/django/core/urlresolvers.py", line 366, in resolve
    for pattern in self.url_patterns:
  File "/data/django/lib/python2.7/site-packages/django/core/urlresolvers.py", line 402, in url_patterns
    patterns = getattr(self.urlconf_module, "urlpatterns", self.urlconf_module)
  File "/data/django/lib/python2.7/site-packages/django/core/urlresolvers.py", line 396, in urlconf_module
    self._urlconf_module = import_module(self.urlconf_name)
  File "/usr/lib64/python2.7/importlib/__init__.py", line 37, in import_module
    __import__(name)
  File "/code/samba/web/web/urls.py", line 18, in <module>
    import dashboard.urls,browse.urls,consumer.urls,deploy.urls,department.urls
  File "/code/samba/web/consumer/urls.py", line 10, in <module>
    url(r'reset_pwd$',views.reset_pwd),
AttributeError: 'module' object has no attribute 'reset_pwd'
2019-01-13 20:23:41,289 ERROR  Internal Server Error: /favicon.ico 
Traceback (most recent call last):
  File "/data/django/lib/python2.7/site-packages/django/core/handlers/base.py", line 108, in get_response
    response = middleware_method(request)
  File "/data/django/lib/python2.7/site-packages/django/middleware/common.py", line 74, in process_request
    if (not urlresolvers.is_valid_path(request.path_info, urlconf) and
  File "/data/django/lib/python2.7/site-packages/django/core/urlresolvers.py", line 647, in is_valid_path
    resolve(path, urlconf)
  File "/data/django/lib/python2.7/site-packages/django/core/urlresolvers.py", line 522, in resolve
    return get_resolver(urlconf).resolve(path)
  File "/data/django/lib/python2.7/site-packages/django/core/urlresolvers.py", line 366, in resolve
    for pattern in self.url_patterns:
  File "/data/django/lib/python2.7/site-packages/django/core/urlresolvers.py", line 402, in url_patterns
    patterns = getattr(self.urlconf_module, "urlpatterns", self.urlconf_module)
  File "/data/django/lib/python2.7/site-packages/django/core/urlresolvers.py", line 396, in urlconf_module
    self._urlconf_module = import_module(self.urlconf_name)
  File "/usr/lib64/python2.7/importlib/__init__.py", line 37, in import_module
    __import__(name)
  File "/code/samba/web/web/urls.py", line 18, in <module>
    import dashboard.urls,browse.urls,consumer.urls,deploy.urls,department.urls
  File "/code/samba/web/consumer/urls.py", line 10, in <module>
    url(r'reset_pwd$',views.reset_pwd),
AttributeError: 'module' object has no attribute 'reset_pwd'
2019-01-13 20:25:18,880 INFO  Kname: samba_conf was get. 
2019-01-13 20:25:18,881 INFO  Kname: samba_conf was get. 
2019-01-13 20:25:19,274 WARNING  Not Found: /favicon.ico 
2019-01-13 20:25:59,875 WARNING  Not Found: /consumer/add_user 
2019-01-13 20:37:33,356 WARNING  Not Found: /consumer/add_user 
2019-01-13 20:42:54,102 WARNING  Not Found: /consumer/add_user 
2019-01-13 20:44:52,364 INFO  Kname: samba_conf was get. 
2019-01-13 20:44:52,365 INFO  Kname: samba_conf was get. 
2019-01-13 20:44:52,366 INFO  Kname: samba_conf was get. 
2019-01-13 20:44:52,369 WARNING  Not Found: /consumer/add_user 
2019-01-13 20:45:37,373 INFO  Kname: samba_conf was get. 
2019-01-13 20:45:37,374 INFO  Kname: samba_conf was get. 
2019-01-13 20:45:37,375 INFO  Kname: samba_conf was get. 
2019-01-13 20:45:37,381 ERROR  Internal Server Error: /consumer/add_user 
Traceback (most recent call last):
  File "/data/django/lib/python2.7/site-packages/django/core/handlers/base.py", line 132, in get_response
    response = wrapped_callback(request, *callback_args, **callback_kwargs)
  File "/code/samba/web/consumer/views.py", line 38, in add_user
    b.creator(name,pwd,role,desc).save()
  File "/data/django/lib/python2.7/site-packages/django/db/models/base.py", line 710, in save
    force_update=force_update, update_fields=update_fields)
  File "/data/django/lib/python2.7/site-packages/django/db/models/base.py", line 738, in save_base
    updated = self._save_table(raw, cls, force_insert, force_update, using, update_fields)
  File "/data/django/lib/python2.7/site-packages/django/db/models/base.py", line 822, in _save_table
    result = self._do_insert(cls._base_manager, using, fields, update_pk, raw)
  File "/data/django/lib/python2.7/site-packages/django/db/models/base.py", line 861, in _do_insert
    using=using, raw=raw)
  File "/data/django/lib/python2.7/site-packages/django/db/models/manager.py", line 127, in manager_method
    return getattr(self.get_queryset(), name)(*args, **kwargs)
  File "/data/django/lib/python2.7/site-packages/django/db/models/query.py", line 920, in _insert
    return query.get_compiler(using=using).execute_sql(return_id)
  File "/data/django/lib/python2.7/site-packages/django/db/models/sql/compiler.py", line 973, in execute_sql
    for sql, params in self.as_sql():
  File "/data/django/lib/python2.7/site-packages/django/db/models/sql/compiler.py", line 931, in as_sql
    for obj in self.query.objs
  File "/data/django/lib/python2.7/site-packages/django/db/models/fields/__init__.py", line 710, in get_db_prep_save
    prepared=False)
  File "/data/django/lib/python2.7/site-packages/django/db/models/fields/__init__.py", line 702, in get_db_prep_value
    value = self.get_prep_value(value)
  File "/data/django/lib/python2.7/site-packages/django/db/models/fields/__init__.py", line 1868, in get_prep_value
    return int(value)
ValueError: invalid literal for int() with base 10: ''
2019-01-13 20:45:54,190 INFO  Kname: samba_conf was get. 
2019-01-13 20:45:54,191 INFO  Kname: samba_conf was get. 
2019-01-13 20:45:54,192 INFO  Kname: samba_conf was get. 
2019-01-13 20:45:54,197 ERROR  Internal Server Error: /consumer/add_user 
Traceback (most recent call last):
  File "/data/django/lib/python2.7/site-packages/django/core/handlers/base.py", line 132, in get_response
    response = wrapped_callback(request, *callback_args, **callback_kwargs)
  File "/code/samba/web/consumer/views.py", line 38, in add_user
    b.creator(name,pwd,role,desc).save()
  File "/data/django/lib/python2.7/site-packages/django/db/models/base.py", line 710, in save
    force_update=force_update, update_fields=update_fields)
  File "/data/django/lib/python2.7/site-packages/django/db/models/base.py", line 738, in save_base
    updated = self._save_table(raw, cls, force_insert, force_update, using, update_fields)
  File "/data/django/lib/python2.7/site-packages/django/db/models/base.py", line 822, in _save_table
    result = self._do_insert(cls._base_manager, using, fields, update_pk, raw)
  File "/data/django/lib/python2.7/site-packages/django/db/models/base.py", line 861, in _do_insert
    using=using, raw=raw)
  File "/data/django/lib/python2.7/site-packages/django/db/models/manager.py", line 127, in manager_method
    return getattr(self.get_queryset(), name)(*args, **kwargs)
  File "/data/django/lib/python2.7/site-packages/django/db/models/query.py", line 920, in _insert
    return query.get_compiler(using=using).execute_sql(return_id)
  File "/data/django/lib/python2.7/site-packages/django/db/models/sql/compiler.py", line 973, in execute_sql
    for sql, params in self.as_sql():
  File "/data/django/lib/python2.7/site-packages/django/db/models/sql/compiler.py", line 931, in as_sql
    for obj in self.query.objs
  File "/data/django/lib/python2.7/site-packages/django/db/models/fields/__init__.py", line 710, in get_db_prep_save
    prepared=False)
  File "/data/django/lib/python2.7/site-packages/django/db/models/fields/__init__.py", line 702, in get_db_prep_value
    value = self.get_prep_value(value)
  File "/data/django/lib/python2.7/site-packages/django/db/models/fields/__init__.py", line 1868, in get_prep_value
    return int(value)
ValueError: invalid literal for int() with base 10: ''
2019-01-13 20:46:17,978 INFO  Kname: samba_conf was get. 
2019-01-13 20:46:17,979 INFO  Kname: samba_conf was get. 
2019-01-13 20:46:17,980 INFO  Kname: samba_conf was get. 
2019-01-13 20:46:17,985 ERROR  Internal Server Error: /consumer/add_user 
Traceback (most recent call last):
  File "/data/django/lib/python2.7/site-packages/django/core/handlers/base.py", line 132, in get_response
    response = wrapped_callback(request, *callback_args, **callback_kwargs)
  File "/code/samba/web/consumer/views.py", line 38, in add_user
    b.creator(name,pwd,role,desc).save()
  File "/data/django/lib/python2.7/site-packages/django/db/models/base.py", line 710, in save
    force_update=force_update, update_fields=update_fields)
  File "/data/django/lib/python2.7/site-packages/django/db/models/base.py", line 738, in save_base
    updated = self._save_table(raw, cls, force_insert, force_update, using, update_fields)
  File "/data/django/lib/python2.7/site-packages/django/db/models/base.py", line 822, in _save_table
    result = self._do_insert(cls._base_manager, using, fields, update_pk, raw)
  File "/data/django/lib/python2.7/site-packages/django/db/models/base.py", line 861, in _do_insert
    using=using, raw=raw)
  File "/data/django/lib/python2.7/site-packages/django/db/models/manager.py", line 127, in manager_method
    return getattr(self.get_queryset(), name)(*args, **kwargs)
  File "/data/django/lib/python2.7/site-packages/django/db/models/query.py", line 920, in _insert
    return query.get_compiler(using=using).execute_sql(return_id)
  File "/data/django/lib/python2.7/site-packages/django/db/models/sql/compiler.py", line 973, in execute_sql
    for sql, params in self.as_sql():
  File "/data/django/lib/python2.7/site-packages/django/db/models/sql/compiler.py", line 931, in as_sql
    for obj in self.query.objs
  File "/data/django/lib/python2.7/site-packages/django/db/models/fields/__init__.py", line 710, in get_db_prep_save
    prepared=False)
  File "/data/django/lib/python2.7/site-packages/django/db/models/fields/__init__.py", line 702, in get_db_prep_value
    value = self.get_prep_value(value)
  File "/data/django/lib/python2.7/site-packages/django/db/models/fields/__init__.py", line 1868, in get_prep_value
    return int(value)
ValueError: invalid literal for int() with base 10: ''
2019-01-13 20:46:51,097 INFO  USER wangbo1was add to db. 
2019-01-13 20:46:51,535 INFO  User was created. 
2019-01-13 20:46:51,536 ERROR  Internal Server Error: /consumer/add_user 
Traceback (most recent call last):
  File "/data/django/lib/python2.7/site-packages/django/core/handlers/base.py", line 132, in get_response
    response = wrapped_callback(request, *callback_args, **callback_kwargs)
  File "/code/samba/web/consumer/views.py", line 43, in add_user
    wuser = wsuser.wsuser(name,pwd)
  File "/code/samba/web/wsamba/wsuser.py", line 15, in __init__
    self.Lock = Lock
NameError: global name 'Lock' is not defined
2019-01-13 20:58:30,604 INFO  Kname: samba_conf was get. 
2019-01-13 20:58:30,606 INFO  Kname: samba_conf was get. 
2019-01-13 20:58:30,606 INFO  Kname: samba_conf was get. 
2019-01-13 21:22:16,389 INFO  Kname: samba_conf was get. 
2019-01-13 21:22:16,393 INFO  Kname: samba_conf was get. 
2019-01-13 21:22:16,394 INFO  Kname: samba_conf was get. 
2019-01-13 21:22:16,398 ERROR  Internal Server Error: /consumer/edit_user 
Traceback (most recent call last):
  File "/data/django/lib/python2.7/site-packages/django/core/handlers/base.py", line 132, in get_response
    response = wrapped_callback(request, *callback_args, **callback_kwargs)
  File "/code/samba/web/consumer/views.py", line 58, in user_edit
    userid = Sa_user.objects.get(id=uid)
  File "/data/django/lib/python2.7/site-packages/django/db/models/manager.py", line 127, in manager_method
    return getattr(self.get_queryset(), name)(*args, **kwargs)
  File "/data/django/lib/python2.7/site-packages/django/db/models/query.py", line 325, in get
    clone = self.filter(*args, **kwargs)
  File "/data/django/lib/python2.7/site-packages/django/db/models/query.py", line 679, in filter
    return self._filter_or_exclude(False, *args, **kwargs)
  File "/data/django/lib/python2.7/site-packages/django/db/models/query.py", line 697, in _filter_or_exclude
    clone.query.add_q(Q(*args, **kwargs))
  File "/data/django/lib/python2.7/site-packages/django/db/models/sql/query.py", line 1304, in add_q
    clause, require_inner = self._add_q(where_part, self.used_aliases)
  File "/data/django/lib/python2.7/site-packages/django/db/models/sql/query.py", line 1332, in _add_q
    allow_joins=allow_joins, split_subq=split_subq,
  File "/data/django/lib/python2.7/site-packages/django/db/models/sql/query.py", line 1203, in build_filter
    condition = self.build_lookup(lookups, col, value)
  File "/data/django/lib/python2.7/site-packages/django/db/models/sql/query.py", line 1096, in build_lookup
    return final_lookup(lhs, rhs)
  File "/data/django/lib/python2.7/site-packages/django/db/models/lookups.py", line 96, in __init__
    self.rhs = self.get_prep_lookup()
  File "/data/django/lib/python2.7/site-packages/django/db/models/lookups.py", line 134, in get_prep_lookup
    return self.lhs.output_field.get_prep_lookup(self.lookup_name, self.rhs)
  File "/data/django/lib/python2.7/site-packages/django/db/models/fields/__init__.py", line 727, in get_prep_lookup
    return self.get_prep_value(value)
  File "/data/django/lib/python2.7/site-packages/django/db/models/fields/__init__.py", line 985, in get_prep_value
    return int(value)
ValueError: invalid literal for int() with base 10: ''
2019-01-13 21:23:02,788 WARNING  Not Found: /consumer/user_edit 
2019-01-13 21:23:02,886 ERROR  userdel: wangbo1 home directory (/home/wangbo1) not found
 
2019-01-13 21:23:02,896 ERROR  Usage: useradd [options] LOGIN
       useradd -D
       useradd -D [options]

Options:
  -b, --base-dir BASE_DIR       base directory for the home directory of the
                                new account
  -c, --comment COMMENT         GECOS field of the new account
  -d, --home-dir HOME_DIR       home directory of the new account
  -D, --defaults                print or change default useradd configuration
  -e, --expiredate EXPIRE_DATE  expiration date of the new account
  -f, --inactive INACTIVE       password inactivity period of the new account
  -g, --gid GROUP               name or ID of the primary group of the new
                                account
  -G, --groups GROUPS           list of supplementary groups of the new
                                account
  -h, --help                    display this help message and exit
  -k, --skel SKEL_DIR           use this alternative skeleton directory
  -K, --key KEY=VALUE           override /etc/login.defs defaults
  -l, --no-log-init             do not add the user to the lastlog and
                                faillog databases
  -m, --create-home             create the user's home directory
  -M, --no-create-home          do not create the user's home directory
  -N, --no-user-group           do not create a group with the same name as
                                the user
  -o, --non-unique              allow to create users with duplicate
                                (non-unique) UID
  -p, --password PASSWORD       encrypted password of the new account
  -r, --system                  create a system account
  -R, --root CHROOT_DIR         directory to chroot into
  -s, --shell SHELL             login shell of the new account
  -u, --uid UID                 user ID of the new account
  -U, --user-group              create a group with the same name as the user
  -Z, --selinux-user SEUSER     use a specific SEUSER for the SELinux user mapping

1
 
2019-01-13 21:23:02,897 ERROR  Internal Server Error: /consumer/edit_user 
Traceback (most recent call last):
  File "/data/django/lib/python2.7/site-packages/django/core/handlers/base.py", line 132, in get_response
    response = wrapped_callback(request, *callback_args, **callback_kwargs)
  File "/code/samba/web/consumer/views.py", line 64, in user_edit
    wsuser.wsuser(name).wudel()
  File "/code/samba/web/wsamba/wsuser.py", line 15, in __init__
    self.Lock = Lock
NameError: global name 'Lock' is not defined
2019-01-13 21:30:13,956 INFO  Kname: samba_conf was get. 
2019-01-13 21:30:13,958 INFO  Kname: samba_conf was get. 
2019-01-13 21:30:13,958 INFO  Kname: samba_conf was get. 
2019-01-13 21:30:13,963 ERROR  Internal Server Error: /consumer/user_edit 
Traceback (most recent call last):
  File "/data/django/lib/python2.7/site-packages/django/core/handlers/base.py", line 132, in get_response
    response = wrapped_callback(request, *callback_args, **callback_kwargs)
  File "/code/samba/web/consumer/views.py", line 58, in user_edit
    userid = Sa_user.objects.get(id=uid)
  File "/data/django/lib/python2.7/site-packages/django/db/models/manager.py", line 127, in manager_method
    return getattr(self.get_queryset(), name)(*args, **kwargs)
  File "/data/django/lib/python2.7/site-packages/django/db/models/query.py", line 325, in get
    clone = self.filter(*args, **kwargs)
  File "/data/django/lib/python2.7/site-packages/django/db/models/query.py", line 679, in filter
    return self._filter_or_exclude(False, *args, **kwargs)
  File "/data/django/lib/python2.7/site-packages/django/db/models/query.py", line 697, in _filter_or_exclude
    clone.query.add_q(Q(*args, **kwargs))
  File "/data/django/lib/python2.7/site-packages/django/db/models/sql/query.py", line 1304, in add_q
    clause, require_inner = self._add_q(where_part, self.used_aliases)
  File "/data/django/lib/python2.7/site-packages/django/db/models/sql/query.py", line 1332, in _add_q
    allow_joins=allow_joins, split_subq=split_subq,
  File "/data/django/lib/python2.7/site-packages/django/db/models/sql/query.py", line 1203, in build_filter
    condition = self.build_lookup(lookups, col, value)
  File "/data/django/lib/python2.7/site-packages/django/db/models/sql/query.py", line 1096, in build_lookup
    return final_lookup(lhs, rhs)
  File "/data/django/lib/python2.7/site-packages/django/db/models/lookups.py", line 96, in __init__
    self.rhs = self.get_prep_lookup()
  File "/data/django/lib/python2.7/site-packages/django/db/models/lookups.py", line 134, in get_prep_lookup
    return self.lhs.output_field.get_prep_lookup(self.lookup_name, self.rhs)
  File "/data/django/lib/python2.7/site-packages/django/db/models/fields/__init__.py", line 727, in get_prep_lookup
    return self.get_prep_value(value)
  File "/data/django/lib/python2.7/site-packages/django/db/models/fields/__init__.py", line 985, in get_prep_value
    return int(value)
ValueError: invalid literal for int() with base 10: ''
2019-01-13 21:34:21,758 WARNING  Not Found: /favicon.ico 
2019-01-13 21:35:36,588 WARNING  Not Found: /favicon.ico 
2019-01-13 21:46:27,035 WARNING  Not Found: /consumer/edit_user 
2019-01-13 21:46:27,044 ERROR  Internal Server Error: /consumer/user_edit 
Traceback (most recent call last):
  File "/data/django/lib/python2.7/site-packages/django/core/handlers/base.py", line 132, in get_response
    response = wrapped_callback(request, *callback_args, **callback_kwargs)
  File "/code/samba/web/consumer/views.py", line 58, in user_edit
    userid = Sa_user.objects.get(id=uid)
  File "/data/django/lib/python2.7/site-packages/django/db/models/manager.py", line 127, in manager_method
    return getattr(self.get_queryset(), name)(*args, **kwargs)
  File "/data/django/lib/python2.7/site-packages/django/db/models/query.py", line 325, in get
    clone = self.filter(*args, **kwargs)
  File "/data/django/lib/python2.7/site-packages/django/db/models/query.py", line 679, in filter
    return self._filter_or_exclude(False, *args, **kwargs)
  File "/data/django/lib/python2.7/site-packages/django/db/models/query.py", line 697, in _filter_or_exclude
    clone.query.add_q(Q(*args, **kwargs))
  File "/data/django/lib/python2.7/site-packages/django/db/models/sql/query.py", line 1304, in add_q
    clause, require_inner = self._add_q(where_part, self.used_aliases)
  File "/data/django/lib/python2.7/site-packages/django/db/models/sql/query.py", line 1332, in _add_q
    allow_joins=allow_joins, split_subq=split_subq,
  File "/data/django/lib/python2.7/site-packages/django/db/models/sql/query.py", line 1203, in build_filter
    condition = self.build_lookup(lookups, col, value)
  File "/data/django/lib/python2.7/site-packages/django/db/models/sql/query.py", line 1096, in build_lookup
    return final_lookup(lhs, rhs)
  File "/data/django/lib/python2.7/site-packages/django/db/models/lookups.py", line 96, in __init__
    self.rhs = self.get_prep_lookup()
  File "/data/django/lib/python2.7/site-packages/django/db/models/lookups.py", line 134, in get_prep_lookup
    return self.lhs.output_field.get_prep_lookup(self.lookup_name, self.rhs)
  File "/data/django/lib/python2.7/site-packages/django/db/models/fields/__init__.py", line 727, in get_prep_lookup
    return self.get_prep_value(value)
  File "/data/django/lib/python2.7/site-packages/django/db/models/fields/__init__.py", line 985, in get_prep_value
    return int(value)
ValueError: invalid literal for int() with base 10: ''
2019-01-13 21:53:38,717 WARNING  Not Found: /consumer/edit_user 
2019-01-13 21:53:38,723 ERROR  Internal Server Error: /consumer/user_edit 
Traceback (most recent call last):
  File "/data/django/lib/python2.7/site-packages/django/core/handlers/base.py", line 132, in get_response
    response = wrapped_callback(request, *callback_args, **callback_kwargs)
  File "/code/samba/web/consumer/views.py", line 58, in user_edit
    userid = Sa_user.objects.get(id=uid)
  File "/data/django/lib/python2.7/site-packages/django/db/models/manager.py", line 127, in manager_method
    return getattr(self.get_queryset(), name)(*args, **kwargs)
  File "/data/django/lib/python2.7/site-packages/django/db/models/query.py", line 325, in get
    clone = self.filter(*args, **kwargs)
  File "/data/django/lib/python2.7/site-packages/django/db/models/query.py", line 679, in filter
    return self._filter_or_exclude(False, *args, **kwargs)
  File "/data/django/lib/python2.7/site-packages/django/db/models/query.py", line 697, in _filter_or_exclude
    clone.query.add_q(Q(*args, **kwargs))
  File "/data/django/lib/python2.7/site-packages/django/db/models/sql/query.py", line 1304, in add_q
    clause, require_inner = self._add_q(where_part, self.used_aliases)
  File "/data/django/lib/python2.7/site-packages/django/db/models/sql/query.py", line 1332, in _add_q
    allow_joins=allow_joins, split_subq=split_subq,
  File "/data/django/lib/python2.7/site-packages/django/db/models/sql/query.py", line 1203, in build_filter
    condition = self.build_lookup(lookups, col, value)
  File "/data/django/lib/python2.7/site-packages/django/db/models/sql/query.py", line 1096, in build_lookup
    return final_lookup(lhs, rhs)
  File "/data/django/lib/python2.7/site-packages/django/db/models/lookups.py", line 96, in __init__
    self.rhs = self.get_prep_lookup()
  File "/data/django/lib/python2.7/site-packages/django/db/models/lookups.py", line 134, in get_prep_lookup
    return self.lhs.output_field.get_prep_lookup(self.lookup_name, self.rhs)
  File "/data/django/lib/python2.7/site-packages/django/db/models/fields/__init__.py", line 727, in get_prep_lookup
    return self.get_prep_value(value)
  File "/data/django/lib/python2.7/site-packages/django/db/models/fields/__init__.py", line 985, in get_prep_value
    return int(value)
ValueError: invalid literal for int() with base 10: ''
2019-01-13 21:54:16,593 WARNING  Not Found: /consumer/edit_user 
2019-01-13 21:54:16,599 ERROR  Internal Server Error: /consumer/user_edit 
Traceback (most recent call last):
  File "/data/django/lib/python2.7/site-packages/django/core/handlers/base.py", line 132, in get_response
    response = wrapped_callback(request, *callback_args, **callback_kwargs)
  File "/code/samba/web/consumer/views.py", line 58, in user_edit
    userid = Sa_user.objects.get(id=uid)
  File "/data/django/lib/python2.7/site-packages/django/db/models/manager.py", line 127, in manager_method
    return getattr(self.get_queryset(), name)(*args, **kwargs)
  File "/data/django/lib/python2.7/site-packages/django/db/models/query.py", line 325, in get
    clone = self.filter(*args, **kwargs)
  File "/data/django/lib/python2.7/site-packages/django/db/models/query.py", line 679, in filter
    return self._filter_or_exclude(False, *args, **kwargs)
  File "/data/django/lib/python2.7/site-packages/django/db/models/query.py", line 697, in _filter_or_exclude
    clone.query.add_q(Q(*args, **kwargs))
  File "/data/django/lib/python2.7/site-packages/django/db/models/sql/query.py", line 1304, in add_q
    clause, require_inner = self._add_q(where_part, self.used_aliases)
  File "/data/django/lib/python2.7/site-packages/django/db/models/sql/query.py", line 1332, in _add_q
    allow_joins=allow_joins, split_subq=split_subq,
  File "/data/django/lib/python2.7/site-packages/django/db/models/sql/query.py", line 1203, in build_filter
    condition = self.build_lookup(lookups, col, value)
  File "/data/django/lib/python2.7/site-packages/django/db/models/sql/query.py", line 1096, in build_lookup
    return final_lookup(lhs, rhs)
  File "/data/django/lib/python2.7/site-packages/django/db/models/lookups.py", line 96, in __init__
    self.rhs = self.get_prep_lookup()
  File "/data/django/lib/python2.7/site-packages/django/db/models/lookups.py", line 134, in get_prep_lookup
    return self.lhs.output_field.get_prep_lookup(self.lookup_name, self.rhs)
  File "/data/django/lib/python2.7/site-packages/django/db/models/fields/__init__.py", line 727, in get_prep_lookup
    return self.get_prep_value(value)
  File "/data/django/lib/python2.7/site-packages/django/db/models/fields/__init__.py", line 985, in get_prep_value
    return int(value)
ValueError: invalid literal for int() with base 10: ''
2019-01-13 21:59:43,437 WARNING  Not Found: /consumer/edit_user 
2019-01-13 21:59:43,445 ERROR  Internal Server Error: /consumer/user_edit 
Traceback (most recent call last):
  File "/data/django/lib/python2.7/site-packages/django/core/handlers/base.py", line 132, in get_response
    response = wrapped_callback(request, *callback_args, **callback_kwargs)
  File "/code/samba/web/consumer/views.py", line 58, in user_edit
    userid = Sa_user.objects.get(id=uid)
  File "/data/django/lib/python2.7/site-packages/django/db/models/manager.py", line 127, in manager_method
    return getattr(self.get_queryset(), name)(*args, **kwargs)
  File "/data/django/lib/python2.7/site-packages/django/db/models/query.py", line 325, in get
    clone = self.filter(*args, **kwargs)
  File "/data/django/lib/python2.7/site-packages/django/db/models/query.py", line 679, in filter
    return self._filter_or_exclude(False, *args, **kwargs)
  File "/data/django/lib/python2.7/site-packages/django/db/models/query.py", line 697, in _filter_or_exclude
    clone.query.add_q(Q(*args, **kwargs))
  File "/data/django/lib/python2.7/site-packages/django/db/models/sql/query.py", line 1304, in add_q
    clause, require_inner = self._add_q(where_part, self.used_aliases)
  File "/data/django/lib/python2.7/site-packages/django/db/models/sql/query.py", line 1332, in _add_q
    allow_joins=allow_joins, split_subq=split_subq,
  File "/data/django/lib/python2.7/site-packages/django/db/models/sql/query.py", line 1203, in build_filter
    condition = self.build_lookup(lookups, col, value)
  File "/data/django/lib/python2.7/site-packages/django/db/models/sql/query.py", line 1096, in build_lookup
    return final_lookup(lhs, rhs)
  File "/data/django/lib/python2.7/site-packages/django/db/models/lookups.py", line 96, in __init__
    self.rhs = self.get_prep_lookup()
  File "/data/django/lib/python2.7/site-packages/django/db/models/lookups.py", line 134, in get_prep_lookup
    return self.lhs.output_field.get_prep_lookup(self.lookup_name, self.rhs)
  File "/data/django/lib/python2.7/site-packages/django/db/models/fields/__init__.py", line 727, in get_prep_lookup
    return self.get_prep_value(value)
  File "/data/django/lib/python2.7/site-packages/django/db/models/fields/__init__.py", line 985, in get_prep_value
    return int(value)
ValueError: invalid literal for int() with base 10: ''
2019-01-13 22:04:49,519 WARNING  Not Found: /consumer/edit_user 
2019-01-13 22:04:49,528 ERROR  Internal Server Error: /consumer/user_edit 
Traceback (most recent call last):
  File "/data/django/lib/python2.7/site-packages/django/core/handlers/base.py", line 132, in get_response
    response = wrapped_callback(request, *callback_args, **callback_kwargs)
  File "/code/samba/web/consumer/views.py", line 58, in user_edit
    userid = Sa_user.objects.get(id=uid)
  File "/data/django/lib/python2.7/site-packages/django/db/models/manager.py", line 127, in manager_method
    return getattr(self.get_queryset(), name)(*args, **kwargs)
  File "/data/django/lib/python2.7/site-packages/django/db/models/query.py", line 325, in get
    clone = self.filter(*args, **kwargs)
  File "/data/django/lib/python2.7/site-packages/django/db/models/query.py", line 679, in filter
    return self._filter_or_exclude(False, *args, **kwargs)
  File "/data/django/lib/python2.7/site-packages/django/db/models/query.py", line 697, in _filter_or_exclude
    clone.query.add_q(Q(*args, **kwargs))
  File "/data/django/lib/python2.7/site-packages/django/db/models/sql/query.py", line 1304, in add_q
    clause, require_inner = self._add_q(where_part, self.used_aliases)
  File "/data/django/lib/python2.7/site-packages/django/db/models/sql/query.py", line 1332, in _add_q
    allow_joins=allow_joins, split_subq=split_subq,
  File "/data/django/lib/python2.7/site-packages/django/db/models/sql/query.py", line 1203, in build_filter
    condition = self.build_lookup(lookups, col, value)
  File "/data/django/lib/python2.7/site-packages/django/db/models/sql/query.py", line 1096, in build_lookup
    return final_lookup(lhs, rhs)
  File "/data/django/lib/python2.7/site-packages/django/db/models/lookups.py", line 96, in __init__
    self.rhs = self.get_prep_lookup()
  File "/data/django/lib/python2.7/site-packages/django/db/models/lookups.py", line 134, in get_prep_lookup
    return self.lhs.output_field.get_prep_lookup(self.lookup_name, self.rhs)
  File "/data/django/lib/python2.7/site-packages/django/db/models/fields/__init__.py", line 727, in get_prep_lookup
    return self.get_prep_value(value)
  File "/data/django/lib/python2.7/site-packages/django/db/models/fields/__init__.py", line 985, in get_prep_value
    return int(value)
ValueError: invalid literal for int() with base 10: ''
2019-01-13 22:04:49,559 WARNING  Not Found: /consumer/edit_user 
2019-01-13 22:06:14,380 ERROR  Internal Server Error: /consumer/user_edit 
Traceback (most recent call last):
  File "/data/django/lib/python2.7/site-packages/django/core/handlers/base.py", line 132, in get_response
    response = wrapped_callback(request, *callback_args, **callback_kwargs)
  File "/code/samba/web/consumer/views.py", line 58, in user_edit
    userid = Sa_user.objects.get(id=uid)
  File "/data/django/lib/python2.7/site-packages/django/db/models/manager.py", line 127, in manager_method
    return getattr(self.get_queryset(), name)(*args, **kwargs)
  File "/data/django/lib/python2.7/site-packages/django/db/models/query.py", line 325, in get
    clone = self.filter(*args, **kwargs)
  File "/data/django/lib/python2.7/site-packages/django/db/models/query.py", line 679, in filter
    return self._filter_or_exclude(False, *args, **kwargs)
  File "/data/django/lib/python2.7/site-packages/django/db/models/query.py", line 697, in _filter_or_exclude
    clone.query.add_q(Q(*args, **kwargs))
  File "/data/django/lib/python2.7/site-packages/django/db/models/sql/query.py", line 1304, in add_q
    clause, require_inner = self._add_q(where_part, self.used_aliases)
  File "/data/django/lib/python2.7/site-packages/django/db/models/sql/query.py", line 1332, in _add_q
    allow_joins=allow_joins, split_subq=split_subq,
  File "/data/django/lib/python2.7/site-packages/django/db/models/sql/query.py", line 1203, in build_filter
    condition = self.build_lookup(lookups, col, value)
  File "/data/django/lib/python2.7/site-packages/django/db/models/sql/query.py", line 1096, in build_lookup
    return final_lookup(lhs, rhs)
  File "/data/django/lib/python2.7/site-packages/django/db/models/lookups.py", line 96, in __init__
    self.rhs = self.get_prep_lookup()
  File "/data/django/lib/python2.7/site-packages/django/db/models/lookups.py", line 134, in get_prep_lookup
    return self.lhs.output_field.get_prep_lookup(self.lookup_name, self.rhs)
  File "/data/django/lib/python2.7/site-packages/django/db/models/fields/__init__.py", line 727, in get_prep_lookup
    return self.get_prep_value(value)
  File "/data/django/lib/python2.7/site-packages/django/db/models/fields/__init__.py", line 985, in get_prep_value
    return int(value)
ValueError: invalid literal for int() with base 10: ''
2019-01-13 22:06:14,394 ERROR  userdel: user 'wangbo1' does not exist
1
 
2019-01-13 22:06:14,428 ERROR  Usage: useradd [options] LOGIN
       useradd -D
       useradd -D [options]

Options:
  -b, --base-dir BASE_DIR       base directory for the home directory of the
                                new account
  -c, --comment COMMENT         GECOS field of the new account
  -d, --home-dir HOME_DIR       home directory of the new account
  -D, --defaults                print or change default useradd configuration
  -e, --expiredate EXPIRE_DATE  expiration date of the new account
  -f, --inactive INACTIVE       password inactivity period of the new account
  -g, --gid GROUP               name or ID of the primary group of the new
                                account
  -G, --groups GROUPS           list of supplementary groups of the new
                                account
  -h, --help                    display this help message and exit
  -k, --skel SKEL_DIR           use this alternative skeleton directory
  -K, --key KEY=VALUE           override /etc/login.defs defaults
  -l, --no-log-init             do not add the user to the lastlog and
                                faillog databases
  -m, --create-home             create the user's home directory
  -M, --no-create-home          do not create the user's home directory
  -N, --no-user-group           do not create a group with the same name as
                                the user
  -o, --non-unique              allow to create users with duplicate
                                (non-unique) UID
  -p, --password PASSWORD       encrypted password of the new account
  -r, --system                  create a system account
  -R, --root CHROOT_DIR         directory to chroot into
  -s, --shell SHELL             login shell of the new account
  -u, --uid UID                 user ID of the new account
  -U, --user-group              create a group with the same name as the user
  -Z, --selinux-user SEUSER     use a specific SEUSER for the SELinux user mapping

1
 
2019-01-13 22:06:14,428 ERROR  Internal Server Error: /consumer/user_edit 
Traceback (most recent call last):
  File "/data/django/lib/python2.7/site-packages/django/core/handlers/base.py", line 132, in get_response
    response = wrapped_callback(request, *callback_args, **callback_kwargs)
  File "/code/samba/web/consumer/views.py", line 64, in user_edit
    wsuser.wsuser(name).wudel()
  File "/code/samba/web/wsamba/wsuser.py", line 15, in __init__
    self.Lock = Lock
NameError: global name 'Lock' is not defined
2019-01-13 22:19:49,697 INFO  Kname: samba_conf was get. 
2019-01-13 22:19:49,698 INFO  Kname: samba_conf was get. 
2019-01-13 22:19:49,699 INFO  Kname: samba_conf was get. 
2019-01-13 22:24:17,282 INFO  Kname: samba_conf was get. 
2019-01-13 22:24:17,283 INFO  Kname: samba_conf was get. 
2019-01-13 22:24:17,284 INFO  Kname: samba_conf was get. 
2019-01-13 22:28:47,817 INFO  USER wangbo2was add to db. 
2019-01-13 22:28:47,900 INFO  User was created. 
2019-01-13 22:28:48,369 ERROR  Internal Server Error: /consumer/add_user 
Traceback (most recent call last):
  File "/data/django/lib/python2.7/site-packages/django/core/handlers/base.py", line 132, in get_response
    response = wrapped_callback(request, *callback_args, **callback_kwargs)
  File "/code/samba/web/consumer/views.py", line 44, in add_user
    wuser.wuadd()
  File "/code/samba/web/wsamba/wsuser.py", line 33, in wuadd
    logger.info('SAMBA USER:'+self.name +'was added.')
AttributeError: 'wsuser' object has no attribute 'name'
2019-01-13 22:32:08,489 INFO  Kname: samba_conf was get. 
2019-01-13 22:32:08,490 INFO  Kname: samba_conf was get. 
2019-01-13 22:32:08,491 INFO  Kname: samba_conf was get. 
2019-01-13 22:34:57,030 INFO  Kname: samba_conf was get. 
2019-01-13 22:34:57,033 INFO  Kname: samba_conf was get. 
2019-01-13 22:34:57,034 INFO  Kname: samba_conf was get. 
2019-01-13 22:35:21,139 INFO  Kname: samba_conf was get. 
2019-01-13 22:35:21,142 INFO  Kname: samba_conf was get. 
2019-01-13 22:35:21,143 INFO  Kname: samba_conf was get. 
2019-01-13 22:43:19,640 INFO  Kname: samba_conf was get. 
2019-01-13 22:43:19,641 INFO  Kname: samba_conf was get. 
2019-01-13 22:43:19,642 INFO  Kname: samba_conf was get. 
2019-01-13 22:47:46,824 INFO  Kname: samba_conf was get. 
2019-01-13 22:47:46,827 ERROR  Internal Server Error: /consumer/ 
Traceback (most recent call last):
  File "/data/django/lib/python2.7/site-packages/django/core/handlers/base.py", line 119, in get_response
    resolver_match = resolver.resolve(request.path_info)
  File "/data/django/lib/python2.7/site-packages/django/core/urlresolvers.py", line 366, in resolve
    for pattern in self.url_patterns:
  File "/data/django/lib/python2.7/site-packages/django/core/urlresolvers.py", line 402, in url_patterns
    patterns = getattr(self.urlconf_module, "urlpatterns", self.urlconf_module)
  File "/data/django/lib/python2.7/site-packages/django/core/urlresolvers.py", line 396, in urlconf_module
    self._urlconf_module = import_module(self.urlconf_name)
  File "/usr/lib64/python2.7/importlib/__init__.py", line 37, in import_module
    __import__(name)
  File "/code/samba/web/web/urls.py", line 18, in <module>
    import dashboard.urls,browse.urls,consumer.urls,deploy.urls,department.urls
  File "/code/samba/web/consumer/urls.py", line 7, in <module>
    url(r'user_delete$',views.user_del),
AttributeError: 'module' object has no attribute 'user_del'
2019-01-13 22:47:57,791 INFO  Kname: samba_conf was get. 
2019-01-13 22:47:57,791 INFO  Kname: samba_conf was get. 
2019-01-13 22:53:47,134 INFO  Kname: samba_conf was get. 
2019-01-13 22:53:47,136 INFO  Kname: samba_conf was get. 
2019-01-13 22:53:47,137 INFO  Kname: samba_conf was get. 
2019-01-13 22:55:08,436 INFO  Kname: samba_conf was get. 
2019-01-13 22:55:08,439 INFO  Kname: samba_conf was get. 
2019-01-13 22:55:08,439 INFO  Kname: samba_conf was get. 
2019-01-13 22:55:24,163 INFO  USER wangbo3was add to db. 
2019-01-13 22:55:24,233 INFO  User was created. 
2019-01-13 22:55:24,318 INFO  SAMBA USER:wangbo3was added. 
2019-01-13 22:55:24,322 ERROR  Internal Server Error: /consumer/add_user 
Traceback (most recent call last):
  File "/data/django/lib/python2.7/site-packages/django/core/handlers/base.py", line 132, in get_response
    response = wrapped_callback(request, *callback_args, **callback_kwargs)
  File "/code/samba/web/consumer/views.py", line 50, in add_user
    return JsonResponse(json.dumps({"uid":uid,"uname":name,"role":role,"desc":desc,"stat":True}))
  File "/data/django/lib/python2.7/site-packages/django/http/response.py", line 532, in __init__
    raise TypeError('In order to allow non-dict objects to be '
TypeError: In order to allow non-dict objects to be serialized set the safe parameter to False
2019-01-13 23:00:00,446 INFO  Kname: samba_conf was get. 
2019-01-13 23:00:00,449 INFO  Kname: samba_conf was get. 
2019-01-13 23:00:00,449 INFO  Kname: samba_conf was get. 
2019-01-13 23:00:19,377 INFO  /deploy/ 
2019-01-13 23:00:25,182 INFO  /deploy/ 
2019-01-13 23:05:03,455 INFO  Kname: samba_conf was get. 
2019-01-13 23:05:03,457 INFO  Kname: samba_conf was get. 
2019-01-13 23:05:03,458 INFO  Kname: samba_conf was get. 
2019-01-13 23:05:03,461 INFO  ----------------- 
2019-01-13 23:06:20,704 INFO  Kname: samba_conf was get. 
2019-01-13 23:06:20,708 INFO  Kname: samba_conf was get. 
2019-01-13 23:06:20,709 INFO  Kname: samba_conf was get. 
2019-01-13 23:06:23,621 INFO  ---------------------- 
2019-01-13 23:06:23,621 INFO   
2019-01-13 23:06:23,621 INFO  ---------------------- 
2019-01-13 23:07:32,219 INFO  ---------------------- 
2019-01-13 23:07:32,219 INFO   
2019-01-13 23:07:32,219 INFO  ---------------------- 
2019-01-13 23:08:15,620 INFO  ---------------------- 
2019-01-13 23:08:15,620 INFO   
2019-01-13 23:08:15,620 INFO  ---------------------- 
2019-01-13 23:11:34,153 INFO  Kname: samba_conf was get. 
2019-01-13 23:11:34,156 INFO  Kname: samba_conf was get. 
2019-01-13 23:11:34,157 INFO  Kname: samba_conf was get. 
2019-01-13 23:11:38,011 INFO  ---------------------- 
2019-01-13 23:11:38,011 INFO  [] 
2019-01-13 23:13:59,005 INFO  Kname: samba_conf was get. 
2019-01-13 23:13:59,007 INFO  Kname: samba_conf was get. 
2019-01-13 23:13:59,008 INFO  Kname: samba_conf was get. 
2019-01-13 23:14:03,949 INFO  ---------------------- 
2019-01-13 23:14:03,950 INFO  <QueryDict: {u'uid[]': [u'6']}> 
2019-01-13 23:14:42,730 INFO  ---------------------- 
2019-01-13 23:14:42,730 INFO  <QueryDict: {u'uid[]': [u'1', u'2', u'3', u'4', u'5']}> 
2019-01-13 23:19:11,753 INFO  ---------------------- 
2019-01-13 23:19:11,753 INFO  <QueryDict: {u'uid[]': [u'6']}> 
2019-01-13 23:23:38,252 INFO  ---------------------- 
2019-01-13 23:23:38,252 INFO  <QueryDict: {u'uid[]': [u'5', u'6']}> 
2019-01-13 23:27:57,553 INFO  ---------------------- 
2019-01-13 23:27:57,553 INFO  <QueryDict: {u'uid[]': [u'5', u'6']}> 
2019-01-13 23:29:15,153 INFO  ---------------------- 
2019-01-13 23:29:15,153 INFO  <QueryDict: {u'undefined': [u'', u'']}> 
2019-01-13 23:31:40,023 INFO  ---------------------- 
2019-01-13 23:31:40,023 INFO  <QueryDict: {u'uid[]': [u'4', u'5', u'6']}> 
2019-01-13 23:33:40,814 INFO  ---------------------- 
2019-01-13 23:33:40,814 INFO  <QueryDict: {u'uid[]': [u'4', u'5', u'6']}> 
2019-01-13 23:34:24,249 INFO  ---------------------- 
2019-01-13 23:34:24,249 INFO  <QueryDict: {u'uid[]': [u'4', u'5']}> 
2019-01-13 23:36:26,531 INFO  ---------------------- 
2019-01-13 23:36:26,532 INFO  <QueryDict: {u'uid[]': [u'4', u'5']}> 
2019-01-13 23:42:00,382 INFO  ---------------------- 
2019-01-13 23:42:00,382 INFO  <QueryDict: {u'uid': [u'5']}> 
2019-01-13 23:42:00,385 ERROR  Internal Server Error: /consumer/user_delete 
Traceback (most recent call last):
  File "/data/django/lib/python2.7/site-packages/django/core/handlers/base.py", line 132, in get_response
    response = wrapped_callback(request, *callback_args, **callback_kwargs)
  File "/code/samba/web/consumer/views.py", line 104, in user_delete
    for i in uid:
AttributeError: 'QuerySet' object has no attribute 'remove'
2019-01-13 23:42:00,418 INFO  ---------------------- 
2019-01-13 23:42:00,418 INFO  <QueryDict: {u'uid': [u'6']}> 
2019-01-13 23:42:00,420 ERROR  Internal Server Error: /consumer/user_delete 
Traceback (most recent call last):
  File "/data/django/lib/python2.7/site-packages/django/core/handlers/base.py", line 132, in get_response
    response = wrapped_callback(request, *callback_args, **callback_kwargs)
  File "/code/samba/web/consumer/views.py", line 104, in user_delete
    for i in uid:
AttributeError: 'QuerySet' object has no attribute 'remove'
2019-01-13 23:42:39,942 INFO  ---------------------- 
2019-01-13 23:42:39,942 INFO  <QueryDict: {u'uid': [u'5']}> 
2019-01-13 23:42:39,944 ERROR  Internal Server Error: /consumer/user_delete 
Traceback (most recent call last):
  File "/data/django/lib/python2.7/site-packages/django/core/handlers/base.py", line 132, in get_response
    response = wrapped_callback(request, *callback_args, **callback_kwargs)
  File "/code/samba/web/consumer/views.py", line 104, in user_delete
    Dpt_user.objects.filter(username=userid.username).remove().save()
AttributeError: 'QuerySet' object has no attribute 'remove'
2019-01-13 23:42:39,982 INFO  ---------------------- 
2019-01-13 23:42:39,982 INFO  <QueryDict: {u'uid': [u'6']}> 
2019-01-13 23:42:39,985 ERROR  Internal Server Error: /consumer/user_delete 
Traceback (most recent call last):
  File "/data/django/lib/python2.7/site-packages/django/core/handlers/base.py", line 132, in get_response
    response = wrapped_callback(request, *callback_args, **callback_kwargs)
  File "/code/samba/web/consumer/views.py", line 104, in user_delete
    Dpt_user.objects.filter(username=userid.username).remove().save()
AttributeError: 'QuerySet' object has no attribute 'remove'
2019-01-13 23:46:36,387 INFO  ---------------------- 
2019-01-13 23:46:36,387 INFO  <QueryDict: {u'uid': [u'6']}> 
2019-01-13 23:46:36,390 ERROR  Internal Server Error: /consumer/user_delete 
Traceback (most recent call last):
  File "/data/django/lib/python2.7/site-packages/django/core/handlers/base.py", line 132, in get_response
    response = wrapped_callback(request, *callback_args, **callback_kwargs)
  File "/code/samba/web/consumer/views.py", line 104, in user_delete
    userid = Sa_user.objects.get(id=i)
AttributeError: 'QuerySet' object has no attribute 'remove'
2019-01-13 23:48:15,388 INFO  ---------------------- 
2019-01-13 23:48:15,389 INFO  <QueryDict: {u'uid': [u'6']}> 
2019-01-13 23:48:15,390 ERROR  Internal Server Error: /consumer/user_delete 
Traceback (most recent call last):
  File "/data/django/lib/python2.7/site-packages/django/core/handlers/base.py", line 132, in get_response
    response = wrapped_callback(request, *callback_args, **callback_kwargs)
  File "/code/samba/web/consumer/views.py", line 104, in user_delete
    userhandler.user_del(userid.username)
AttributeError: 'QuerySet' object has no attribute 'remove'
2019-01-14 00:04:31,722 INFO  ---------------------- 
2019-01-14 00:04:31,723 INFO  <QueryDict: {u'uid': [u'6']}> 
2019-01-14 00:04:31,725 ERROR  Internal Server Error: /consumer/user_delete 
Traceback (most recent call last):
  File "/data/django/lib/python2.7/site-packages/django/core/handlers/base.py", line 132, in get_response
    response = wrapped_callback(request, *callback_args, **callback_kwargs)
  File "/code/samba/web/consumer/views.py", line 104, in user_delete
    userhandler.user_del(userid.username)
AttributeError: 'QuerySet' object has no attribute 'remove'
2019-01-14 00:04:31,756 INFO  ---------------------- 
2019-01-14 00:04:31,756 INFO  <QueryDict: {u'uid': [u'5']}> 
2019-01-14 00:04:31,758 ERROR  Internal Server Error: /consumer/user_delete 
Traceback (most recent call last):
  File "/data/django/lib/python2.7/site-packages/django/core/handlers/base.py", line 132, in get_response
    response = wrapped_callback(request, *callback_args, **callback_kwargs)
  File "/code/samba/web/consumer/views.py", line 104, in user_delete
    userhandler.user_del(userid.username)
AttributeError: 'QuerySet' object has no attribute 'remove'
2019-01-14 00:05:03,324 INFO  ---------------------- 
2019-01-14 00:05:03,324 INFO  <QueryDict: {u'uid': [u'5']}> 
2019-01-14 00:05:03,326 ERROR  Internal Server Error: /consumer/user_delete 
Traceback (most recent call last):
  File "/data/django/lib/python2.7/site-packages/django/core/handlers/base.py", line 132, in get_response
    response = wrapped_callback(request, *callback_args, **callback_kwargs)
  File "/code/samba/web/consumer/views.py", line 104, in user_delete
    userhandler.user_del(userid.username)
AttributeError: 'QuerySet' object has no attribute 'remove'
2019-01-14 00:05:03,359 INFO  ---------------------- 
2019-01-14 00:05:03,359 INFO  <QueryDict: {u'uid': [u'6']}> 
2019-01-14 00:05:03,361 ERROR  Internal Server Error: /consumer/user_delete 
Traceback (most recent call last):
  File "/data/django/lib/python2.7/site-packages/django/core/handlers/base.py", line 132, in get_response
    response = wrapped_callback(request, *callback_args, **callback_kwargs)
  File "/code/samba/web/consumer/views.py", line 104, in user_delete
    userhandler.user_del(userid.username)
AttributeError: 'QuerySet' object has no attribute 'remove'
2019-01-14 00:10:15,232 INFO  Kname: samba_conf was get. 
2019-01-14 00:10:15,234 INFO  Kname: samba_conf was get. 
2019-01-14 00:10:15,234 INFO  Kname: samba_conf was get. 
2019-01-14 00:10:18,904 WARNING  Not Found: /favicon.ico 
2019-01-14 00:10:22,984 INFO  ---------------------- 
2019-01-14 00:10:22,984 INFO  5 
2019-01-14 00:10:22,987 ERROR  Internal Server Error: /consumer/user_delete 
Traceback (most recent call last):
  File "/data/django/lib/python2.7/site-packages/django/core/handlers/base.py", line 132, in get_response
    response = wrapped_callback(request, *callback_args, **callback_kwargs)
  File "/code/samba/web/consumer/views.py", line 103, in user_delete
    Dpt_user.objects.filter(username=userid.username).delete().save()
AttributeError: 'NoneType' object has no attribute 'save'
2019-01-14 00:10:23,023 INFO  ---------------------- 
2019-01-14 00:10:23,024 INFO  6 
2019-01-14 00:10:23,026 ERROR  Internal Server Error: /consumer/user_delete 
Traceback (most recent call last):
  File "/data/django/lib/python2.7/site-packages/django/core/handlers/base.py", line 132, in get_response
    response = wrapped_callback(request, *callback_args, **callback_kwargs)
  File "/code/samba/web/consumer/views.py", line 103, in user_delete
    Dpt_user.objects.filter(username=userid.username).delete().save()
AttributeError: 'NoneType' object has no attribute 'save'
2019-01-14 00:10:58,146 INFO  Kname: samba_conf was get. 
2019-01-14 00:10:58,149 INFO  Kname: samba_conf was get. 
2019-01-14 00:10:58,150 INFO  Kname: samba_conf was get. 
2019-01-14 00:11:01,747 INFO  ---------------------- 
2019-01-14 00:11:01,747 INFO  6 
2019-01-14 00:11:01,752 INFO  ---------------------- 
2019-01-14 00:11:01,753 INFO  5 
2019-01-14 00:11:01,873 ERROR  userdel: wangbo3 home directory (/home/wangbo3) not found
 
2019-01-14 00:11:01,879 ERROR  1
 
2019-01-14 00:11:01,923 ERROR  Failed to find a Unix account for wangbo3
Failed to delete entry for user wangbo3.
1
 
2019-01-14 00:11:01,924 ERROR  Internal Server Error: /consumer/user_delete 
Traceback (most recent call last):
  File "/data/django/lib/python2.7/site-packages/django/core/handlers/base.py", line 132, in get_response
    response = wrapped_callback(request, *callback_args, **callback_kwargs)
  File "/code/samba/web/consumer/views.py", line 106, in user_delete
    userid.remove().save()
AttributeError: 'Sa_user' object has no attribute 'remove'
2019-01-14 00:11:02,036 ERROR  userdel: wangbo2 home directory (/home/wangbo2) not found
 
2019-01-14 00:11:02,043 ERROR  1
 
2019-01-14 00:11:02,076 ERROR  Failed to find a Unix account for wangbo2
Failed to delete entry for user wangbo2.
1
 
2019-01-14 00:11:02,076 ERROR  Internal Server Error: /consumer/user_delete 
Traceback (most recent call last):
  File "/data/django/lib/python2.7/site-packages/django/core/handlers/base.py", line 132, in get_response
    response = wrapped_callback(request, *callback_args, **callback_kwargs)
  File "/code/samba/web/consumer/views.py", line 106, in user_delete
    userid.remove().save()
AttributeError: 'Sa_user' object has no attribute 'remove'
2019-01-14 00:13:35,866 INFO  Kname: samba_conf was get. 
2019-01-14 00:13:35,871 INFO  Kname: samba_conf was get. 
2019-01-14 00:13:35,871 INFO  Kname: samba_conf was get. 
2019-01-14 00:13:39,945 INFO  ---------------------- 
2019-01-14 00:13:39,945 INFO  5 
2019-01-14 00:13:39,957 INFO  ---------------------- 
2019-01-14 00:13:39,957 INFO  6 
2019-01-14 00:13:39,966 ERROR  userdel: user 'wangbo2' does not exist
1
 
2019-01-14 00:13:39,976 ERROR  1
 
2019-01-14 00:13:39,980 ERROR  userdel: user 'wangbo3' does not exist
1
 
2019-01-14 00:13:39,993 ERROR  1
 
2019-01-14 00:13:40,032 ERROR  Failed to find a Unix account for wangbo2
Failed to delete entry for user wangbo2.
1
 
2019-01-14 00:13:40,057 ERROR  Failed to find a Unix account for wangbo3
Failed to delete entry for user wangbo3.
1
 
2019-01-14 00:17:43,788 INFO  ---------------------- 
2019-01-14 00:17:43,788 INFO  4 
2019-01-14 00:17:43,799 ERROR  userdel: user 'wangbo1' does not exist
1
 
2019-01-14 00:17:43,806 ERROR  1
 
2019-01-14 00:17:43,836 ERROR  Failed to find entry for user wangbo1.
1
 
2019-01-14 00:18:09,920 INFO  USER wangbo1was add to db. 
2019-01-14 00:18:10,001 INFO  User was created. 
2019-01-14 00:18:10,098 INFO  SAMBA USER:wangbo1was added. 
2019-01-14 00:18:10,101 ERROR  Internal Server Error: /consumer/add_user 
Traceback (most recent call last):
  File "/data/django/lib/python2.7/site-packages/django/core/handlers/base.py", line 132, in get_response
    response = wrapped_callback(request, *callback_args, **callback_kwargs)
  File "/code/samba/web/consumer/views.py", line 49, in add_user
    return JsonResponse(json.dumps({"uid":uid,"uname":name,"role":role,"desc":desc,"success":True}))
  File "/data/django/lib/python2.7/site-packages/django/http/response.py", line 532, in __init__
    raise TypeError('In order to allow non-dict objects to be '
TypeError: In order to allow non-dict objects to be serialized set the safe parameter to False
2019-01-14 00:19:01,424 INFO  Kname: samba_conf was get. 
2019-01-14 00:19:01,427 INFO  Kname: samba_conf was get. 
2019-01-14 00:19:01,427 INFO  Kname: samba_conf was get. 
2019-01-14 00:19:05,958 INFO  ---------------------- 
2019-01-14 00:19:05,959 INFO  7 
2019-01-14 00:19:06,057 ERROR  userdel: wangbo1 home directory (/home/wangbo1) not found
 
2019-01-14 00:19:06,063 ERROR  1
 
2019-01-14 00:19:06,095 ERROR  Failed to find a Unix account for wangbo1
Failed to delete entry for user wangbo1.
1
 
2019-01-14 00:19:21,898 INFO  USER wangbo1was add to db. 
2019-01-14 00:19:21,979 INFO  User was created. 
2019-01-14 00:19:22,030 INFO  SAMBA USER:wangbo1was added. 
2019-01-14 00:19:22,032 ERROR  Internal Server Error: /consumer/add_user 
Traceback (most recent call last):
  File "/data/django/lib/python2.7/site-packages/django/core/handlers/base.py", line 132, in get_response
    response = wrapped_callback(request, *callback_args, **callback_kwargs)
  File "/code/samba/web/consumer/views.py", line 49, in add_user
    return JsonResponse(json.dumps({"success":True}))
  File "/data/django/lib/python2.7/site-packages/django/http/response.py", line 532, in __init__
    raise TypeError('In order to allow non-dict objects to be '
TypeError: In order to allow non-dict objects to be serialized set the safe parameter to False
2019-01-14 00:20:27,956 INFO  ---------------------- 
2019-01-14 00:20:27,956 INFO  8 
2019-01-14 00:20:28,046 ERROR  userdel: wangbo1 home directory (/home/wangbo1) not found
 
2019-01-14 00:20:28,054 ERROR  1
 
2019-01-14 00:20:28,087 ERROR  Failed to find a Unix account for wangbo1
Failed to delete entry for user wangbo1.
1
 
2019-01-14 00:22:30,218 INFO  Kname: samba_conf was get. 
2019-01-14 00:22:30,220 INFO  Kname: samba_conf was get. 
2019-01-14 00:22:30,220 INFO  Kname: samba_conf was get. 
2019-01-14 00:22:30,253 INFO  USER wangbo1was add to db. 
2019-01-14 00:22:30,339 INFO  User was created. 
2019-01-14 00:22:30,431 INFO  SAMBA USER:wangbo1was added. 
2019-01-14 00:22:30,434 ERROR  Internal Server Error: /consumer/add_user 
Traceback (most recent call last):
  File "/data/django/lib/python2.7/site-packages/django/core/handlers/base.py", line 132, in get_response
    response = wrapped_callback(request, *callback_args, **callback_kwargs)
  File "/code/samba/web/consumer/views.py", line 49, in add_user
    return JsonResponse(json.dumps({"success":True}))
  File "/data/django/lib/python2.7/site-packages/django/http/response.py", line 532, in __init__
    raise TypeError('In order to allow non-dict objects to be '
TypeError: In order to allow non-dict objects to be serialized set the safe parameter to False
2019-01-14 00:23:00,555 INFO  ---------------------- 
2019-01-14 00:23:00,556 INFO  9 
2019-01-14 00:23:00,639 ERROR  userdel: wangbo1 home directory (/home/wangbo1) not found
 
2019-01-14 00:23:00,645 ERROR  1
 
2019-01-14 00:23:00,685 ERROR  Internal Server Error: /consumer/user_delete 
Traceback (most recent call last):
  File "/data/django/lib/python2.7/site-packages/django/core/handlers/base.py", line 132, in get_response
    response = wrapped_callback(request, *callback_args, **callback_kwargs)
  File "/code/samba/web/consumer/views.py", line 105, in user_delete
    wsuser.wsuser(userid.username).wudel()
  File "/code/samba/web/wsamba/wsuser.py", line 42, in wudel
    logger.info('SAMBA USER:'+self.name +'was deleted.')
AttributeError: 'wsuser' object has no attribute 'name'
2019-01-14 00:25:00,465 INFO  Kname: samba_conf was get. 
2019-01-14 00:25:00,467 INFO  Kname: samba_conf was get. 
2019-01-14 00:25:00,467 INFO  Kname: samba_conf was get. 
2019-01-14 00:25:04,478 INFO  ---------------------- 
2019-01-14 00:25:04,478 INFO  9 
2019-01-14 00:25:04,488 ERROR  userdel: user 'wangbo1' does not exist
1
 
2019-01-14 00:25:04,493 ERROR  1
 
2019-01-14 00:25:04,520 ERROR  user wangbo1 does not exist in the passdb
1
 
2019-01-14 00:25:32,250 INFO  USER wangbo1was add to db. 
2019-01-14 00:25:32,334 INFO  User was created. 
2019-01-14 00:25:32,424 INFO  SAMBA USER:wangbo1was added. 
2019-01-14 00:25:32,426 ERROR  Internal Server Error: /consumer/add_user 
Traceback (most recent call last):
  File "/data/django/lib/python2.7/site-packages/django/core/handlers/base.py", line 132, in get_response
    response = wrapped_callback(request, *callback_args, **callback_kwargs)
  File "/code/samba/web/consumer/views.py", line 49, in add_user
    return JsonResponse(json.dumps({"success":True}))
  File "/data/django/lib/python2.7/site-packages/django/http/response.py", line 532, in __init__
    raise TypeError('In order to allow non-dict objects to be '
TypeError: In order to allow non-dict objects to be serialized set the safe parameter to False
2019-01-14 00:26:01,818 INFO  ---------------------- 
2019-01-14 00:26:01,818 INFO  10 
2019-01-14 00:26:01,933 ERROR  userdel: wangbo1 home directory (/home/wangbo1) not found
 
2019-01-14 00:26:01,940 ERROR  1
 
2019-01-14 00:26:01,999 INFO  SAMBA USER:wangbo1was deleted. 
2019-01-14 00:27:09,949 INFO  Kname: samba_conf was get. 
2019-01-14 00:27:09,950 INFO  Kname: samba_conf was get. 
2019-01-14 00:27:09,951 INFO  Kname: samba_conf was get. 
2019-01-14 00:27:10,019 INFO  USER wangbo1was add to db. 
2019-01-14 00:27:10,140 INFO  User was created. 
2019-01-14 00:27:10,238 INFO  SAMBA USER:wangbo1was added. 
2019-01-14 00:27:10,240 ERROR  Internal Server Error: /consumer/add_user 
Traceback (most recent call last):
  File "/data/django/lib/python2.7/site-packages/django/core/handlers/base.py", line 132, in get_response
    response = wrapped_callback(request, *callback_args, **callback_kwargs)
  File "/code/samba/web/consumer/views.py", line 49, in add_user
    return JsonResponse(json.dumps({"success":True}))
  File "/data/django/lib/python2.7/site-packages/django/http/response.py", line 532, in __init__
    raise TypeError('In order to allow non-dict objects to be '
TypeError: In order to allow non-dict objects to be serialized set the safe parameter to False
2019-01-14 00:27:17,320 ERROR  Internal Server Error: /consumer/user_edit 
Traceback (most recent call last):
  File "/data/django/lib/python2.7/site-packages/django/core/handlers/base.py", line 132, in get_response
    response = wrapped_callback(request, *callback_args, **callback_kwargs)
  File "/code/samba/web/consumer/views.py", line 57, in user_edit
    userid = Sa_user.objects.get(id=uid)
  File "/data/django/lib/python2.7/site-packages/django/db/models/manager.py", line 127, in manager_method
    return getattr(self.get_queryset(), name)(*args, **kwargs)
  File "/data/django/lib/python2.7/site-packages/django/db/models/query.py", line 325, in get
    clone = self.filter(*args, **kwargs)
  File "/data/django/lib/python2.7/site-packages/django/db/models/query.py", line 679, in filter
    return self._filter_or_exclude(False, *args, **kwargs)
  File "/data/django/lib/python2.7/site-packages/django/db/models/query.py", line 697, in _filter_or_exclude
    clone.query.add_q(Q(*args, **kwargs))
  File "/data/django/lib/python2.7/site-packages/django/db/models/sql/query.py", line 1304, in add_q
    clause, require_inner = self._add_q(where_part, self.used_aliases)
  File "/data/django/lib/python2.7/site-packages/django/db/models/sql/query.py", line 1332, in _add_q
    allow_joins=allow_joins, split_subq=split_subq,
  File "/data/django/lib/python2.7/site-packages/django/db/models/sql/query.py", line 1203, in build_filter
    condition = self.build_lookup(lookups, col, value)
  File "/data/django/lib/python2.7/site-packages/django/db/models/sql/query.py", line 1096, in build_lookup
    return final_lookup(lhs, rhs)
  File "/data/django/lib/python2.7/site-packages/django/db/models/lookups.py", line 96, in __init__
    self.rhs = self.get_prep_lookup()
  File "/data/django/lib/python2.7/site-packages/django/db/models/lookups.py", line 134, in get_prep_lookup
    return self.lhs.output_field.get_prep_lookup(self.lookup_name, self.rhs)
  File "/data/django/lib/python2.7/site-packages/django/db/models/fields/__init__.py", line 727, in get_prep_lookup
    return self.get_prep_value(value)
  File "/data/django/lib/python2.7/site-packages/django/db/models/fields/__init__.py", line 985, in get_prep_value
    return int(value)
ValueError: invalid literal for int() with base 10: ''
2019-01-14 00:27:17,507 ERROR  userdel: wangbo1 home directory (/home/wangbo1) not found
 
2019-01-14 00:27:17,516 ERROR  Usage: useradd [options] LOGIN
       useradd -D
       useradd -D [options]

Options:
  -b, --base-dir BASE_DIR       base directory for the home directory of the
                                new account
  -c, --comment COMMENT         GECOS field of the new account
  -d, --home-dir HOME_DIR       home directory of the new account
  -D, --defaults                print or change default useradd configuration
  -e, --expiredate EXPIRE_DATE  expiration date of the new account
  -f, --inactive INACTIVE       password inactivity period of the new account
  -g, --gid GROUP               name or ID of the primary group of the new
                                account
  -G, --groups GROUPS           list of supplementary groups of the new
                                account
  -h, --help                    display this help message and exit
  -k, --skel SKEL_DIR           use this alternative skeleton directory
  -K, --key KEY=VALUE           override /etc/login.defs defaults
  -l, --no-log-init             do not add the user to the lastlog and
                                faillog databases
  -m, --create-home             create the user's home directory
  -M, --no-create-home          do not create the user's home directory
  -N, --no-user-group           do not create a group with the same name as
                                the user
  -o, --non-unique              allow to create users with duplicate
                                (non-unique) UID
  -p, --password PASSWORD       encrypted password of the new account
  -r, --system                  create a system account
  -R, --root CHROOT_DIR         directory to chroot into
  -s, --shell SHELL             login shell of the new account
  -u, --uid UID                 user ID of the new account
  -U, --user-group              create a group with the same name as the user
  -Z, --selinux-user SEUSER     use a specific SEUSER for the SELinux user mapping

1
 
2019-01-14 00:32:19,379 ERROR  Internal Server Error: /consumer/user_edit 
Traceback (most recent call last):
  File "/data/django/lib/python2.7/site-packages/django/core/handlers/base.py", line 132, in get_response
    response = wrapped_callback(request, *callback_args, **callback_kwargs)
  File "/code/samba/web/consumer/views.py", line 57, in user_edit
    userid = Sa_user.objects.get(id=uid)
  File "/data/django/lib/python2.7/site-packages/django/db/models/manager.py", line 127, in manager_method
    return getattr(self.get_queryset(), name)(*args, **kwargs)
  File "/data/django/lib/python2.7/site-packages/django/db/models/query.py", line 325, in get
    clone = self.filter(*args, **kwargs)
  File "/data/django/lib/python2.7/site-packages/django/db/models/query.py", line 679, in filter
    return self._filter_or_exclude(False, *args, **kwargs)
  File "/data/django/lib/python2.7/site-packages/django/db/models/query.py", line 697, in _filter_or_exclude
    clone.query.add_q(Q(*args, **kwargs))
  File "/data/django/lib/python2.7/site-packages/django/db/models/sql/query.py", line 1304, in add_q
    clause, require_inner = self._add_q(where_part, self.used_aliases)
  File "/data/django/lib/python2.7/site-packages/django/db/models/sql/query.py", line 1332, in _add_q
    allow_joins=allow_joins, split_subq=split_subq,
  File "/data/django/lib/python2.7/site-packages/django/db/models/sql/query.py", line 1203, in build_filter
    condition = self.build_lookup(lookups, col, value)
  File "/data/django/lib/python2.7/site-packages/django/db/models/sql/query.py", line 1096, in build_lookup
    return final_lookup(lhs, rhs)
  File "/data/django/lib/python2.7/site-packages/django/db/models/lookups.py", line 96, in __init__
    self.rhs = self.get_prep_lookup()
  File "/data/django/lib/python2.7/site-packages/django/db/models/lookups.py", line 134, in get_prep_lookup
    return self.lhs.output_field.get_prep_lookup(self.lookup_name, self.rhs)
  File "/data/django/lib/python2.7/site-packages/django/db/models/fields/__init__.py", line 727, in get_prep_lookup
    return self.get_prep_value(value)
  File "/data/django/lib/python2.7/site-packages/django/db/models/fields/__init__.py", line 985, in get_prep_value
    return int(value)
ValueError: invalid literal for int() with base 10: ''
2019-01-14 00:32:19,422 ERROR  1
 
2019-01-14 00:32:19,422 ERROR  Internal Server Error: /consumer/user_edit 
Traceback (most recent call last):
  File "/data/django/lib/python2.7/site-packages/django/core/handlers/base.py", line 132, in get_response
    response = wrapped_callback(request, *callback_args, **callback_kwargs)
  File "/code/samba/web/consumer/views.py", line 67, in user_edit
    wsuser.wsuser(name).wuadd(name,pwd)
NameError: global name 'pwd' is not defined
2019-01-14 00:34:25,541 INFO  Kname: samba_conf was get. 
2019-01-14 00:34:25,544 INFO  Kname: samba_conf was get. 
2019-01-14 00:34:25,544 INFO  Kname: samba_conf was get. 
2019-01-14 00:34:29,259 ERROR  Internal Server Error: /consumer/user_edit 
Traceback (most recent call last):
  File "/data/django/lib/python2.7/site-packages/django/core/handlers/base.py", line 132, in get_response
    response = wrapped_callback(request, *callback_args, **callback_kwargs)
  File "/code/samba/web/consumer/views.py", line 57, in user_edit
    userid = Sa_user.objects.get(id=uid)
  File "/data/django/lib/python2.7/site-packages/django/db/models/manager.py", line 127, in manager_method
    return getattr(self.get_queryset(), name)(*args, **kwargs)
  File "/data/django/lib/python2.7/site-packages/django/db/models/query.py", line 325, in get
    clone = self.filter(*args, **kwargs)
  File "/data/django/lib/python2.7/site-packages/django/db/models/query.py", line 679, in filter
    return self._filter_or_exclude(False, *args, **kwargs)
  File "/data/django/lib/python2.7/site-packages/django/db/models/query.py", line 697, in _filter_or_exclude
    clone.query.add_q(Q(*args, **kwargs))
  File "/data/django/lib/python2.7/site-packages/django/db/models/sql/query.py", line 1304, in add_q
    clause, require_inner = self._add_q(where_part, self.used_aliases)
  File "/data/django/lib/python2.7/site-packages/django/db/models/sql/query.py", line 1332, in _add_q
    allow_joins=allow_joins, split_subq=split_subq,
  File "/data/django/lib/python2.7/site-packages/django/db/models/sql/query.py", line 1203, in build_filter
    condition = self.build_lookup(lookups, col, value)
  File "/data/django/lib/python2.7/site-packages/django/db/models/sql/query.py", line 1096, in build_lookup
    return final_lookup(lhs, rhs)
  File "/data/django/lib/python2.7/site-packages/django/db/models/lookups.py", line 96, in __init__
    self.rhs = self.get_prep_lookup()
  File "/data/django/lib/python2.7/site-packages/django/db/models/lookups.py", line 134, in get_prep_lookup
    return self.lhs.output_field.get_prep_lookup(self.lookup_name, self.rhs)
  File "/data/django/lib/python2.7/site-packages/django/db/models/fields/__init__.py", line 727, in get_prep_lookup
    return self.get_prep_value(value)
  File "/data/django/lib/python2.7/site-packages/django/db/models/fields/__init__.py", line 985, in get_prep_value
    return int(value)
ValueError: invalid literal for int() with base 10: ''
2019-01-14 00:34:29,401 ERROR  1
 
2019-01-14 00:34:29,401 ERROR  Internal Server Error: /consumer/user_edit 
Traceback (most recent call last):
  File "/data/django/lib/python2.7/site-packages/django/core/handlers/base.py", line 132, in get_response
    response = wrapped_callback(request, *callback_args, **callback_kwargs)
  File "/code/samba/web/consumer/views.py", line 67, in user_edit
    wsuser.wsuser(name).wuadd(name,pwd)
TypeError: wuadd() takes exactly 1 argument (3 given)
2019-01-14 00:35:23,234 INFO  Kname: samba_conf was get. 
2019-01-14 00:35:23,236 INFO  Kname: samba_conf was get. 
2019-01-14 00:35:23,237 INFO  Kname: samba_conf was get. 
2019-01-14 00:35:35,002 ERROR  Internal Server Error: /consumer/user_edit 
Traceback (most recent call last):
  File "/data/django/lib/python2.7/site-packages/django/core/handlers/base.py", line 132, in get_response
    response = wrapped_callback(request, *callback_args, **callback_kwargs)
  File "/code/samba/web/consumer/views.py", line 57, in user_edit
    userid = Sa_user.objects.get(id=uid)
  File "/data/django/lib/python2.7/site-packages/django/db/models/manager.py", line 127, in manager_method
    return getattr(self.get_queryset(), name)(*args, **kwargs)
  File "/data/django/lib/python2.7/site-packages/django/db/models/query.py", line 325, in get
    clone = self.filter(*args, **kwargs)
  File "/data/django/lib/python2.7/site-packages/django/db/models/query.py", line 679, in filter
    return self._filter_or_exclude(False, *args, **kwargs)
  File "/data/django/lib/python2.7/site-packages/django/db/models/query.py", line 697, in _filter_or_exclude
    clone.query.add_q(Q(*args, **kwargs))
  File "/data/django/lib/python2.7/site-packages/django/db/models/sql/query.py", line 1304, in add_q
    clause, require_inner = self._add_q(where_part, self.used_aliases)
  File "/data/django/lib/python2.7/site-packages/django/db/models/sql/query.py", line 1332, in _add_q
    allow_joins=allow_joins, split_subq=split_subq,
  File "/data/django/lib/python2.7/site-packages/django/db/models/sql/query.py", line 1203, in build_filter
    condition = self.build_lookup(lookups, col, value)
  File "/data/django/lib/python2.7/site-packages/django/db/models/sql/query.py", line 1096, in build_lookup
    return final_lookup(lhs, rhs)
  File "/data/django/lib/python2.7/site-packages/django/db/models/lookups.py", line 96, in __init__
    self.rhs = self.get_prep_lookup()
  File "/data/django/lib/python2.7/site-packages/django/db/models/lookups.py", line 134, in get_prep_lookup
    return self.lhs.output_field.get_prep_lookup(self.lookup_name, self.rhs)
  File "/data/django/lib/python2.7/site-packages/django/db/models/fields/__init__.py", line 727, in get_prep_lookup
    return self.get_prep_value(value)
  File "/data/django/lib/python2.7/site-packages/django/db/models/fields/__init__.py", line 985, in get_prep_value
    return int(value)
ValueError: invalid literal for int() with base 10: ''
2019-01-14 00:35:35,157 ERROR  1
 
2019-01-14 00:35:35,157 ERROR  Internal Server Error: /consumer/user_edit 
Traceback (most recent call last):
  File "/data/django/lib/python2.7/site-packages/django/core/handlers/base.py", line 132, in get_response
    response = wrapped_callback(request, *callback_args, **callback_kwargs)
  File "/code/samba/web/consumer/views.py", line 67, in user_edit
    wsuser.wsuser(name).wuadd(name,pwd)
NameError: global name 'pwd' is not defined
2019-01-14 00:36:11,802 INFO  Kname: samba_conf was get. 
2019-01-14 00:36:11,804 INFO  Kname: samba_conf was get. 
2019-01-14 00:36:11,805 INFO  Kname: samba_conf was get. 
2019-01-14 00:36:18,553 ERROR  Internal Server Error: /consumer/user_edit 
Traceback (most recent call last):
  File "/data/django/lib/python2.7/site-packages/django/core/handlers/base.py", line 132, in get_response
    response = wrapped_callback(request, *callback_args, **callback_kwargs)
  File "/code/samba/web/consumer/views.py", line 57, in user_edit
    userid = Sa_user.objects.get(id=uid)
  File "/data/django/lib/python2.7/site-packages/django/db/models/manager.py", line 127, in manager_method
    return getattr(self.get_queryset(), name)(*args, **kwargs)
  File "/data/django/lib/python2.7/site-packages/django/db/models/query.py", line 325, in get
    clone = self.filter(*args, **kwargs)
  File "/data/django/lib/python2.7/site-packages/django/db/models/query.py", line 679, in filter
    return self._filter_or_exclude(False, *args, **kwargs)
  File "/data/django/lib/python2.7/site-packages/django/db/models/query.py", line 697, in _filter_or_exclude
    clone.query.add_q(Q(*args, **kwargs))
  File "/data/django/lib/python2.7/site-packages/django/db/models/sql/query.py", line 1304, in add_q
    clause, require_inner = self._add_q(where_part, self.used_aliases)
  File "/data/django/lib/python2.7/site-packages/django/db/models/sql/query.py", line 1332, in _add_q
    allow_joins=allow_joins, split_subq=split_subq,
  File "/data/django/lib/python2.7/site-packages/django/db/models/sql/query.py", line 1203, in build_filter
    condition = self.build_lookup(lookups, col, value)
  File "/data/django/lib/python2.7/site-packages/django/db/models/sql/query.py", line 1096, in build_lookup
    return final_lookup(lhs, rhs)
  File "/data/django/lib/python2.7/site-packages/django/db/models/lookups.py", line 96, in __init__
    self.rhs = self.get_prep_lookup()
  File "/data/django/lib/python2.7/site-packages/django/db/models/lookups.py", line 134, in get_prep_lookup
    return self.lhs.output_field.get_prep_lookup(self.lookup_name, self.rhs)
  File "/data/django/lib/python2.7/site-packages/django/db/models/fields/__init__.py", line 727, in get_prep_lookup
    return self.get_prep_value(value)
  File "/data/django/lib/python2.7/site-packages/django/db/models/fields/__init__.py", line 985, in get_prep_value
    return int(value)
ValueError: invalid literal for int() with base 10: ''
2019-01-14 00:36:18,644 INFO  fity2013------------------- 
2019-01-14 00:36:18,677 ERROR  1
 
2019-01-14 00:36:18,677 ERROR  Internal Server Error: /consumer/user_edit 
Traceback (most recent call last):
  File "/data/django/lib/python2.7/site-packages/django/core/handlers/base.py", line 132, in get_response
    response = wrapped_callback(request, *callback_args, **callback_kwargs)
  File "/code/samba/web/consumer/views.py", line 67, in user_edit
    wsuser.wsuser(name).wuadd(name,pwd)
NameError: global name 'pwd' is not defined
2019-01-14 00:38:32,172 INFO  Kname: samba_conf was get. 
2019-01-14 00:38:32,174 INFO  Kname: samba_conf was get. 
2019-01-14 00:38:32,175 INFO  Kname: samba_conf was get. 
2019-01-14 00:38:55,688 INFO  fity2013------------------- 
2019-01-14 00:38:55,695 ERROR  1
 
2019-01-14 00:38:55,705 ERROR  Internal Server Error: /consumer/user_edit 
Traceback (most recent call last):
  File "/data/django/lib/python2.7/site-packages/django/core/handlers/base.py", line 132, in get_response
    response = wrapped_callback(request, *callback_args, **callback_kwargs)
  File "/code/samba/web/consumer/views.py", line 57, in user_edit
    userid = Sa_user.objects.get(id=uid)
  File "/data/django/lib/python2.7/site-packages/django/db/models/manager.py", line 127, in manager_method
    return getattr(self.get_queryset(), name)(*args, **kwargs)
  File "/data/django/lib/python2.7/site-packages/django/db/models/query.py", line 325, in get
    clone = self.filter(*args, **kwargs)
  File "/data/django/lib/python2.7/site-packages/django/db/models/query.py", line 679, in filter
    return self._filter_or_exclude(False, *args, **kwargs)
  File "/data/django/lib/python2.7/site-packages/django/db/models/query.py", line 697, in _filter_or_exclude
    clone.query.add_q(Q(*args, **kwargs))
  File "/data/django/lib/python2.7/site-packages/django/db/models/sql/query.py", line 1304, in add_q
    clause, require_inner = self._add_q(where_part, self.used_aliases)
  File "/data/django/lib/python2.7/site-packages/django/db/models/sql/query.py", line 1332, in _add_q
    allow_joins=allow_joins, split_subq=split_subq,
  File "/data/django/lib/python2.7/site-packages/django/db/models/sql/query.py", line 1203, in build_filter
    condition = self.build_lookup(lookups, col, value)
  File "/data/django/lib/python2.7/site-packages/django/db/models/sql/query.py", line 1096, in build_lookup
    return final_lookup(lhs, rhs)
  File "/data/django/lib/python2.7/site-packages/django/db/models/lookups.py", line 96, in __init__
    self.rhs = self.get_prep_lookup()
  File "/data/django/lib/python2.7/site-packages/django/db/models/lookups.py", line 134, in get_prep_lookup
    return self.lhs.output_field.get_prep_lookup(self.lookup_name, self.rhs)
  File "/data/django/lib/python2.7/site-packages/django/db/models/fields/__init__.py", line 727, in get_prep_lookup
    return self.get_prep_value(value)
  File "/data/django/lib/python2.7/site-packages/django/db/models/fields/__init__.py", line 985, in get_prep_value
    return int(value)
ValueError: invalid literal for int() with base 10: ''
2019-01-14 00:38:55,848 ERROR  Failed to find a Unix account for wangbo1
Failed to find a Unix account for wangbo1
 
2019-01-14 00:38:55,854 ERROR  1
 
2019-01-14 00:38:55,885 ERROR  Failed to find a Unix account for wangbo1
Failed to find a Unix account for wangbo1
Failed to find a Unix account for wangbo1
 
2019-01-14 00:38:55,886 ERROR  Internal Server Error: /consumer/user_edit 
Traceback (most recent call last):
  File "/data/django/lib/python2.7/site-packages/django/core/handlers/base.py", line 132, in get_response
    response = wrapped_callback(request, *callback_args, **callback_kwargs)
  File "/code/samba/web/consumer/views.py", line 74, in user_edit
    userid.save()
  File "/data/django/lib/python2.7/site-packages/django/db/models/base.py", line 710, in save
    force_update=force_update, update_fields=update_fields)
  File "/data/django/lib/python2.7/site-packages/django/db/models/base.py", line 738, in save_base
    updated = self._save_table(raw, cls, force_insert, force_update, using, update_fields)
  File "/data/django/lib/python2.7/site-packages/django/db/models/base.py", line 803, in _save_table
    forced_update)
  File "/data/django/lib/python2.7/site-packages/django/db/models/base.py", line 853, in _do_update
    return filtered._update(values) > 0
  File "/data/django/lib/python2.7/site-packages/django/db/models/query.py", line 580, in _update
    return query.get_compiler(self.db).execute_sql(CURSOR)
  File "/data/django/lib/python2.7/site-packages/django/db/models/sql/compiler.py", line 1062, in execute_sql
    cursor = super(SQLUpdateCompiler, self).execute_sql(result_type)
  File "/data/django/lib/python2.7/site-packages/django/db/models/sql/compiler.py", line 829, in execute_sql
    sql, params = self.as_sql()
  File "/data/django/lib/python2.7/site-packages/django/db/models/sql/compiler.py", line 1030, in as_sql
    val = field.get_db_prep_save(val, connection=self.connection)
  File "/data/django/lib/python2.7/site-packages/django/db/models/fields/__init__.py", line 710, in get_db_prep_save
    prepared=False)
  File "/data/django/lib/python2.7/site-packages/django/db/models/fields/__init__.py", line 702, in get_db_prep_value
    value = self.get_prep_value(value)
  File "/data/django/lib/python2.7/site-packages/django/db/models/fields/__init__.py", line 1868, in get_prep_value
    return int(value)
UnicodeEncodeError: 'decimal' codec can't encode characters in position 0-1: invalid decimal Unicode string
2019-01-14 00:44:22,234 INFO  Kname: samba_conf was get. 
2019-01-14 00:44:22,237 INFO  Kname: samba_conf was get. 
2019-01-14 00:44:22,237 INFO  Kname: samba_conf was get. 
2019-01-14 00:44:32,661 INFO  fity2013------------------- 
2019-01-14 00:44:32,668 ERROR  1
 
2019-01-14 00:44:32,714 ERROR  Failed to find a Unix account for wangbo1
Failed to find a Unix account for wangbo1
 
2019-01-14 00:44:32,721 ERROR  1
 
2019-01-14 00:44:32,752 ERROR  Failed to find a Unix account for wangbo1
Failed to find a Unix account for wangbo1
Failed to find a Unix account for wangbo1
 
2019-01-14 00:44:32,754 ERROR  Internal Server Error: /consumer/user_edit 
Traceback (most recent call last):
  File "/data/django/lib/python2.7/site-packages/django/core/handlers/base.py", line 132, in get_response
    response = wrapped_callback(request, *callback_args, **callback_kwargs)
  File "/code/samba/web/consumer/views.py", line 74, in user_edit
    userid.save()
  File "/data/django/lib/python2.7/site-packages/django/db/models/base.py", line 710, in save
    force_update=force_update, update_fields=update_fields)
  File "/data/django/lib/python2.7/site-packages/django/db/models/base.py", line 738, in save_base
    updated = self._save_table(raw, cls, force_insert, force_update, using, update_fields)
  File "/data/django/lib/python2.7/site-packages/django/db/models/base.py", line 803, in _save_table
    forced_update)
  File "/data/django/lib/python2.7/site-packages/django/db/models/base.py", line 853, in _do_update
    return filtered._update(values) > 0
  File "/data/django/lib/python2.7/site-packages/django/db/models/query.py", line 580, in _update
    return query.get_compiler(self.db).execute_sql(CURSOR)
  File "/data/django/lib/python2.7/site-packages/django/db/models/sql/compiler.py", line 1062, in execute_sql
    cursor = super(SQLUpdateCompiler, self).execute_sql(result_type)
  File "/data/django/lib/python2.7/site-packages/django/db/models/sql/compiler.py", line 829, in execute_sql
    sql, params = self.as_sql()
  File "/data/django/lib/python2.7/site-packages/django/db/models/sql/compiler.py", line 1030, in as_sql
    val = field.get_db_prep_save(val, connection=self.connection)
  File "/data/django/lib/python2.7/site-packages/django/db/models/fields/__init__.py", line 710, in get_db_prep_save
    prepared=False)
  File "/data/django/lib/python2.7/site-packages/django/db/models/fields/__init__.py", line 702, in get_db_prep_value
    value = self.get_prep_value(value)
  File "/data/django/lib/python2.7/site-packages/django/db/models/fields/__init__.py", line 1868, in get_prep_value
    return int(value)
UnicodeEncodeError: 'decimal' codec can't encode characters in position 0-1: invalid decimal Unicode string
2019-01-14 00:44:32,808 ERROR  Internal Server Error: /consumer/user_edit 
Traceback (most recent call last):
  File "/data/django/lib/python2.7/site-packages/django/core/handlers/base.py", line 132, in get_response
    response = wrapped_callback(request, *callback_args, **callback_kwargs)
  File "/code/samba/web/consumer/views.py", line 57, in user_edit
    userid = Sa_user.objects.get(id=uid)
  File "/data/django/lib/python2.7/site-packages/django/db/models/manager.py", line 127, in manager_method
    return getattr(self.get_queryset(), name)(*args, **kwargs)
  File "/data/django/lib/python2.7/site-packages/django/db/models/query.py", line 325, in get
    clone = self.filter(*args, **kwargs)
  File "/data/django/lib/python2.7/site-packages/django/db/models/query.py", line 679, in filter
    return self._filter_or_exclude(False, *args, **kwargs)
  File "/data/django/lib/python2.7/site-packages/django/db/models/query.py", line 697, in _filter_or_exclude
    clone.query.add_q(Q(*args, **kwargs))
  File "/data/django/lib/python2.7/site-packages/django/db/models/sql/query.py", line 1304, in add_q
    clause, require_inner = self._add_q(where_part, self.used_aliases)
  File "/data/django/lib/python2.7/site-packages/django/db/models/sql/query.py", line 1332, in _add_q
    allow_joins=allow_joins, split_subq=split_subq,
  File "/data/django/lib/python2.7/site-packages/django/db/models/sql/query.py", line 1203, in build_filter
    condition = self.build_lookup(lookups, col, value)
  File "/data/django/lib/python2.7/site-packages/django/db/models/sql/query.py", line 1096, in build_lookup
    return final_lookup(lhs, rhs)
  File "/data/django/lib/python2.7/site-packages/django/db/models/lookups.py", line 96, in __init__
    self.rhs = self.get_prep_lookup()
  File "/data/django/lib/python2.7/site-packages/django/db/models/lookups.py", line 134, in get_prep_lookup
    return self.lhs.output_field.get_prep_lookup(self.lookup_name, self.rhs)
  File "/data/django/lib/python2.7/site-packages/django/db/models/fields/__init__.py", line 727, in get_prep_lookup
    return self.get_prep_value(value)
  File "/data/django/lib/python2.7/site-packages/django/db/models/fields/__init__.py", line 985, in get_prep_value
    return int(value)
ValueError: invalid literal for int() with base 10: ''
2019-01-14 00:45:27,966 INFO  ---------------------- 
2019-01-14 00:45:27,967 INFO  11 
2019-01-14 00:45:27,979 ERROR  userdel: user 'wangbo1' does not exist
1
 
2019-01-14 00:45:27,985 ERROR  1
 
2019-01-14 00:45:28,024 INFO  SAMBA USER:wangbo1  was deleted. 
2019-01-14 00:45:49,889 INFO  USER wangbo1was add to db. 
2019-01-14 00:45:49,975 INFO  User was created. 
2019-01-14 00:45:50,044 INFO  SAMBA USER:wangbo1was added. 
2019-01-14 00:45:50,047 ERROR  Internal Server Error: /consumer/add_user 
Traceback (most recent call last):
  File "/data/django/lib/python2.7/site-packages/django/core/handlers/base.py", line 132, in get_response
    response = wrapped_callback(request, *callback_args, **callback_kwargs)
  File "/code/samba/web/consumer/views.py", line 49, in add_user
    return JsonResponse(json.dumps({"success":True}))
  File "/data/django/lib/python2.7/site-packages/django/http/response.py", line 532, in __init__
    raise TypeError('In order to allow non-dict objects to be '
TypeError: In order to allow non-dict objects to be serialized set the safe parameter to False
2019-01-14 00:46:33,608 INFO  fity2013@------------------- 
2019-01-14 00:46:33,616 ERROR  Internal Server Error: /consumer/user_edit 
Traceback (most recent call last):
  File "/data/django/lib/python2.7/site-packages/django/core/handlers/base.py", line 132, in get_response
    response = wrapped_callback(request, *callback_args, **callback_kwargs)
  File "/code/samba/web/consumer/views.py", line 57, in user_edit
    userid = Sa_user.objects.get(id=uid)
  File "/data/django/lib/python2.7/site-packages/django/db/models/manager.py", line 127, in manager_method
    return getattr(self.get_queryset(), name)(*args, **kwargs)
  File "/data/django/lib/python2.7/site-packages/django/db/models/query.py", line 325, in get
    clone = self.filter(*args, **kwargs)
  File "/data/django/lib/python2.7/site-packages/django/db/models/query.py", line 679, in filter
    return self._filter_or_exclude(False, *args, **kwargs)
  File "/data/django/lib/python2.7/site-packages/django/db/models/query.py", line 697, in _filter_or_exclude
    clone.query.add_q(Q(*args, **kwargs))
  File "/data/django/lib/python2.7/site-packages/django/db/models/sql/query.py", line 1304, in add_q
    clause, require_inner = self._add_q(where_part, self.used_aliases)
  File "/data/django/lib/python2.7/site-packages/django/db/models/sql/query.py", line 1332, in _add_q
    allow_joins=allow_joins, split_subq=split_subq,
  File "/data/django/lib/python2.7/site-packages/django/db/models/sql/query.py", line 1203, in build_filter
    condition = self.build_lookup(lookups, col, value)
  File "/data/django/lib/python2.7/site-packages/django/db/models/sql/query.py", line 1096, in build_lookup
    return final_lookup(lhs, rhs)
  File "/data/django/lib/python2.7/site-packages/django/db/models/lookups.py", line 96, in __init__
    self.rhs = self.get_prep_lookup()
  File "/data/django/lib/python2.7/site-packages/django/db/models/lookups.py", line 134, in get_prep_lookup
    return self.lhs.output_field.get_prep_lookup(self.lookup_name, self.rhs)
  File "/data/django/lib/python2.7/site-packages/django/db/models/fields/__init__.py", line 727, in get_prep_lookup
    return self.get_prep_value(value)
  File "/data/django/lib/python2.7/site-packages/django/db/models/fields/__init__.py", line 985, in get_prep_value
    return int(value)
ValueError: invalid literal for int() with base 10: ''
2019-01-14 00:46:33,776 INFO  SAMBA USER:wangbo1was added. 
2019-01-14 00:46:33,822 INFO  SAMBA USER:wangbo1was enabled. 
2019-01-14 00:46:33,824 ERROR  Internal Server Error: /consumer/user_edit 
Traceback (most recent call last):
  File "/data/django/lib/python2.7/site-packages/django/core/handlers/base.py", line 132, in get_response
    response = wrapped_callback(request, *callback_args, **callback_kwargs)
  File "/code/samba/web/consumer/views.py", line 74, in user_edit
    userid.save()
  File "/data/django/lib/python2.7/site-packages/django/db/models/base.py", line 710, in save
    force_update=force_update, update_fields=update_fields)
  File "/data/django/lib/python2.7/site-packages/django/db/models/base.py", line 738, in save_base
    updated = self._save_table(raw, cls, force_insert, force_update, using, update_fields)
  File "/data/django/lib/python2.7/site-packages/django/db/models/base.py", line 803, in _save_table
    forced_update)
  File "/data/django/lib/python2.7/site-packages/django/db/models/base.py", line 853, in _do_update
    return filtered._update(values) > 0
  File "/data/django/lib/python2.7/site-packages/django/db/models/query.py", line 580, in _update
    return query.get_compiler(self.db).execute_sql(CURSOR)
  File "/data/django/lib/python2.7/site-packages/django/db/models/sql/compiler.py", line 1062, in execute_sql
    cursor = super(SQLUpdateCompiler, self).execute_sql(result_type)
  File "/data/django/lib/python2.7/site-packages/django/db/models/sql/compiler.py", line 829, in execute_sql
    sql, params = self.as_sql()
  File "/data/django/lib/python2.7/site-packages/django/db/models/sql/compiler.py", line 1030, in as_sql
    val = field.get_db_prep_save(val, connection=self.connection)
  File "/data/django/lib/python2.7/site-packages/django/db/models/fields/__init__.py", line 710, in get_db_prep_save
    prepared=False)
  File "/data/django/lib/python2.7/site-packages/django/db/models/fields/__init__.py", line 702, in get_db_prep_value
    value = self.get_prep_value(value)
  File "/data/django/lib/python2.7/site-packages/django/db/models/fields/__init__.py", line 1868, in get_prep_value
    return int(value)
UnicodeEncodeError: 'decimal' codec can't encode characters in position 0-1: invalid decimal Unicode string
2019-01-14 00:49:43,732 INFO  Kname: samba_conf was get. 
2019-01-14 00:49:43,735 INFO  Kname: samba_conf was get. 
2019-01-14 00:49:43,736 INFO  Kname: samba_conf was get. 
2019-01-14 00:49:48,669 INFO  fity2013@------------------- 
2019-01-14 00:49:48,694 ERROR  Internal Server Error: /consumer/user_edit 
Traceback (most recent call last):
  File "/data/django/lib/python2.7/site-packages/django/core/handlers/base.py", line 132, in get_response
    response = wrapped_callback(request, *callback_args, **callback_kwargs)
  File "/code/samba/web/consumer/views.py", line 57, in user_edit
    userid = Sa_user.objects.get(id=uid)
  File "/data/django/lib/python2.7/site-packages/django/db/models/manager.py", line 127, in manager_method
    return getattr(self.get_queryset(), name)(*args, **kwargs)
  File "/data/django/lib/python2.7/site-packages/django/db/models/query.py", line 325, in get
    clone = self.filter(*args, **kwargs)
  File "/data/django/lib/python2.7/site-packages/django/db/models/query.py", line 679, in filter
    return self._filter_or_exclude(False, *args, **kwargs)
  File "/data/django/lib/python2.7/site-packages/django/db/models/query.py", line 697, in _filter_or_exclude
    clone.query.add_q(Q(*args, **kwargs))
  File "/data/django/lib/python2.7/site-packages/django/db/models/sql/query.py", line 1304, in add_q
    clause, require_inner = self._add_q(where_part, self.used_aliases)
  File "/data/django/lib/python2.7/site-packages/django/db/models/sql/query.py", line 1332, in _add_q
    allow_joins=allow_joins, split_subq=split_subq,
  File "/data/django/lib/python2.7/site-packages/django/db/models/sql/query.py", line 1203, in build_filter
    condition = self.build_lookup(lookups, col, value)
  File "/data/django/lib/python2.7/site-packages/django/db/models/sql/query.py", line 1096, in build_lookup
    return final_lookup(lhs, rhs)
  File "/data/django/lib/python2.7/site-packages/django/db/models/lookups.py", line 96, in __init__
    self.rhs = self.get_prep_lookup()
  File "/data/django/lib/python2.7/site-packages/django/db/models/lookups.py", line 134, in get_prep_lookup
    return self.lhs.output_field.get_prep_lookup(self.lookup_name, self.rhs)
  File "/data/django/lib/python2.7/site-packages/django/db/models/fields/__init__.py", line 727, in get_prep_lookup
    return self.get_prep_value(value)
  File "/data/django/lib/python2.7/site-packages/django/db/models/fields/__init__.py", line 985, in get_prep_value
    return int(value)
ValueError: invalid literal for int() with base 10: ''
2019-01-14 00:49:48,823 INFO  SAMBA USER:wangbo1was added. 
2019-01-14 00:49:48,858 INFO  SAMBA USER:wangbo1was enabled. 
2019-01-14 00:49:48,860 ERROR  Internal Server Error: /consumer/user_edit 
Traceback (most recent call last):
  File "/data/django/lib/python2.7/site-packages/django/core/handlers/base.py", line 132, in get_response
    response = wrapped_callback(request, *callback_args, **callback_kwargs)
  File "/code/samba/web/consumer/views.py", line 70, in user_edit
    Sa_user.objects.filter(id=uid).update(username=name,desc=desc,userpwd=pwd,user_role=role)
  File "/data/django/lib/python2.7/site-packages/django/db/models/query.py", line 563, in update
    rows = query.get_compiler(self.db).execute_sql(CURSOR)
  File "/data/django/lib/python2.7/site-packages/django/db/models/sql/compiler.py", line 1062, in execute_sql
    cursor = super(SQLUpdateCompiler, self).execute_sql(result_type)
  File "/data/django/lib/python2.7/site-packages/django/db/models/sql/compiler.py", line 829, in execute_sql
    sql, params = self.as_sql()
  File "/data/django/lib/python2.7/site-packages/django/db/models/sql/compiler.py", line 1030, in as_sql
    val = field.get_db_prep_save(val, connection=self.connection)
  File "/data/django/lib/python2.7/site-packages/django/db/models/fields/__init__.py", line 710, in get_db_prep_save
    prepared=False)
  File "/data/django/lib/python2.7/site-packages/django/db/models/fields/__init__.py", line 702, in get_db_prep_value
    value = self.get_prep_value(value)
  File "/data/django/lib/python2.7/site-packages/django/db/models/fields/__init__.py", line 1868, in get_prep_value
    return int(value)
UnicodeEncodeError: 'decimal' codec can't encode characters in position 0-1: invalid decimal Unicode string
2019-01-15 20:19:34,350 INFO  Kname: samba_conf was get. 
2019-01-15 20:19:34,352 INFO  Kname: samba_conf was get. 
2019-01-15 20:19:34,353 INFO  Kname: samba_conf was get. 
2019-01-15 20:19:34,916 WARNING  Not Found: /favicon.ico 
2019-01-15 20:19:48,350 INFO  ---------------------- 
2019-01-15 20:19:48,350 INFO  12 
2019-01-15 20:19:48,619 ERROR  userdel: wangbo1 home directory (/home/wangbo1) not found
 
2019-01-15 20:19:48,634 ERROR  1
 
2019-01-15 20:19:49,785 INFO  SAMBA USER:wangbo1  was deleted. 
2019-01-15 20:54:35,212 INFO  Kname: samba_conf was get. 
2019-01-15 20:54:35,215 INFO  Kname: samba_conf was get. 
2019-01-15 20:54:35,215 INFO  Kname: samba_conf was get. 
2019-01-15 20:54:58,466 INFO  USER wangbo1was add to db. 
2019-01-15 20:54:58,542 INFO  User was created. 
2019-01-15 20:54:59,045 INFO  SAMBA USER:wangbo1was added. 
2019-01-15 20:54:59,047 ERROR  Internal Server Error: /consumer/add_user 
Traceback (most recent call last):
  File "/data/django/lib/python2.7/site-packages/django/core/handlers/base.py", line 132, in get_response
    response = wrapped_callback(request, *callback_args, **callback_kwargs)
  File "/code/samba/web/consumer/views.py", line 49, in add_user
    return JsonResponse(json.dumps({"success":True}))
  File "/data/django/lib/python2.7/site-packages/django/http/response.py", line 532, in __init__
    raise TypeError('In order to allow non-dict objects to be '
TypeError: In order to allow non-dict objects to be serialized set the safe parameter to False
2019-01-15 20:55:11,836 ERROR  Internal Server Error: /consumer/reset_pwd 
Traceback (most recent call last):
  File "/data/django/lib/python2.7/site-packages/django/core/handlers/base.py", line 132, in get_response
    response = wrapped_callback(request, *callback_args, **callback_kwargs)
  File "/code/samba/web/consumer/views.py", line 76, in reset_pwd
    wsuser.wsuser(name).wudel()
NameError: global name 'name' is not defined
2019-01-15 20:59:40,041 INFO  Kname: samba_conf was get. 
2019-01-15 20:59:40,045 INFO  Kname: samba_conf was get. 
2019-01-15 20:59:40,045 INFO  Kname: samba_conf was get. 
2019-01-15 20:59:49,507 INFO  SAMBA USER:wangbo1  was deleted. 
2019-01-15 20:59:49,589 INFO  SAMBA USER:wangbo1was added. 
2019-01-15 20:59:49,632 INFO  SAMBA USER:wangbo1was enabled. 
2019-01-15 20:59:49,655 ERROR  Internal Server Error: /consumer/reset_pwd 
Traceback (most recent call last):
  File "/data/django/lib/python2.7/site-packages/django/core/handlers/base.py", line 132, in get_response
    response = wrapped_callback(request, *callback_args, **callback_kwargs)
  File "/code/samba/web/consumer/views.py", line 81, in reset_pwd
    return JsonResponse(json.dumps({"success":True}))
  File "/data/django/lib/python2.7/site-packages/django/http/response.py", line 532, in __init__
    raise TypeError('In order to allow non-dict objects to be '
TypeError: In order to allow non-dict objects to be serialized set the safe parameter to False
2019-01-15 21:10:39,531 INFO  Kname: samba_conf was get. 
2019-01-15 21:10:39,535 INFO  Kname: samba_conf was get. 
2019-01-15 21:10:39,536 INFO  Kname: samba_conf was get. 
2019-01-15 21:10:44,998 INFO  SAMBA USER:wangbo1was stoped. 
2019-01-15 21:10:44,999 ERROR  Internal Server Error: /consumer/lock_user 
Traceback (most recent call last):
  File "/data/django/lib/python2.7/site-packages/django/core/handlers/base.py", line 132, in get_response
    response = wrapped_callback(request, *callback_args, **callback_kwargs)
  File "/code/samba/web/consumer/views.py", line 99, in user_lock
    return JsonResponse(json.dumps({"success":True}))
  File "/data/django/lib/python2.7/site-packages/django/http/response.py", line 532, in __init__
    raise TypeError('In order to allow non-dict objects to be '
TypeError: In order to allow non-dict objects to be serialized set the safe parameter to False
2019-01-15 21:22:51,716 INFO  Kname: samba_conf was get. 
2019-01-15 21:22:51,718 INFO  Kname: samba_conf was get. 
2019-01-15 21:22:51,719 INFO  Kname: samba_conf was get. 
2019-01-15 21:29:14,010 INFO  Kname: samba_conf was get. 
2019-01-15 21:29:14,015 INFO  Kname: samba_conf was get. 
2019-01-15 21:29:14,015 INFO  Kname: samba_conf was get. 
2019-01-15 22:03:01,818 INFO  Kname: samba_conf was get. 
2019-01-15 22:03:01,819 INFO  Kname: samba_conf was get. 
2019-01-15 22:03:01,820 INFO  Kname: samba_conf was get. 
2019-01-15 22:03:14,364 INFO  SAMBA USER:wangbo1was enabled. 
2019-01-15 22:03:14,407 ERROR  Internal Server Error: /consumer/lock_user 
Traceback (most recent call last):
  File "/data/django/lib/python2.7/site-packages/django/core/handlers/base.py", line 132, in get_response
    response = wrapped_callback(request, *callback_args, **callback_kwargs)
  File "/code/samba/web/consumer/views.py", line 99, in user_lock
    return JsonResponse(json.dumps({"success":True}))
  File "/data/django/lib/python2.7/site-packages/django/http/response.py", line 532, in __init__
    raise TypeError('In order to allow non-dict objects to be '
TypeError: In order to allow non-dict objects to be serialized set the safe parameter to False
2019-01-15 22:31:33,298 INFO  Kname: samba_conf was get. 
2019-01-15 22:31:33,301 INFO  Kname: samba_conf was get. 
2019-01-15 22:31:33,301 INFO  Kname: samba_conf was get. 
2019-01-15 22:41:21,914 INFO  Kname: samba_conf was get. 
2019-01-15 22:41:21,915 INFO  Kname: samba_conf was get. 
2019-01-15 22:41:21,916 INFO  Kname: samba_conf was get. 
2019-01-15 22:42:36,008 INFO  Kname: samba_conf was get. 
2019-01-15 22:42:36,009 INFO  Kname: samba_conf was get. 
2019-01-15 22:42:36,010 INFO  Kname: samba_conf was get. 
2019-01-15 23:00:40,579 INFO  Kname: samba_conf was get. 
2019-01-15 23:00:40,580 INFO  Kname: samba_conf was get. 
2019-01-15 23:00:40,583 INFO  Kname: samba_conf was get. 
2019-01-15 23:00:46,594 WARNING  Not Found: /department/lock_department 
2019-01-15 23:00:46,658 WARNING  Not Found: /department/lock_department 
2019-01-15 23:05:01,723 WARNING  Not Found: /department/delete_department 
2019-01-15 23:05:05,314 WARNING  Not Found: /department/edit_department 
2019-01-15 23:21:19,103 WARNING  Not Found: /department/lock_department 
2019-01-15 23:21:57,702 INFO  Kname: samba_conf was get. 
2019-01-15 23:21:57,703 INFO  Kname: samba_conf was get. 
2019-01-15 23:21:57,704 INFO  Kname: samba_conf was get. 
2019-01-15 23:22:08,631 WARNING  Not Found: /department/lock_department 
